# %ECSV 0.9
# ---
# datatype:
# - {name: cid, datatype: object}
# - {name: num_points_91bg_proj_csp_u, datatype: object}
# - {name: num_points_91bg_proj_csp_g, datatype: object}
# - {name: num_points_91bg_proj_csp_r, datatype: object}
# - {name: num_points_91bg_proj_csp_i, datatype: object}
# - {name: num_points_91bg_proj_csp_B, datatype: object}
# - {name: num_points_91bg_proj_csp_V0, datatype: object}
# - {name: num_points_91bg_proj_csp_V1, datatype: object}
# - {name: num_points_91bg_proj_csp_V, datatype: object}
# - {name: num_points_91bg_proj_csp_Y, datatype: object}
# - {name: num_points_91bg_proj_csp_H, datatype: object}
# - {name: num_points_91bg_proj_csp_J, datatype: object}
# - {name: num_points_91bg_proj_csp_Jrc2, datatype: object}
# - {name: num_points_91bg_proj_csp_Ydw, datatype: object}
# - {name: num_points_91bg_proj_csp_Jdw, datatype: object}
# - {name: num_points_91bg_proj_csp_Hdw, datatype: object}
# - {name: z, datatype: object}
# - {name: t0, datatype: object}
# - {name: x0, datatype: object}
# - {name: x1, datatype: object}
# - {name: c, datatype: object}
# - {name: z_err, datatype: object}
# - {name: t0_err, datatype: object}
# - {name: x0_err, datatype: object}
# - {name: x1_err, datatype: object}
# - {name: c_err, datatype: object}
# - {name: chi, datatype: object}
# - {name: dof, datatype: object}
# - {name: message, datatype: object}
# meta: !!omap
# - bounds:
#     c: [0, 1]
#     x1': [0.65, 1.25]
#     z: [0.002, 0.085]
# - {warn: false}
# schema: astropy-2.0
cid num_points_91bg_proj_csp_u num_points_91bg_proj_csp_g num_points_91bg_proj_csp_r num_points_91bg_proj_csp_i num_points_91bg_proj_csp_B num_points_91bg_proj_csp_V0 num_points_91bg_proj_csp_V1 num_points_91bg_proj_csp_V num_points_91bg_proj_csp_Y num_points_91bg_proj_csp_H num_points_91bg_proj_csp_J num_points_91bg_proj_csp_Jrc2 num_points_91bg_proj_csp_Ydw num_points_91bg_proj_csp_Jdw num_points_91bg_proj_csp_Hdw z t0 x0 x1 c z_err t0_err x0_err x1_err c_err chi dof message
2008J 8 10 10 9 10 0 0 10 10 3 11 0 0 0 0 0.08499999997267765 1380.190000879672 5.859266278692136e-14 12.345565953379463 0.38876948399608585 5.09630296733482e-06 0.016811678014960307 9.542461815186156e-16 0.12832766126221606 0.006471689200742647 8747.339050740542 52 "Covariance may not be accurate. Covariance not positive definite. Covariance forced positive definite."
2005kc 9 13 12 13 13 13 0 0 18 16 18 0 0 0 0 0.0020000000000082287 697.2590805914965 2.1070741919189768e-14 1.4240963567661071 2.466915560717098e-13 2.995961938907646e-06 0.011910505275068317 2.787478919726837e-16 0.02253725478349758 2.4822055305961932e-05 17881.66132655483 68 "Covariance may not be accurate. Covariance not positive definite. Covariance forced positive definite."
2005A 0 28 33 33 17 28 0 0 0 15 14 0 14 0 0 0.009221400207397942 377.9502772563922 8.553171314788912e-15 1.8367257564558606 0.6473472274168426 0.0001621282385262093 0.10832811093794703 8.117194838759051e-17 0.010862935374890144 0.006551087620499663 19804.361913048713 148 "Covariance may not be accurate. Covariance not positive definite. Covariance forced positive definite."
2009Y 29 27 28 31 30 0 0 30 29 26 6 22 6 0 0 nan nan nan nan nan nan nan nan nan nan nan nan "exception was raised in user function
User function arguments:
     z = +0.002000
    t0 = +1896.049983
    x0 = +0.000000
    x1 = -0.427591
     c = +0.994917
Original python exception in user function:
ValueError: Error code returned by bispev: 10
  File ""/anaconda3/envs/sdss_classification_3.7/lib/python3.7/site-packages/sncosmo/fitting.py"", line 46, in chisq
    zp=data.zp, zpsys=data.zpsys)
  File ""/anaconda3/envs/sdss_classification_3.7/lib/python3.7/site-packages/sncosmo/models.py"", line 1400, in bandflux
    raise e
  File ""/anaconda3/envs/sdss_classification_3.7/lib/python3.7/site-packages/sncosmo/models.py"", line 1397, in bandflux
    return _bandflux(self, band, time, zp, zpsys)
  File ""/anaconda3/envs/sdss_classification_3.7/lib/python3.7/site-packages/sncosmo/models.py"", line 154, in _bandflux
    fsum = _bandflux_single(model, b, time_or_phase[mask])
  File ""/anaconda3/envs/sdss_classification_3.7/lib/python3.7/site-packages/sncosmo/models.py"", line 116, in _bandflux_single
    f = model._flux(time_or_phase, wave)
  File ""/anaconda3/envs/sdss_classification_3.7/lib/python3.7/site-packages/sncosmo/models.py"", line 1272, in _flux
    f = a * self._source._flux(phase, restwave)
  File ""/Users/daniel/Github/SDSS-Classification/analysis_pipeline/_sn91bg_model/_model.py"", line 135, in _flux
    y = [self._model_flux[c1](phase / (st / 0.65), wave),
  File ""/anaconda3/envs/sdss_classification_3.7/lib/python3.7/site-packages/scipy/interpolate/fitpack2.py"", line 848, in __call__
    raise ValueError(""Error code returned by bispev: %s"" % ier)"
2004gs 19 49 50 46 43 53 0 0 0 7 15 0 17 0 0 0.0020000000001144025 356.4313852668254 6.3822661635664356e-15 1.0965240749582792 1.124100812432971e-12 2.2080032463255884e-06 0.03301226762226861 5.732080082222743e-17 0.01080667859144525 9.974079063057584e-06 36689.94021734522 272 "Covariance may not be accurate. Covariance not positive definite. Covariance forced positive definite."
2004eo 36 34 35 39 38 39 0 0 0 17 16 0 15 0 0 0.0020000000000063903 277.97875477011297 2.7602485407501295e-14 1.405861998070301 2.2570834090629432e-13 1.8161184271747212e-07 0.009370463118273165 1.4113138793407025e-16 0.005685689099275155 2.127090168640988e-06 463232.36649625073 231 "Covariance may not be accurate. Covariance not positive definite. Covariance forced positive definite."
2008gp 14 17 20 20 21 0 0 21 20 17 19 0 0 0 0 nan nan nan nan nan nan nan nan nan nan nan nan "exception was raised in user function
User function arguments:
     z = +0.002000
    t0 = +1778.107797
    x0 = +0.000000
    x1 = -0.160076
     c = +0.983584
Original python exception in user function:
ValueError: Error code returned by bispev: 10
  File ""/anaconda3/envs/sdss_classification_3.7/lib/python3.7/site-packages/sncosmo/fitting.py"", line 46, in chisq
    zp=data.zp, zpsys=data.zpsys)
  File ""/anaconda3/envs/sdss_classification_3.7/lib/python3.7/site-packages/sncosmo/models.py"", line 1400, in bandflux
    raise e
  File ""/anaconda3/envs/sdss_classification_3.7/lib/python3.7/site-packages/sncosmo/models.py"", line 1397, in bandflux
    return _bandflux(self, band, time, zp, zpsys)
  File ""/anaconda3/envs/sdss_classification_3.7/lib/python3.7/site-packages/sncosmo/models.py"", line 154, in _bandflux
    fsum = _bandflux_single(model, b, time_or_phase[mask])
  File ""/anaconda3/envs/sdss_classification_3.7/lib/python3.7/site-packages/sncosmo/models.py"", line 116, in _bandflux_single
    f = model._flux(time_or_phase, wave)
  File ""/anaconda3/envs/sdss_classification_3.7/lib/python3.7/site-packages/sncosmo/models.py"", line 1272, in _flux
    f = a * self._source._flux(phase, restwave)
  File ""/Users/daniel/Github/SDSS-Classification/analysis_pipeline/_sn91bg_model/_model.py"", line 135, in _flux
    y = [self._model_flux[c1](phase / (st / 0.65), wave),
  File ""/anaconda3/envs/sdss_classification_3.7/lib/python3.7/site-packages/scipy/interpolate/fitpack2.py"", line 848, in __call__
    raise ValueError(""Error code returned by bispev: %s"" % ier)"
2007ca 8 12 12 12 12 0 0 12 12 14 15 0 8 0 0 nan nan nan nan nan nan nan nan nan nan nan nan "exception was raised in user function
User function arguments:
     z = +0.002000
    t0 = +1220.097928
    x0 = +0.000000
    x1 = -1.845384
     c = +0.999612
Original python exception in user function:
ValueError: Error code returned by bispev: 10
  File ""/anaconda3/envs/sdss_classification_3.7/lib/python3.7/site-packages/sncosmo/fitting.py"", line 46, in chisq
    zp=data.zp, zpsys=data.zpsys)
  File ""/anaconda3/envs/sdss_classification_3.7/lib/python3.7/site-packages/sncosmo/models.py"", line 1400, in bandflux
    raise e
  File ""/anaconda3/envs/sdss_classification_3.7/lib/python3.7/site-packages/sncosmo/models.py"", line 1397, in bandflux
    return _bandflux(self, band, time, zp, zpsys)
  File ""/anaconda3/envs/sdss_classification_3.7/lib/python3.7/site-packages/sncosmo/models.py"", line 154, in _bandflux
    fsum = _bandflux_single(model, b, time_or_phase[mask])
  File ""/anaconda3/envs/sdss_classification_3.7/lib/python3.7/site-packages/sncosmo/models.py"", line 116, in _bandflux_single
    f = model._flux(time_or_phase, wave)
  File ""/anaconda3/envs/sdss_classification_3.7/lib/python3.7/site-packages/sncosmo/models.py"", line 1272, in _flux
    f = a * self._source._flux(phase, restwave)
  File ""/Users/daniel/Github/SDSS-Classification/analysis_pipeline/_sn91bg_model/_model.py"", line 135, in _flux
    y = [self._model_flux[c1](phase / (st / 0.65), wave),
  File ""/anaconda3/envs/sdss_classification_3.7/lib/python3.7/site-packages/scipy/interpolate/fitpack2.py"", line 848, in __call__
    raise ValueError(""Error code returned by bispev: %s"" % ier)"
2009al 12 14 14 14 14 0 0 15 14 12 2 12 0 0 0 nan nan nan nan nan nan nan nan nan nan nan nan "exception was raised in user function
User function arguments:
     z = +0.002000
    t0 = +1889.134223
    x0 = +0.000000
    x1 = -0.120599
     c = +0.999595
Original python exception in user function:
ValueError: Error code returned by bispev: 10
  File ""/anaconda3/envs/sdss_classification_3.7/lib/python3.7/site-packages/sncosmo/fitting.py"", line 46, in chisq
    zp=data.zp, zpsys=data.zpsys)
  File ""/anaconda3/envs/sdss_classification_3.7/lib/python3.7/site-packages/sncosmo/models.py"", line 1400, in bandflux
    raise e
  File ""/anaconda3/envs/sdss_classification_3.7/lib/python3.7/site-packages/sncosmo/models.py"", line 1397, in bandflux
    return _bandflux(self, band, time, zp, zpsys)
  File ""/anaconda3/envs/sdss_classification_3.7/lib/python3.7/site-packages/sncosmo/models.py"", line 154, in _bandflux
    fsum = _bandflux_single(model, b, time_or_phase[mask])
  File ""/anaconda3/envs/sdss_classification_3.7/lib/python3.7/site-packages/sncosmo/models.py"", line 116, in _bandflux_single
    f = model._flux(time_or_phase, wave)
  File ""/anaconda3/envs/sdss_classification_3.7/lib/python3.7/site-packages/sncosmo/models.py"", line 1272, in _flux
    f = a * self._source._flux(phase, restwave)
  File ""/Users/daniel/Github/SDSS-Classification/analysis_pipeline/_sn91bg_model/_model.py"", line 135, in _flux
    y = [self._model_flux[c1](phase / (st / 0.65), wave),
  File ""/anaconda3/envs/sdss_classification_3.7/lib/python3.7/site-packages/scipy/interpolate/fitpack2.py"", line 848, in __call__
    raise ValueError(""Error code returned by bispev: %s"" % ier)"
2008ae 2 2 5 5 8 0 0 18 17 16 20 0 8 0 0 0.08499999999799944 1492.4924330222568 5.884509169867343e-15 1.4740200415257847 0.0558689539873819 3.418825793539276e-05 0.28835847952950644 1.452150834504715e-16 0.012752946537608785 0.01379992140054287 7615.104957768645 43 "Covariance may not be accurate. Covariance not positive definite. Covariance forced positive definite."
2006dd 25 39 38 37 38 0 0 39 1 0 0 0 0 0 0 0.0020000000000307636 920.4211908903784 2.003501991638938e-13 1.847004361725007 6.871725410917406e-13 2.890418216740503e-07 0.039690677063561 3.15446434621852e-16 0.0014649054249574783 3.3805643449014156e-06 355480.52464034525 211 "Minimization exited successfully."
2005ki 30 47 45 43 44 17 0 25 18 17 21 0 3 0 0 0.0020000000000221984 704.5205652943843 1.8801345109816033e-14 1.2765980589681183 8.226197500960097e-13 2.412892565939375e-07 0.03948218207085574 1.8860717082241541e-16 0.010342576039677887 2.089615210060236e-06 165156.78451110734 249 "Covariance may not be accurate. Covariance not positive definite. Covariance forced positive definite."
2007if 4 15 0 15 15 0 0 17 0 0 0 0 10 0 0 0.0020000006108736508 1353.4298279539364 4.353038159975691e-15 1.6971241224531863 0.15519155086135084 3.0761234079638294e-06 0.1403905369693348 5.3785576768591744e-17 0.012746181440837412 0.006690320148266815 8273.50017750149 71 "Covariance may not be accurate. Covariance not positive definite. Covariance forced positive definite."
2006D 32 38 38 41 39 0 0 38 20 21 23 0 8 0 0 0.002000000000941509 758.0210486451921 6.846577931370962e-14 1.2226424846143522 3.5982328228101323e-12 1.7586315247423642e-07 0.06675091517928422 5.562946655263426e-16 0.005604953185365237 1.7629087183945735e-06 300482.3681485418 229 "Covariance may not be accurate. Covariance not positive definite. Covariance forced positive definite."
2006lu 6 26 26 17 21 0 0 27 2 0 0 0 3 0 0 nan nan nan nan nan nan nan nan nan nan nan nan "exception was raised in user function
User function arguments:
     z = +0.082959
    t0 = +1022.959252
    x0 = +0.000000
    x1 = -1.828264
     c = +0.975994
Original python exception in user function:
ValueError: Error code returned by bispev: 10
  File ""/anaconda3/envs/sdss_classification_3.7/lib/python3.7/site-packages/sncosmo/fitting.py"", line 46, in chisq
    zp=data.zp, zpsys=data.zpsys)
  File ""/anaconda3/envs/sdss_classification_3.7/lib/python3.7/site-packages/sncosmo/models.py"", line 1400, in bandflux
    raise e
  File ""/anaconda3/envs/sdss_classification_3.7/lib/python3.7/site-packages/sncosmo/models.py"", line 1397, in bandflux
    return _bandflux(self, band, time, zp, zpsys)
  File ""/anaconda3/envs/sdss_classification_3.7/lib/python3.7/site-packages/sncosmo/models.py"", line 154, in _bandflux
    fsum = _bandflux_single(model, b, time_or_phase[mask])
  File ""/anaconda3/envs/sdss_classification_3.7/lib/python3.7/site-packages/sncosmo/models.py"", line 116, in _bandflux_single
    f = model._flux(time_or_phase, wave)
  File ""/anaconda3/envs/sdss_classification_3.7/lib/python3.7/site-packages/sncosmo/models.py"", line 1272, in _flux
    f = a * self._source._flux(phase, restwave)
  File ""/Users/daniel/Github/SDSS-Classification/analysis_pipeline/_sn91bg_model/_model.py"", line 135, in _flux
    y = [self._model_flux[c1](phase / (st / 0.65), wave),
  File ""/anaconda3/envs/sdss_classification_3.7/lib/python3.7/site-packages/scipy/interpolate/fitpack2.py"", line 848, in __call__
    raise ValueError(""Error code returned by bispev: %s"" % ier)"
2009ag 18 18 18 18 18 0 0 18 32 31 3 30 4 0 0 0.0020000000158824456 1892.1205882224215 3.415803912347157e-14 1.5345900516931008 0.10320520074719808 4.547726480567905e-06 0.05973933530242448 2.7071572902550367e-16 0.006380752108836006 0.003355111213750983 64530.16592409475 107 "Covariance may not be accurate. Covariance not positive definite. Covariance forced positive definite."
2006ev 0 10 10 10 9 0 0 10 16 20 23 0 8 0 0 0.0020000000251075944 993.7232587370345 4.257684277163216e-15 1.3049351373155198 1.167399510393352e-13 5.164557160726186e-07 0.13170367031432306 5.004715285281926e-17 0.016752012692166886 5.75597585369958e-06 23768.765297738326 52 "Covariance may not be accurate. Covariance not positive definite. Covariance forced positive definite."
2009cz 8 8 8 8 8 0 0 8 9 12 2 10 2 0 0 nan nan nan nan nan nan nan nan nan nan nan nan "exception was raised in user function
User function arguments:
     z = +0.002000
    t0 = +1952.712965
    x0 = +0.000000
    x1 = -6.896415
     c = +0.997578
Original python exception in user function:
ValueError: Error code returned by bispev: 10
  File ""/anaconda3/envs/sdss_classification_3.7/lib/python3.7/site-packages/sncosmo/fitting.py"", line 46, in chisq
    zp=data.zp, zpsys=data.zpsys)
  File ""/anaconda3/envs/sdss_classification_3.7/lib/python3.7/site-packages/sncosmo/models.py"", line 1400, in bandflux
    raise e
  File ""/anaconda3/envs/sdss_classification_3.7/lib/python3.7/site-packages/sncosmo/models.py"", line 1397, in bandflux
    return _bandflux(self, band, time, zp, zpsys)
  File ""/anaconda3/envs/sdss_classification_3.7/lib/python3.7/site-packages/sncosmo/models.py"", line 154, in _bandflux
    fsum = _bandflux_single(model, b, time_or_phase[mask])
  File ""/anaconda3/envs/sdss_classification_3.7/lib/python3.7/site-packages/sncosmo/models.py"", line 116, in _bandflux_single
    f = model._flux(time_or_phase, wave)
  File ""/anaconda3/envs/sdss_classification_3.7/lib/python3.7/site-packages/sncosmo/models.py"", line 1272, in _flux
    f = a * self._source._flux(phase, restwave)
  File ""/Users/daniel/Github/SDSS-Classification/analysis_pipeline/_sn91bg_model/_model.py"", line 135, in _flux
    y = [self._model_flux[c1](phase / (st / 0.65), wave),
  File ""/anaconda3/envs/sdss_classification_3.7/lib/python3.7/site-packages/scipy/interpolate/fitpack2.py"", line 848, in __call__
    raise ValueError(""Error code returned by bispev: %s"" % ier)"
2006gj 4 19 19 16 12 0 0 17 14 7 9 0 5 0 0 nan nan nan nan nan nan nan nan nan nan nan nan "exception was raised in user function
User function arguments:
     z = +0.084056
    t0 = +957.527244
    x0 = +0.000000
    x1 = -0.737211
     c = +0.982300
Original python exception in user function:
ValueError: Error code returned by bispev: 10
  File ""/anaconda3/envs/sdss_classification_3.7/lib/python3.7/site-packages/sncosmo/fitting.py"", line 46, in chisq
    zp=data.zp, zpsys=data.zpsys)
  File ""/anaconda3/envs/sdss_classification_3.7/lib/python3.7/site-packages/sncosmo/models.py"", line 1400, in bandflux
    raise e
  File ""/anaconda3/envs/sdss_classification_3.7/lib/python3.7/site-packages/sncosmo/models.py"", line 1397, in bandflux
    return _bandflux(self, band, time, zp, zpsys)
  File ""/anaconda3/envs/sdss_classification_3.7/lib/python3.7/site-packages/sncosmo/models.py"", line 154, in _bandflux
    fsum = _bandflux_single(model, b, time_or_phase[mask])
  File ""/anaconda3/envs/sdss_classification_3.7/lib/python3.7/site-packages/sncosmo/models.py"", line 116, in _bandflux_single
    f = model._flux(time_or_phase, wave)
  File ""/anaconda3/envs/sdss_classification_3.7/lib/python3.7/site-packages/sncosmo/models.py"", line 1272, in _flux
    f = a * self._source._flux(phase, restwave)
  File ""/Users/daniel/Github/SDSS-Classification/analysis_pipeline/_sn91bg_model/_model.py"", line 135, in _flux
    y = [self._model_flux[c1](phase / (st / 0.65), wave),
  File ""/anaconda3/envs/sdss_classification_3.7/lib/python3.7/site-packages/scipy/interpolate/fitpack2.py"", line 848, in __call__
    raise ValueError(""Error code returned by bispev: %s"" % ier)"
2005el 24 22 22 24 24 23 0 0 38 24 31 0 4 0 0 nan nan nan nan nan nan nan nan nan nan nan nan "exception was raised in user function
User function arguments:
     z = +0.002000
    t0 = +642.487677
    x0 = +0.000000
    x1 = -0.111012
     c = +0.992874
Original python exception in user function:
ValueError: Error code returned by bispev: 10
  File ""/anaconda3/envs/sdss_classification_3.7/lib/python3.7/site-packages/sncosmo/fitting.py"", line 46, in chisq
    zp=data.zp, zpsys=data.zpsys)
  File ""/anaconda3/envs/sdss_classification_3.7/lib/python3.7/site-packages/sncosmo/models.py"", line 1400, in bandflux
    raise e
  File ""/anaconda3/envs/sdss_classification_3.7/lib/python3.7/site-packages/sncosmo/models.py"", line 1397, in bandflux
    return _bandflux(self, band, time, zp, zpsys)
  File ""/anaconda3/envs/sdss_classification_3.7/lib/python3.7/site-packages/sncosmo/models.py"", line 154, in _bandflux
    fsum = _bandflux_single(model, b, time_or_phase[mask])
  File ""/anaconda3/envs/sdss_classification_3.7/lib/python3.7/site-packages/sncosmo/models.py"", line 116, in _bandflux_single
    f = model._flux(time_or_phase, wave)
  File ""/anaconda3/envs/sdss_classification_3.7/lib/python3.7/site-packages/sncosmo/models.py"", line 1272, in _flux
    f = a * self._source._flux(phase, restwave)
  File ""/Users/daniel/Github/SDSS-Classification/analysis_pipeline/_sn91bg_model/_model.py"", line 135, in _flux
    y = [self._model_flux[c1](phase / (st / 0.65), wave),
  File ""/anaconda3/envs/sdss_classification_3.7/lib/python3.7/site-packages/scipy/interpolate/fitpack2.py"", line 848, in __call__
    raise ValueError(""Error code returned by bispev: %s"" % ier)"
2007jh 0 9 10 8 7 0 0 9 1 1 0 0 0 0 0 0.01488155408741319 1365.7806139390354 1.984039779794181e-15 1.0574075940914534 1.1180534276178378e-10 0.000782173760111679 0.05878494014677926 4.6814211995204754e-17 0.032542497512427694 0.00045689520903638425 410.64632724996403 38 "Covariance may not be accurate. Covariance not positive definite. Covariance forced positive definite."
2007so 4 8 8 8 7 0 0 8 8 6 4 0 5 0 0 nan nan nan nan nan nan nan nan nan nan nan nan "exception was raised in user function
User function arguments:
     z = +0.084999
    t0 = +1431.274365
    x0 = +0.000000
    x1 = -1.012028
     c = +0.938701
Original python exception in user function:
ValueError: Error code returned by bispev: 10
  File ""/anaconda3/envs/sdss_classification_3.7/lib/python3.7/site-packages/sncosmo/fitting.py"", line 46, in chisq
    zp=data.zp, zpsys=data.zpsys)
  File ""/anaconda3/envs/sdss_classification_3.7/lib/python3.7/site-packages/sncosmo/models.py"", line 1400, in bandflux
    raise e
  File ""/anaconda3/envs/sdss_classification_3.7/lib/python3.7/site-packages/sncosmo/models.py"", line 1397, in bandflux
    return _bandflux(self, band, time, zp, zpsys)
  File ""/anaconda3/envs/sdss_classification_3.7/lib/python3.7/site-packages/sncosmo/models.py"", line 154, in _bandflux
    fsum = _bandflux_single(model, b, time_or_phase[mask])
  File ""/anaconda3/envs/sdss_classification_3.7/lib/python3.7/site-packages/sncosmo/models.py"", line 116, in _bandflux_single
    f = model._flux(time_or_phase, wave)
  File ""/anaconda3/envs/sdss_classification_3.7/lib/python3.7/site-packages/sncosmo/models.py"", line 1272, in _flux
    f = a * self._source._flux(phase, restwave)
  File ""/Users/daniel/Github/SDSS-Classification/analysis_pipeline/_sn91bg_model/_model.py"", line 135, in _flux
    y = [self._model_flux[c1](phase / (st / 0.65), wave),
  File ""/anaconda3/envs/sdss_classification_3.7/lib/python3.7/site-packages/scipy/interpolate/fitpack2.py"", line 848, in __call__
    raise ValueError(""Error code returned by bispev: %s"" % ier)"
2006gt 4 12 13 12 11 0 0 12 9 2 10 0 8 0 0 nan nan nan nan nan nan nan nan nan nan nan nan "exception was raised in user function
User function arguments:
     z = +0.080329
    t0 = +996.738169
    x0 = +0.000000
    x1 = -0.203305
     c = +0.550000
Original python exception in user function:
ValueError: Error code returned by bispev: 10
  File ""/anaconda3/envs/sdss_classification_3.7/lib/python3.7/site-packages/sncosmo/fitting.py"", line 46, in chisq
    zp=data.zp, zpsys=data.zpsys)
  File ""/anaconda3/envs/sdss_classification_3.7/lib/python3.7/site-packages/sncosmo/models.py"", line 1400, in bandflux
    raise e
  File ""/anaconda3/envs/sdss_classification_3.7/lib/python3.7/site-packages/sncosmo/models.py"", line 1397, in bandflux
    return _bandflux(self, band, time, zp, zpsys)
  File ""/anaconda3/envs/sdss_classification_3.7/lib/python3.7/site-packages/sncosmo/models.py"", line 154, in _bandflux
    fsum = _bandflux_single(model, b, time_or_phase[mask])
  File ""/anaconda3/envs/sdss_classification_3.7/lib/python3.7/site-packages/sncosmo/models.py"", line 116, in _bandflux_single
    f = model._flux(time_or_phase, wave)
  File ""/anaconda3/envs/sdss_classification_3.7/lib/python3.7/site-packages/sncosmo/models.py"", line 1272, in _flux
    f = a * self._source._flux(phase, restwave)
  File ""/Users/daniel/Github/SDSS-Classification/analysis_pipeline/_sn91bg_model/_model.py"", line 135, in _flux
    y = [self._model_flux[c1](phase / (st / 0.65), wave),
  File ""/anaconda3/envs/sdss_classification_3.7/lib/python3.7/site-packages/scipy/interpolate/fitpack2.py"", line 848, in __call__
    raise ValueError(""Error code returned by bispev: %s"" % ier)"
2007ai 6 15 17 16 15 0 0 16 6 6 10 0 4 0 0 nan nan nan nan nan nan nan nan nan nan nan nan "exception was raised in user function
User function arguments:
     z = +0.081641
    t0 = +1167.128953
    x0 = +0.000000
    x1 = -2.990038
     c = +0.941692
Original python exception in user function:
ValueError: Error code returned by bispev: 10
  File ""/anaconda3/envs/sdss_classification_3.7/lib/python3.7/site-packages/sncosmo/fitting.py"", line 46, in chisq
    zp=data.zp, zpsys=data.zpsys)
  File ""/anaconda3/envs/sdss_classification_3.7/lib/python3.7/site-packages/sncosmo/models.py"", line 1400, in bandflux
    raise e
  File ""/anaconda3/envs/sdss_classification_3.7/lib/python3.7/site-packages/sncosmo/models.py"", line 1397, in bandflux
    return _bandflux(self, band, time, zp, zpsys)
  File ""/anaconda3/envs/sdss_classification_3.7/lib/python3.7/site-packages/sncosmo/models.py"", line 154, in _bandflux
    fsum = _bandflux_single(model, b, time_or_phase[mask])
  File ""/anaconda3/envs/sdss_classification_3.7/lib/python3.7/site-packages/sncosmo/models.py"", line 116, in _bandflux_single
    f = model._flux(time_or_phase, wave)
  File ""/anaconda3/envs/sdss_classification_3.7/lib/python3.7/site-packages/sncosmo/models.py"", line 1272, in _flux
    f = a * self._source._flux(phase, restwave)
  File ""/Users/daniel/Github/SDSS-Classification/analysis_pipeline/_sn91bg_model/_model.py"", line 135, in _flux
    y = [self._model_flux[c1](phase / (st / 0.65), wave),
  File ""/anaconda3/envs/sdss_classification_3.7/lib/python3.7/site-packages/scipy/interpolate/fitpack2.py"", line 848, in __call__
    raise ValueError(""Error code returned by bispev: %s"" % ier)"
2006hb 9 26 27 27 28 0 0 26 20 12 15 0 0 0 0 0.0020000000000067867 1007.3475439654349 2.0226619624102457e-14 1.1047312512617806 5.336842079373127e-13 6.237712413008009e-07 0.10449545933971649 2.2308194787828544e-16 0.007745544872083028 5.470672240603935e-06 34658.3397731829 138 "Covariance may not be accurate. Covariance not positive definite. Covariance forced positive definite."
2007hj 13 27 28 28 26 0 0 27 34 36 33 0 14 0 0 nan nan nan nan nan nan nan nan nan nan nan nan "exception was raised in user function
User function arguments:
     z = +0.070603
    t0 = +1323.624799
    x0 = +0.000000
    x1 = -0.096638
     c = +0.999453
Original python exception in user function:
ValueError: Error code returned by bispev: 10
  File ""/anaconda3/envs/sdss_classification_3.7/lib/python3.7/site-packages/sncosmo/fitting.py"", line 46, in chisq
    zp=data.zp, zpsys=data.zpsys)
  File ""/anaconda3/envs/sdss_classification_3.7/lib/python3.7/site-packages/sncosmo/models.py"", line 1400, in bandflux
    raise e
  File ""/anaconda3/envs/sdss_classification_3.7/lib/python3.7/site-packages/sncosmo/models.py"", line 1397, in bandflux
    return _bandflux(self, band, time, zp, zpsys)
  File ""/anaconda3/envs/sdss_classification_3.7/lib/python3.7/site-packages/sncosmo/models.py"", line 154, in _bandflux
    fsum = _bandflux_single(model, b, time_or_phase[mask])
  File ""/anaconda3/envs/sdss_classification_3.7/lib/python3.7/site-packages/sncosmo/models.py"", line 116, in _bandflux_single
    f = model._flux(time_or_phase, wave)
  File ""/anaconda3/envs/sdss_classification_3.7/lib/python3.7/site-packages/sncosmo/models.py"", line 1272, in _flux
    f = a * self._source._flux(phase, restwave)
  File ""/Users/daniel/Github/SDSS-Classification/analysis_pipeline/_sn91bg_model/_model.py"", line 135, in _flux
    y = [self._model_flux[c1](phase / (st / 0.65), wave),
  File ""/anaconda3/envs/sdss_classification_3.7/lib/python3.7/site-packages/scipy/interpolate/fitpack2.py"", line 848, in __call__
    raise ValueError(""Error code returned by bispev: %s"" % ier)"
2008ia 15 11 15 14 16 0 0 15 19 28 18 5 10 0 0 0.002000000000028156 1785.4869396645142 9.595720309361989e-14 0.6286828953911965 3.6988634377621565e-11 8.442792440411248e-06 0.06219018507783858 1.6516425267538702e-15 0.005288741648679846 0.00022133194306969695 139891.63743023982 91 "Covariance may not be accurate. Covariance not positive definite. Covariance forced positive definite."
2007ol 3 7 7 0 7 0 0 7 0 0 0 0 0 0 0 0.002000000093633821 1331.4042356249367 1.0308368343635065e-13 0.9034564563388148 1.0119016735643527e-11 2.601345791029743e-05 1.6084477980163001 8.282412086731789e-16 0.015646105440549632 0.00014208130892109927 3817.826661871306 26 "Covariance may not be accurate. Covariance not positive definite. Covariance forced positive definite."
2008fw 21 24 23 22 23 0 0 24 10 6 7 0 2 0 0 nan nan nan nan nan nan nan nan nan nan nan nan "exception was raised in user function
User function arguments:
     z = +0.002000
    t0 = +1733.965704
    x0 = +0.000000
    x1 = -0.226568
     c = +0.995556
Original python exception in user function:
ValueError: Error code returned by bispev: 10
  File ""/anaconda3/envs/sdss_classification_3.7/lib/python3.7/site-packages/sncosmo/fitting.py"", line 46, in chisq
    zp=data.zp, zpsys=data.zpsys)
  File ""/anaconda3/envs/sdss_classification_3.7/lib/python3.7/site-packages/sncosmo/models.py"", line 1400, in bandflux
    raise e
  File ""/anaconda3/envs/sdss_classification_3.7/lib/python3.7/site-packages/sncosmo/models.py"", line 1397, in bandflux
    return _bandflux(self, band, time, zp, zpsys)
  File ""/anaconda3/envs/sdss_classification_3.7/lib/python3.7/site-packages/sncosmo/models.py"", line 154, in _bandflux
    fsum = _bandflux_single(model, b, time_or_phase[mask])
  File ""/anaconda3/envs/sdss_classification_3.7/lib/python3.7/site-packages/sncosmo/models.py"", line 116, in _bandflux_single
    f = model._flux(time_or_phase, wave)
  File ""/anaconda3/envs/sdss_classification_3.7/lib/python3.7/site-packages/sncosmo/models.py"", line 1272, in _flux
    f = a * self._source._flux(phase, restwave)
  File ""/Users/daniel/Github/SDSS-Classification/analysis_pipeline/_sn91bg_model/_model.py"", line 135, in _flux
    y = [self._model_flux[c1](phase / (st / 0.65), wave),
  File ""/anaconda3/envs/sdss_classification_3.7/lib/python3.7/site-packages/scipy/interpolate/fitpack2.py"", line 848, in __call__
    raise ValueError(""Error code returned by bispev: %s"" % ier)"
2005mc 5 17 17 14 15 7 0 8 0 0 0 0 0 0 0 0.0020000011694915444 735.7867182771522 5.792786299534482e-15 1.0919294885128965 6.657032536327989e-09 9.02705287164976e-06 0.15090831595034615 7.504023662018812e-17 0.011694733516572282 5.985875310990374e-05 4098.912055419048 78 "Covariance may not be accurate. Covariance not positive definite. Covariance forced positive definite."
2009dc 10 10 10 9 10 0 0 10 15 19 4 15 4 0 0 nan nan nan nan nan nan nan nan nan nan nan nan "exception was raised in user function
User function arguments:
     z = +0.002000
    t0 = +1928.256364
    x0 = +0.000000
    x1 = -0.100632
     c = +0.928934
Original python exception in user function:
ValueError: Error code returned by bispev: 10
  File ""/anaconda3/envs/sdss_classification_3.7/lib/python3.7/site-packages/sncosmo/fitting.py"", line 46, in chisq
    zp=data.zp, zpsys=data.zpsys)
  File ""/anaconda3/envs/sdss_classification_3.7/lib/python3.7/site-packages/sncosmo/models.py"", line 1400, in bandflux
    raise e
  File ""/anaconda3/envs/sdss_classification_3.7/lib/python3.7/site-packages/sncosmo/models.py"", line 1397, in bandflux
    return _bandflux(self, band, time, zp, zpsys)
  File ""/anaconda3/envs/sdss_classification_3.7/lib/python3.7/site-packages/sncosmo/models.py"", line 154, in _bandflux
    fsum = _bandflux_single(model, b, time_or_phase[mask])
  File ""/anaconda3/envs/sdss_classification_3.7/lib/python3.7/site-packages/sncosmo/models.py"", line 116, in _bandflux_single
    f = model._flux(time_or_phase, wave)
  File ""/anaconda3/envs/sdss_classification_3.7/lib/python3.7/site-packages/sncosmo/models.py"", line 1272, in _flux
    f = a * self._source._flux(phase, restwave)
  File ""/Users/daniel/Github/SDSS-Classification/analysis_pipeline/_sn91bg_model/_model.py"", line 135, in _flux
    y = [self._model_flux[c1](phase / (st / 0.65), wave),
  File ""/anaconda3/envs/sdss_classification_3.7/lib/python3.7/site-packages/scipy/interpolate/fitpack2.py"", line 848, in __call__
    raise ValueError(""Error code returned by bispev: %s"" % ier)"
2009F 9 13 16 16 17 0 0 18 10 14 8 10 8 0 0 0.07770920618629 1843.0293020188567 1.0650995052092097e-14 0.8884344571199367 0.14244218784119056 0.00025151530386410825 0.021848955755899624 1.0202008109800212e-16 0.006174181969036562 0.0052125885283417495 12791.6236479484 92 "Covariance may not be accurate. Covariance not positive definite. Covariance forced positive definite."
2008go 6 6 6 6 6 0 0 6 7 0 0 0 0 0 0 0.002000000000179547 1661.2600011477666 8.861332624004035e-14 1.1453299591060253 9.998113448261847e-13 5.072588269233952e-06 0.3714277480515875 4.691942898380851e-16 0.002104671207777542 1.8499617062350815e-05 26435.68376357446 31 "Minimization exited successfully."
2008cf 6 13 13 13 13 0 0 13 9 10 1 0 5 0 0 nan nan nan nan nan nan nan nan nan nan nan nan "exception was raised in user function
User function arguments:
     z = +0.002000
    t0 = +1608.404665
    x0 = +0.000000
    x1 = -0.551991
     c = +0.988019
Original python exception in user function:
ValueError: Error code returned by bispev: 10
  File ""/anaconda3/envs/sdss_classification_3.7/lib/python3.7/site-packages/sncosmo/fitting.py"", line 46, in chisq
    zp=data.zp, zpsys=data.zpsys)
  File ""/anaconda3/envs/sdss_classification_3.7/lib/python3.7/site-packages/sncosmo/models.py"", line 1400, in bandflux
    raise e
  File ""/anaconda3/envs/sdss_classification_3.7/lib/python3.7/site-packages/sncosmo/models.py"", line 1397, in bandflux
    return _bandflux(self, band, time, zp, zpsys)
  File ""/anaconda3/envs/sdss_classification_3.7/lib/python3.7/site-packages/sncosmo/models.py"", line 154, in _bandflux
    fsum = _bandflux_single(model, b, time_or_phase[mask])
  File ""/anaconda3/envs/sdss_classification_3.7/lib/python3.7/site-packages/sncosmo/models.py"", line 116, in _bandflux_single
    f = model._flux(time_or_phase, wave)
  File ""/anaconda3/envs/sdss_classification_3.7/lib/python3.7/site-packages/sncosmo/models.py"", line 1272, in _flux
    f = a * self._source._flux(phase, restwave)
  File ""/Users/daniel/Github/SDSS-Classification/analysis_pipeline/_sn91bg_model/_model.py"", line 135, in _flux
    y = [self._model_flux[c1](phase / (st / 0.65), wave),
  File ""/anaconda3/envs/sdss_classification_3.7/lib/python3.7/site-packages/scipy/interpolate/fitpack2.py"", line 848, in __call__
    raise ValueError(""Error code returned by bispev: %s"" % ier)"
2006bd 0 8 8 8 5 0 0 8 4 4 7 0 0 0 0 0.018998911358968446 825.2875545456168 3.4017549306640217e-15 0.8898066368438632 0.4266254818752176 0.0003682196272924605 0.04167212938250486 6.825162873709174e-17 0.014687467360573617 0.014699496465751305 270.5930516531274 32 "Covariance may not be accurate. Covariance not positive definite. Covariance forced positive definite."
2007bm 7 8 7 10 10 0 0 10 3 14 16 0 0 0 0 0.0020000000000263683 1226.4297209027604 9.508897341918995e-14 1.3345140356156144 0.08043472227068399 2.8904282038935344e-06 0.029141537006012186 8.060339784118398e-16 0.003970265785408665 0.005408309347964019 51131.79537750593 47 "Covariance may not be accurate. Covariance not positive definite. Covariance forced positive definite."
2006kf 9 16 20 19 17 0 0 20 24 18 27 0 10 0 0 0.002000000000971365 1040.2420244357108 9.692735091160264e-15 1.154427446771542 9.46864808781811e-12 9.853850130850036e-07 0.010561232608665705 1.1312030105167844e-16 0.015206641035521232 9.404650745975518e-06 35764.414589916894 106 "Covariance may not be accurate. Covariance not positive definite. Covariance forced positive definite."
2008bt 8 14 14 14 13 0 0 14 5 1 1 0 0 0 0 0.0020000000034684656 1572.717303903217 1.3988958656586788e-14 0.9692919896013166 0.21399536621659854 0.0003091080702127939 0.01817258271080391 1.8989781143006545e-16 0.007703340215050214 0.008745296012162812 2684.9471829001996 72 "Covariance may not be accurate. Covariance not positive definite. Covariance forced positive definite."
2006mr 18 28 27 30 29 0 0 28 24 18 17 0 2 0 0 0.00200000005947604 1051.5506049099004 8.027991659129706e-14 0.8300729611663904 0.39108087884646536 3.096286310460758e-06 0.008638900243454373 1.332428847117503e-15 0.007335535179274352 0.008148156159262981 15863.624156455482 157 "Covariance may not be accurate. Covariance not positive definite. Covariance forced positive definite."
2007le 21 23 25 25 25 0 0 25 25 32 33 0 8 0 0 0.0020000000002900788 1398.7423931885733 1.1084377741462912e-13 1.74381729619791 5.232658750742303e-11 7.053113037225334e-07 0.034499327518346945 4.696014669572198e-16 0.004822623925761843 9.413480747066938e-06 141769.01108322555 147 "Minimization exited successfully."
2008hu 7 12 16 16 12 0 0 14 10 3 5 0 2 0 0 0.0020000000049983564 1787.4137215522226 2.2769221872531414e-14 0.47801515976453207 3.912314916476589e-12 6.847803489571898e-06 0.1730121522734862 5.239272857438266e-16 0.0037243721863696655 1.9682539797422072e-05 29053.68924353552 74 "Covariance may not be accurate. Covariance not positive definite. Covariance forced positive definite."
2009J 3 7 7 7 6 0 0 7 4 0 0 0 0 0 0 nan nan nan nan nan nan nan nan nan nan nan nan "exception was raised in user function
User function arguments:
     z = +0.002309
    t0 = +1849.463537
    x0 = +0.000000
    x1 = -0.016746
     c = +0.550000
Original python exception in user function:
ValueError: Error code returned by bispev: 10
  File ""/anaconda3/envs/sdss_classification_3.7/lib/python3.7/site-packages/sncosmo/fitting.py"", line 46, in chisq
    zp=data.zp, zpsys=data.zpsys)
  File ""/anaconda3/envs/sdss_classification_3.7/lib/python3.7/site-packages/sncosmo/models.py"", line 1400, in bandflux
    raise e
  File ""/anaconda3/envs/sdss_classification_3.7/lib/python3.7/site-packages/sncosmo/models.py"", line 1397, in bandflux
    return _bandflux(self, band, time, zp, zpsys)
  File ""/anaconda3/envs/sdss_classification_3.7/lib/python3.7/site-packages/sncosmo/models.py"", line 154, in _bandflux
    fsum = _bandflux_single(model, b, time_or_phase[mask])
  File ""/anaconda3/envs/sdss_classification_3.7/lib/python3.7/site-packages/sncosmo/models.py"", line 116, in _bandflux_single
    f = model._flux(time_or_phase, wave)
  File ""/anaconda3/envs/sdss_classification_3.7/lib/python3.7/site-packages/sncosmo/models.py"", line 1272, in _flux
    f = a * self._source._flux(phase, restwave)
  File ""/Users/daniel/Github/SDSS-Classification/analysis_pipeline/_sn91bg_model/_model.py"", line 135, in _flux
    y = [self._model_flux[c1](phase / (st / 0.65), wave),
  File ""/anaconda3/envs/sdss_classification_3.7/lib/python3.7/site-packages/scipy/interpolate/fitpack2.py"", line 848, in __call__
    raise ValueError(""Error code returned by bispev: %s"" % ier)"
2007N 3 20 21 22 20 0 0 22 20 14 14 0 9 0 0 0.002000000005853808 1124.5863922932497 1.2731711938637446e-14 0.8800495225987437 0.9455364932908347 2.2376891708174047e-06 0.07141117113906148 2.0521194359251492e-16 0.006581396689779352 0.012202223938901247 8067.561963066708 112 "Covariance may not be accurate. Covariance not positive definite. Covariance forced positive definite."
2006ob 2 8 13 12 5 0 0 10 7 2 2 0 2 0 0 0.0020000000000291096 1038.119546656093 1.8688859279653088e-14 0.5727445811879575 7.016548453364635e-11 4.9148778943947265e-06 0.32181007285942087 6.998349803198041e-16 0.007946822851667078 3.687912566624485e-05 17687.82919115632 47 "Covariance may not be accurate. Covariance not positive definite. Covariance forced positive definite."
2006bh 17 18 18 19 19 0 0 19 20 19 22 0 4 0 0 nan nan nan nan nan nan nan nan nan nan nan nan "exception was raised in user function
User function arguments:
     z = +0.002000
    t0 = +775.142163
    x0 = +0.000000
    x1 = -1.043545
     c = +0.999787
Original python exception in user function:
ValueError: Error code returned by bispev: 10
  File ""/anaconda3/envs/sdss_classification_3.7/lib/python3.7/site-packages/sncosmo/fitting.py"", line 46, in chisq
    zp=data.zp, zpsys=data.zpsys)
  File ""/anaconda3/envs/sdss_classification_3.7/lib/python3.7/site-packages/sncosmo/models.py"", line 1400, in bandflux
    raise e
  File ""/anaconda3/envs/sdss_classification_3.7/lib/python3.7/site-packages/sncosmo/models.py"", line 1397, in bandflux
    return _bandflux(self, band, time, zp, zpsys)
  File ""/anaconda3/envs/sdss_classification_3.7/lib/python3.7/site-packages/sncosmo/models.py"", line 154, in _bandflux
    fsum = _bandflux_single(model, b, time_or_phase[mask])
  File ""/anaconda3/envs/sdss_classification_3.7/lib/python3.7/site-packages/sncosmo/models.py"", line 116, in _bandflux_single
    f = model._flux(time_or_phase, wave)
  File ""/anaconda3/envs/sdss_classification_3.7/lib/python3.7/site-packages/sncosmo/models.py"", line 1272, in _flux
    f = a * self._source._flux(phase, restwave)
  File ""/Users/daniel/Github/SDSS-Classification/analysis_pipeline/_sn91bg_model/_model.py"", line 135, in _flux
    y = [self._model_flux[c1](phase / (st / 0.65), wave),
  File ""/anaconda3/envs/sdss_classification_3.7/lib/python3.7/site-packages/scipy/interpolate/fitpack2.py"", line 848, in __call__
    raise ValueError(""Error code returned by bispev: %s"" % ier)"
2007ba 6 17 13 12 16 0 0 17 21 6 11 0 5 0 0 nan nan nan nan nan nan nan nan nan nan nan nan "exception was raised in user function
User function arguments:
     z = +0.002010
    t0 = +1174.882440
    x0 = +0.000000
    x1 = -1.575563
     c = +0.704071
Original python exception in user function:
ValueError: Error code returned by bispev: 10
  File ""/anaconda3/envs/sdss_classification_3.7/lib/python3.7/site-packages/sncosmo/fitting.py"", line 46, in chisq
    zp=data.zp, zpsys=data.zpsys)
  File ""/anaconda3/envs/sdss_classification_3.7/lib/python3.7/site-packages/sncosmo/models.py"", line 1400, in bandflux
    raise e
  File ""/anaconda3/envs/sdss_classification_3.7/lib/python3.7/site-packages/sncosmo/models.py"", line 1397, in bandflux
    return _bandflux(self, band, time, zp, zpsys)
  File ""/anaconda3/envs/sdss_classification_3.7/lib/python3.7/site-packages/sncosmo/models.py"", line 154, in _bandflux
    fsum = _bandflux_single(model, b, time_or_phase[mask])
  File ""/anaconda3/envs/sdss_classification_3.7/lib/python3.7/site-packages/sncosmo/models.py"", line 116, in _bandflux_single
    f = model._flux(time_or_phase, wave)
  File ""/anaconda3/envs/sdss_classification_3.7/lib/python3.7/site-packages/sncosmo/models.py"", line 1272, in _flux
    f = a * self._source._flux(phase, restwave)
  File ""/Users/daniel/Github/SDSS-Classification/analysis_pipeline/_sn91bg_model/_model.py"", line 135, in _flux
    y = [self._model_flux[c1](phase / (st / 0.65), wave),
  File ""/anaconda3/envs/sdss_classification_3.7/lib/python3.7/site-packages/scipy/interpolate/fitpack2.py"", line 848, in __call__
    raise ValueError(""Error code returned by bispev: %s"" % ier)"
2008fp 27 29 28 29 29 0 0 30 26 42 41 0 19 0 0 0.002000000000000235 1729.3876824938668 1.4208797563355852e-13 1.4833952621363928 0.35434529334055154 4.424531490931395e-07 0.014626618587158191 9.970203365845448e-16 0.005597497979885716 0.0036975052516600437 227942.8697332272 186 "Covariance may not be accurate. Covariance not positive definite. Covariance forced positive definite."
2005na 16 25 27 27 26 5 0 19 6 9 5 0 5 0 0 0.002000000000331919 716.6213174518268 7.126450830885208e-14 0.7710197062524644 2.785699448892842e-11 8.811388874517719e-07 0.15134942971235432 9.388121137090851e-16 0.004132812158943108 5.961294989531574e-06 278907.9956935042 145 "Covariance may not be accurate. Covariance not positive definite. Covariance forced positive definite."
2008R 10 11 12 13 10 0 0 12 15 9 14 0 1 0 0 0.0020000000004022976 1477.0083289716606 2.520996855315647e-13 0.461701329677329 7.943645741192995e-14 3.6948761598775554e-06 0.035551531632336264 4.60990065997533e-16 0.0005620920091921964 1.8851850208972953e-05 187933.36581445695 64 "Minimization exited successfully."
2005bg 15 15 15 16 17 17 0 0 0 0 0 0 0 0 0 nan nan nan nan nan nan nan nan nan nan nan nan "exception was raised in user function
User function arguments:
     z = +0.002000
    t0 = +458.566916
    x0 = +0.000000
    x1 = -9.345771
     c = +0.986410
Original python exception in user function:
ValueError: Error code returned by bispev: 10
  File ""/anaconda3/envs/sdss_classification_3.7/lib/python3.7/site-packages/sncosmo/fitting.py"", line 46, in chisq
    zp=data.zp, zpsys=data.zpsys)
  File ""/anaconda3/envs/sdss_classification_3.7/lib/python3.7/site-packages/sncosmo/models.py"", line 1400, in bandflux
    raise e
  File ""/anaconda3/envs/sdss_classification_3.7/lib/python3.7/site-packages/sncosmo/models.py"", line 1397, in bandflux
    return _bandflux(self, band, time, zp, zpsys)
  File ""/anaconda3/envs/sdss_classification_3.7/lib/python3.7/site-packages/sncosmo/models.py"", line 154, in _bandflux
    fsum = _bandflux_single(model, b, time_or_phase[mask])
  File ""/anaconda3/envs/sdss_classification_3.7/lib/python3.7/site-packages/sncosmo/models.py"", line 116, in _bandflux_single
    f = model._flux(time_or_phase, wave)
  File ""/anaconda3/envs/sdss_classification_3.7/lib/python3.7/site-packages/sncosmo/models.py"", line 1272, in _flux
    f = a * self._source._flux(phase, restwave)
  File ""/Users/daniel/Github/SDSS-Classification/analysis_pipeline/_sn91bg_model/_model.py"", line 135, in _flux
    y = [self._model_flux[c1](phase / (st / 0.65), wave),
  File ""/anaconda3/envs/sdss_classification_3.7/lib/python3.7/site-packages/scipy/interpolate/fitpack2.py"", line 848, in __call__
    raise ValueError(""Error code returned by bispev: %s"" % ier)"
2005ke 33 38 36 38 38 21 0 15 39 49 48 0 12 0 0 0.002000000000000005 698.4756077459631 9.542042180746427e-14 1.0145900948100266 0.20503728803815996 7.62805855957123e-07 0.009879561728553199 8.885624859077793e-16 0.003450541552100107 0.004450331940008406 70516.88583999814 226 "Covariance may not be accurate. Covariance not positive definite. Covariance forced positive definite."
2007cg 3 7 7 7 4 0 0 8 5 0 0 0 4 0 0 0.0020000000101785312 1229.296417769714 3.306279416084647e-15 2.13991213341275 0.3551588235357789 8.494106004819021e-06 0.2376171797537836 5.565632631732948e-17 0.030327576978024663 0.011011359384845987 3150.1035358079826 35 "Covariance may not be accurate. Covariance not positive definite. Covariance forced positive definite."
2004gu 12 24 29 28 26 26 0 0 0 2 3 0 6 0 0 nan nan nan nan nan nan nan nan nan nan nan nan "exception was raised in user function
User function arguments:
     z = +0.043399
    t0 = +260.438951
    x0 = -0.000000
    x1 = -0.352761
     c = +0.565101
Original python exception in user function:
ValueError: Error code returned by bispev: 10
  File ""/anaconda3/envs/sdss_classification_3.7/lib/python3.7/site-packages/sncosmo/fitting.py"", line 46, in chisq
    zp=data.zp, zpsys=data.zpsys)
  File ""/anaconda3/envs/sdss_classification_3.7/lib/python3.7/site-packages/sncosmo/models.py"", line 1400, in bandflux
    raise e
  File ""/anaconda3/envs/sdss_classification_3.7/lib/python3.7/site-packages/sncosmo/models.py"", line 1397, in bandflux
    return _bandflux(self, band, time, zp, zpsys)
  File ""/anaconda3/envs/sdss_classification_3.7/lib/python3.7/site-packages/sncosmo/models.py"", line 154, in _bandflux
    fsum = _bandflux_single(model, b, time_or_phase[mask])
  File ""/anaconda3/envs/sdss_classification_3.7/lib/python3.7/site-packages/sncosmo/models.py"", line 116, in _bandflux_single
    f = model._flux(time_or_phase, wave)
  File ""/anaconda3/envs/sdss_classification_3.7/lib/python3.7/site-packages/sncosmo/models.py"", line 1272, in _flux
    f = a * self._source._flux(phase, restwave)
  File ""/Users/daniel/Github/SDSS-Classification/analysis_pipeline/_sn91bg_model/_model.py"", line 135, in _flux
    y = [self._model_flux[c1](phase / (st / 0.65), wave),
  File ""/anaconda3/envs/sdss_classification_3.7/lib/python3.7/site-packages/scipy/interpolate/fitpack2.py"", line 848, in __call__
    raise ValueError(""Error code returned by bispev: %s"" % ier)"
2007jd 2 11 0 14 10 0 0 10 0 0 0 0 3 0 0 0.002000000565577654 1363.3225405294936 1.1338804407506222e-15 1.1161042507723944 9.8616190213896e-09 3.3807259793177703e-06 0.24455418005322827 2.565461618550288e-17 0.038174750080415897 3.773667341427922e-05 1234.9366649445215 45 "Covariance may not be accurate. Covariance not positive definite. Covariance forced positive definite."
2007hx 2 10 0 11 9 0 0 9 0 0 0 0 3 0 0 0.0020000000955921055 1334.8705074767815 1.0244096484133593e-14 0.4917271737234418 3.123853953290734e-10 7.777404437048782e-06 0.30153916459050834 5.0529015391831e-16 0.007814534275223805 6.564103701536816e-05 5082.666647357115 39 "Covariance may not be accurate. Covariance not positive definite. Covariance forced positive definite."
2008ha 7 14 18 18 12 0 0 17 7 7 6 0 0 0 0 0.07342792831904392 1784.7841675798795 3.2506646015259566e-15 0.963084064787422 1.3279100041785341e-11 0.0006990012675342494 0.09164133317074175 4.376230057581644e-17 0.015431760320571843 1.447037196483647e-05 2921.6531956610856 81 "Covariance may not be accurate. Covariance not positive definite. Covariance forced positive definite."
2005hj 5 16 16 16 14 14 0 1 13 0 7 0 0 0 0 nan nan nan nan nan nan nan nan nan nan nan nan "exception was raised in user function
User function arguments:
     z = +0.002051
    t0 = +676.695320
    x0 = +0.000000
    x1 = -0.741597
     c = +0.550000
Original python exception in user function:
ValueError: Error code returned by bispev: 10
  File ""/anaconda3/envs/sdss_classification_3.7/lib/python3.7/site-packages/sncosmo/fitting.py"", line 46, in chisq
    zp=data.zp, zpsys=data.zpsys)
  File ""/anaconda3/envs/sdss_classification_3.7/lib/python3.7/site-packages/sncosmo/models.py"", line 1400, in bandflux
    raise e
  File ""/anaconda3/envs/sdss_classification_3.7/lib/python3.7/site-packages/sncosmo/models.py"", line 1397, in bandflux
    return _bandflux(self, band, time, zp, zpsys)
  File ""/anaconda3/envs/sdss_classification_3.7/lib/python3.7/site-packages/sncosmo/models.py"", line 154, in _bandflux
    fsum = _bandflux_single(model, b, time_or_phase[mask])
  File ""/anaconda3/envs/sdss_classification_3.7/lib/python3.7/site-packages/sncosmo/models.py"", line 116, in _bandflux_single
    f = model._flux(time_or_phase, wave)
  File ""/anaconda3/envs/sdss_classification_3.7/lib/python3.7/site-packages/sncosmo/models.py"", line 1272, in _flux
    f = a * self._source._flux(phase, restwave)
  File ""/Users/daniel/Github/SDSS-Classification/analysis_pipeline/_sn91bg_model/_model.py"", line 135, in _flux
    y = [self._model_flux[c1](phase / (st / 0.65), wave),
  File ""/anaconda3/envs/sdss_classification_3.7/lib/python3.7/site-packages/scipy/interpolate/fitpack2.py"", line 848, in __call__
    raise ValueError(""Error code returned by bispev: %s"" % ier)"
2005hk 18 24 24 24 24 22 0 1 23 37 40 0 8 0 0 nan nan nan nan nan nan nan nan nan nan nan nan "exception was raised in user function
User function arguments:
     z = +0.082750
    t0 = +685.954840
    x0 = +0.000000
    x1 = -0.072399
     c = +0.999959
Original python exception in user function:
ValueError: Error code returned by bispev: 10
  File ""/anaconda3/envs/sdss_classification_3.7/lib/python3.7/site-packages/sncosmo/fitting.py"", line 46, in chisq
    zp=data.zp, zpsys=data.zpsys)
  File ""/anaconda3/envs/sdss_classification_3.7/lib/python3.7/site-packages/sncosmo/models.py"", line 1400, in bandflux
    raise e
  File ""/anaconda3/envs/sdss_classification_3.7/lib/python3.7/site-packages/sncosmo/models.py"", line 1397, in bandflux
    return _bandflux(self, band, time, zp, zpsys)
  File ""/anaconda3/envs/sdss_classification_3.7/lib/python3.7/site-packages/sncosmo/models.py"", line 154, in _bandflux
    fsum = _bandflux_single(model, b, time_or_phase[mask])
  File ""/anaconda3/envs/sdss_classification_3.7/lib/python3.7/site-packages/sncosmo/models.py"", line 116, in _bandflux_single
    f = model._flux(time_or_phase, wave)
  File ""/anaconda3/envs/sdss_classification_3.7/lib/python3.7/site-packages/sncosmo/models.py"", line 1272, in _flux
    f = a * self._source._flux(phase, restwave)
  File ""/Users/daniel/Github/SDSS-Classification/analysis_pipeline/_sn91bg_model/_model.py"", line 135, in _flux
    y = [self._model_flux[c1](phase / (st / 0.65), wave),
  File ""/anaconda3/envs/sdss_classification_3.7/lib/python3.7/site-packages/scipy/interpolate/fitpack2.py"", line 848, in __call__
    raise ValueError(""Error code returned by bispev: %s"" % ier)"
2005ir 8 10 0 13 12 12 0 0 0 0 0 0 0 0 0 nan nan nan nan nan nan nan nan nan nan nan nan "exception was raised in user function
User function arguments:
     z = +0.002000
    t0 = +671.596184
    x0 = +0.000000
    x1 = -0.703124
     c = +0.996601
Original python exception in user function:
ValueError: Error code returned by bispev: 10
  File ""/anaconda3/envs/sdss_classification_3.7/lib/python3.7/site-packages/sncosmo/fitting.py"", line 46, in chisq
    zp=data.zp, zpsys=data.zpsys)
  File ""/anaconda3/envs/sdss_classification_3.7/lib/python3.7/site-packages/sncosmo/models.py"", line 1400, in bandflux
    raise e
  File ""/anaconda3/envs/sdss_classification_3.7/lib/python3.7/site-packages/sncosmo/models.py"", line 1397, in bandflux
    return _bandflux(self, band, time, zp, zpsys)
  File ""/anaconda3/envs/sdss_classification_3.7/lib/python3.7/site-packages/sncosmo/models.py"", line 154, in _bandflux
    fsum = _bandflux_single(model, b, time_or_phase[mask])
  File ""/anaconda3/envs/sdss_classification_3.7/lib/python3.7/site-packages/sncosmo/models.py"", line 116, in _bandflux_single
    f = model._flux(time_or_phase, wave)
  File ""/anaconda3/envs/sdss_classification_3.7/lib/python3.7/site-packages/sncosmo/models.py"", line 1272, in _flux
    f = a * self._source._flux(phase, restwave)
  File ""/Users/daniel/Github/SDSS-Classification/analysis_pipeline/_sn91bg_model/_model.py"", line 135, in _flux
    y = [self._model_flux[c1](phase / (st / 0.65), wave),
  File ""/anaconda3/envs/sdss_classification_3.7/lib/python3.7/site-packages/scipy/interpolate/fitpack2.py"", line 848, in __call__
    raise ValueError(""Error code returned by bispev: %s"" % ier)"
2005bl 7 11 11 12 11 12 0 0 0 0 0 0 0 0 0 0.01490692401754107 482.8542315983907 3.9820004738470896e-15 0.9609641760743779 0.3758464184873988 0.0008597106028479396 0.023264364459379294 6.125050949039752e-17 0.00862530615578444 0.009033748645193684 893.7764854469644 59 "Covariance may not be accurate. Covariance not positive definite. Covariance forced positive definite."
2005M 38 59 56 55 55 57 0 0 0 20 21 0 20 0 0 nan nan nan nan nan nan nan nan nan nan nan nan "exception was raised in user function
User function arguments:
     z = +0.002000
    t0 = +406.842119
    x0 = +0.000000
    x1 = -2.002815
     c = +0.978897
Original python exception in user function:
ValueError: Error code returned by bispev: 10
  File ""/anaconda3/envs/sdss_classification_3.7/lib/python3.7/site-packages/sncosmo/fitting.py"", line 46, in chisq
    zp=data.zp, zpsys=data.zpsys)
  File ""/anaconda3/envs/sdss_classification_3.7/lib/python3.7/site-packages/sncosmo/models.py"", line 1400, in bandflux
    raise e
  File ""/anaconda3/envs/sdss_classification_3.7/lib/python3.7/site-packages/sncosmo/models.py"", line 1397, in bandflux
    return _bandflux(self, band, time, zp, zpsys)
  File ""/anaconda3/envs/sdss_classification_3.7/lib/python3.7/site-packages/sncosmo/models.py"", line 154, in _bandflux
    fsum = _bandflux_single(model, b, time_or_phase[mask])
  File ""/anaconda3/envs/sdss_classification_3.7/lib/python3.7/site-packages/sncosmo/models.py"", line 116, in _bandflux_single
    f = model._flux(time_or_phase, wave)
  File ""/anaconda3/envs/sdss_classification_3.7/lib/python3.7/site-packages/sncosmo/models.py"", line 1272, in _flux
    f = a * self._source._flux(phase, restwave)
  File ""/Users/daniel/Github/SDSS-Classification/analysis_pipeline/_sn91bg_model/_model.py"", line 135, in _flux
    y = [self._model_flux[c1](phase / (st / 0.65), wave),
  File ""/anaconda3/envs/sdss_classification_3.7/lib/python3.7/site-packages/scipy/interpolate/fitpack2.py"", line 848, in __call__
    raise ValueError(""Error code returned by bispev: %s"" % ier)"
2008bf 20 27 27 27 27 0 0 27 10 5 10 0 4 0 0 nan nan nan nan nan nan nan nan nan nan nan nan "exception was raised in user function
User function arguments:
     z = +0.002000
    t0 = +1550.926019
    x0 = +0.000000
    x1 = -1.139523
     c = +0.985390
Original python exception in user function:
ValueError: Error code returned by bispev: 10
  File ""/anaconda3/envs/sdss_classification_3.7/lib/python3.7/site-packages/sncosmo/fitting.py"", line 46, in chisq
    zp=data.zp, zpsys=data.zpsys)
  File ""/anaconda3/envs/sdss_classification_3.7/lib/python3.7/site-packages/sncosmo/models.py"", line 1400, in bandflux
    raise e
  File ""/anaconda3/envs/sdss_classification_3.7/lib/python3.7/site-packages/sncosmo/models.py"", line 1397, in bandflux
    return _bandflux(self, band, time, zp, zpsys)
  File ""/anaconda3/envs/sdss_classification_3.7/lib/python3.7/site-packages/sncosmo/models.py"", line 154, in _bandflux
    fsum = _bandflux_single(model, b, time_or_phase[mask])
  File ""/anaconda3/envs/sdss_classification_3.7/lib/python3.7/site-packages/sncosmo/models.py"", line 116, in _bandflux_single
    f = model._flux(time_or_phase, wave)
  File ""/anaconda3/envs/sdss_classification_3.7/lib/python3.7/site-packages/sncosmo/models.py"", line 1272, in _flux
    f = a * self._source._flux(phase, restwave)
  File ""/Users/daniel/Github/SDSS-Classification/analysis_pipeline/_sn91bg_model/_model.py"", line 135, in _flux
    y = [self._model_flux[c1](phase / (st / 0.65), wave),
  File ""/anaconda3/envs/sdss_classification_3.7/lib/python3.7/site-packages/scipy/interpolate/fitpack2.py"", line 848, in __call__
    raise ValueError(""Error code returned by bispev: %s"" % ier)"
2006eq 2 10 15 14 12 0 0 12 14 3 11 0 5 0 0 nan nan nan nan nan nan nan nan nan nan nan nan "exception was raised in user function
User function arguments:
     z = +0.081937
    t0 = +975.486171
    x0 = +0.000000
    x1 = -0.029173
     c = +0.946232
Original python exception in user function:
ValueError: Error code returned by bispev: 10
  File ""/anaconda3/envs/sdss_classification_3.7/lib/python3.7/site-packages/sncosmo/fitting.py"", line 46, in chisq
    zp=data.zp, zpsys=data.zpsys)
  File ""/anaconda3/envs/sdss_classification_3.7/lib/python3.7/site-packages/sncosmo/models.py"", line 1400, in bandflux
    raise e
  File ""/anaconda3/envs/sdss_classification_3.7/lib/python3.7/site-packages/sncosmo/models.py"", line 1397, in bandflux
    return _bandflux(self, band, time, zp, zpsys)
  File ""/anaconda3/envs/sdss_classification_3.7/lib/python3.7/site-packages/sncosmo/models.py"", line 154, in _bandflux
    fsum = _bandflux_single(model, b, time_or_phase[mask])
  File ""/anaconda3/envs/sdss_classification_3.7/lib/python3.7/site-packages/sncosmo/models.py"", line 116, in _bandflux_single
    f = model._flux(time_or_phase, wave)
  File ""/anaconda3/envs/sdss_classification_3.7/lib/python3.7/site-packages/sncosmo/models.py"", line 1272, in _flux
    f = a * self._source._flux(phase, restwave)
  File ""/Users/daniel/Github/SDSS-Classification/analysis_pipeline/_sn91bg_model/_model.py"", line 135, in _flux
    y = [self._model_flux[c1](phase / (st / 0.65), wave),
  File ""/anaconda3/envs/sdss_classification_3.7/lib/python3.7/site-packages/scipy/interpolate/fitpack2.py"", line 848, in __call__
    raise ValueError(""Error code returned by bispev: %s"" % ier)"
2009aa 16 22 22 22 22 0 0 22 32 32 5 31 6 0 0 nan nan nan nan nan nan nan nan nan nan nan nan "exception was raised in user function
User function arguments:
     z = +0.002051
    t0 = +1875.473537
    x0 = +0.000000
    x1 = -0.000000
     c = +0.550000
Original python exception in user function:
ValueError: Error code returned by bispev: 10
  File ""/anaconda3/envs/sdss_classification_3.7/lib/python3.7/site-packages/sncosmo/fitting.py"", line 46, in chisq
    zp=data.zp, zpsys=data.zpsys)
  File ""/anaconda3/envs/sdss_classification_3.7/lib/python3.7/site-packages/sncosmo/models.py"", line 1400, in bandflux
    raise e
  File ""/anaconda3/envs/sdss_classification_3.7/lib/python3.7/site-packages/sncosmo/models.py"", line 1397, in bandflux
    return _bandflux(self, band, time, zp, zpsys)
  File ""/anaconda3/envs/sdss_classification_3.7/lib/python3.7/site-packages/sncosmo/models.py"", line 154, in _bandflux
    fsum = _bandflux_single(model, b, time_or_phase[mask])
  File ""/anaconda3/envs/sdss_classification_3.7/lib/python3.7/site-packages/sncosmo/models.py"", line 116, in _bandflux_single
    f = model._flux(time_or_phase, wave)
  File ""/anaconda3/envs/sdss_classification_3.7/lib/python3.7/site-packages/sncosmo/models.py"", line 1272, in _flux
    f = a * self._source._flux(phase, restwave)
  File ""/Users/daniel/Github/SDSS-Classification/analysis_pipeline/_sn91bg_model/_model.py"", line 135, in _flux
    y = [self._model_flux[c1](phase / (st / 0.65), wave),
  File ""/anaconda3/envs/sdss_classification_3.7/lib/python3.7/site-packages/scipy/interpolate/fitpack2.py"", line 848, in __call__
    raise ValueError(""Error code returned by bispev: %s"" % ier)"
2008hj 14 16 16 16 16 0 0 16 18 6 7 0 2 0 0 nan nan nan nan nan nan nan nan nan nan nan nan "exception was raised in user function
User function arguments:
     z = +0.002051
    t0 = +1802.363537
    x0 = +0.000000
    x1 = -0.024090
     c = +0.550000
Original python exception in user function:
ValueError: Error code returned by bispev: 10
  File ""/anaconda3/envs/sdss_classification_3.7/lib/python3.7/site-packages/sncosmo/fitting.py"", line 46, in chisq
    zp=data.zp, zpsys=data.zpsys)
  File ""/anaconda3/envs/sdss_classification_3.7/lib/python3.7/site-packages/sncosmo/models.py"", line 1400, in bandflux
    raise e
  File ""/anaconda3/envs/sdss_classification_3.7/lib/python3.7/site-packages/sncosmo/models.py"", line 1397, in bandflux
    return _bandflux(self, band, time, zp, zpsys)
  File ""/anaconda3/envs/sdss_classification_3.7/lib/python3.7/site-packages/sncosmo/models.py"", line 154, in _bandflux
    fsum = _bandflux_single(model, b, time_or_phase[mask])
  File ""/anaconda3/envs/sdss_classification_3.7/lib/python3.7/site-packages/sncosmo/models.py"", line 116, in _bandflux_single
    f = model._flux(time_or_phase, wave)
  File ""/anaconda3/envs/sdss_classification_3.7/lib/python3.7/site-packages/sncosmo/models.py"", line 1272, in _flux
    f = a * self._source._flux(phase, restwave)
  File ""/Users/daniel/Github/SDSS-Classification/analysis_pipeline/_sn91bg_model/_model.py"", line 135, in _flux
    y = [self._model_flux[c1](phase / (st / 0.65), wave),
  File ""/anaconda3/envs/sdss_classification_3.7/lib/python3.7/site-packages/scipy/interpolate/fitpack2.py"", line 848, in __call__
    raise ValueError(""Error code returned by bispev: %s"" % ier)"
2006ax 18 22 22 23 25 0 0 25 29 31 35 0 6 0 0 nan nan nan nan nan nan nan nan nan nan nan nan "exception was raised in user function
User function arguments:
     z = +0.002000
    t0 = +823.481218
    x0 = +0.000000
    x1 = -1.399612
     c = +0.999555
Original python exception in user function:
ValueError: Error code returned by bispev: 10
  File ""/anaconda3/envs/sdss_classification_3.7/lib/python3.7/site-packages/sncosmo/fitting.py"", line 46, in chisq
    zp=data.zp, zpsys=data.zpsys)
  File ""/anaconda3/envs/sdss_classification_3.7/lib/python3.7/site-packages/sncosmo/models.py"", line 1400, in bandflux
    raise e
  File ""/anaconda3/envs/sdss_classification_3.7/lib/python3.7/site-packages/sncosmo/models.py"", line 1397, in bandflux
    return _bandflux(self, band, time, zp, zpsys)
  File ""/anaconda3/envs/sdss_classification_3.7/lib/python3.7/site-packages/sncosmo/models.py"", line 154, in _bandflux
    fsum = _bandflux_single(model, b, time_or_phase[mask])
  File ""/anaconda3/envs/sdss_classification_3.7/lib/python3.7/site-packages/sncosmo/models.py"", line 116, in _bandflux_single
    f = model._flux(time_or_phase, wave)
  File ""/anaconda3/envs/sdss_classification_3.7/lib/python3.7/site-packages/sncosmo/models.py"", line 1272, in _flux
    f = a * self._source._flux(phase, restwave)
  File ""/Users/daniel/Github/SDSS-Classification/analysis_pipeline/_sn91bg_model/_model.py"", line 135, in _flux
    y = [self._model_flux[c1](phase / (st / 0.65), wave),
  File ""/anaconda3/envs/sdss_classification_3.7/lib/python3.7/site-packages/scipy/interpolate/fitpack2.py"", line 848, in __call__
    raise ValueError(""Error code returned by bispev: %s"" % ier)"
2009D 20 21 21 21 21 0 0 21 13 14 6 12 6 0 0 nan nan nan nan nan nan nan nan nan nan nan nan "exception was raised in user function
User function arguments:
     z = +0.002000
    t0 = +1843.970521
    x0 = +0.000000
    x1 = -0.352225
     c = +0.979722
Original python exception in user function:
ValueError: Error code returned by bispev: 10
  File ""/anaconda3/envs/sdss_classification_3.7/lib/python3.7/site-packages/sncosmo/fitting.py"", line 46, in chisq
    zp=data.zp, zpsys=data.zpsys)
  File ""/anaconda3/envs/sdss_classification_3.7/lib/python3.7/site-packages/sncosmo/models.py"", line 1400, in bandflux
    raise e
  File ""/anaconda3/envs/sdss_classification_3.7/lib/python3.7/site-packages/sncosmo/models.py"", line 1397, in bandflux
    return _bandflux(self, band, time, zp, zpsys)
  File ""/anaconda3/envs/sdss_classification_3.7/lib/python3.7/site-packages/sncosmo/models.py"", line 154, in _bandflux
    fsum = _bandflux_single(model, b, time_or_phase[mask])
  File ""/anaconda3/envs/sdss_classification_3.7/lib/python3.7/site-packages/sncosmo/models.py"", line 116, in _bandflux_single
    f = model._flux(time_or_phase, wave)
  File ""/anaconda3/envs/sdss_classification_3.7/lib/python3.7/site-packages/sncosmo/models.py"", line 1272, in _flux
    f = a * self._source._flux(phase, restwave)
  File ""/Users/daniel/Github/SDSS-Classification/analysis_pipeline/_sn91bg_model/_model.py"", line 135, in _flux
    y = [self._model_flux[c1](phase / (st / 0.65), wave),
  File ""/anaconda3/envs/sdss_classification_3.7/lib/python3.7/site-packages/scipy/interpolate/fitpack2.py"", line 848, in __call__
    raise ValueError(""Error code returned by bispev: %s"" % ier)"
2008gl 16 22 22 22 19 0 0 22 20 8 15 0 0 0 0 0.002000000110168392 1744.416149119402 4.753895915564139e-14 0.6578701128091996 2.0058954497415016e-11 6.703132318052179e-07 0.14332378915355548 6.239700391945082e-16 0.003479717442491007 4.935382609538852e-06 236721.3542103063 118 "Covariance may not be accurate. Covariance not positive definite. Covariance forced positive definite."
2008cd 0 5 4 5 4 0 0 5 0 0 0 0 0 0 0 nan nan nan nan nan nan nan nan nan nan nan nan "exception was raised in user function
User function arguments:
     z = +0.084548
    t0 = +1579.806299
    x0 = +0.000000
    x1 = -1.246750
     c = +0.840455
Original python exception in user function:
ValueError: Error code returned by bispev: 10
  File ""/anaconda3/envs/sdss_classification_3.7/lib/python3.7/site-packages/sncosmo/fitting.py"", line 46, in chisq
    zp=data.zp, zpsys=data.zpsys)
  File ""/anaconda3/envs/sdss_classification_3.7/lib/python3.7/site-packages/sncosmo/models.py"", line 1400, in bandflux
    raise e
  File ""/anaconda3/envs/sdss_classification_3.7/lib/python3.7/site-packages/sncosmo/models.py"", line 1397, in bandflux
    return _bandflux(self, band, time, zp, zpsys)
  File ""/anaconda3/envs/sdss_classification_3.7/lib/python3.7/site-packages/sncosmo/models.py"", line 154, in _bandflux
    fsum = _bandflux_single(model, b, time_or_phase[mask])
  File ""/anaconda3/envs/sdss_classification_3.7/lib/python3.7/site-packages/sncosmo/models.py"", line 116, in _bandflux_single
    f = model._flux(time_or_phase, wave)
  File ""/anaconda3/envs/sdss_classification_3.7/lib/python3.7/site-packages/sncosmo/models.py"", line 1272, in _flux
    f = a * self._source._flux(phase, restwave)
  File ""/Users/daniel/Github/SDSS-Classification/analysis_pipeline/_sn91bg_model/_model.py"", line 135, in _flux
    y = [self._model_flux[c1](phase / (st / 0.65), wave),
  File ""/anaconda3/envs/sdss_classification_3.7/lib/python3.7/site-packages/scipy/interpolate/fitpack2.py"", line 848, in __call__
    raise ValueError(""Error code returned by bispev: %s"" % ier)"
2007A 5 6 8 10 8 0 0 8 18 3 10 0 0 0 0 0.0020000000056056657 1113.8510240520131 1.9662944797776482e-13 0.13896114503641038 9.708900350346994e-14 5.9914796371714554e-06 0.0010854829140498623 5.48957962295531e-16 0.00013986282572061616 1.8288913937708484e-05 260306.19422604257 40 "Minimization exited successfully."
2008ar 8 18 18 18 18 0 0 18 16 7 7 0 4 0 0 0.002000000000056989 1491.3395315798937 7.829288127731055e-14 0.9782293197981583 1.5709655798445965e-14 5.211762256573807e-06 0.31631053921239527 1.3835234248451476e-15 0.0053729348065698675 1.6236231328903283e-05 136090.33401383087 97 "Covariance may not be accurate. Covariance not positive definite. Covariance forced positive definite."
2006X 19 34 33 34 35 0 0 36 23 42 40 0 16 0 0 0.0020000000034772563 786.4129168929453 2.0927242781415002e-13 1.5387383579426632 0.9570413957798602 1.6325347623510466e-06 0.01346042133411629 1.6047675670436172e-15 0.004424596030558771 0.004206426128943175 128766.39766749679 202 "Covariance may not be accurate. Covariance not positive definite. Covariance forced positive definite."
2006ej 5 13 5 6 12 0 0 13 3 2 5 0 0 0 0 0.00200000004046894 970.0323779143498 7.365479589091947e-14 0.5217654488951394 5.374268807756266e-10 3.8658969519916615e-06 0.09831283343550012 1.773214375502067e-15 0.005480533317904565 3.001355622977986e-05 42136.43832724925 49 "Covariance may not be accurate. Covariance not positive definite. Covariance forced positive definite."
2005eq 19 27 27 27 27 26 0 0 25 13 19 0 1 0 0 nan nan nan nan nan nan nan nan nan nan nan nan "exception was raised in user function
User function arguments:
     z = +0.002000
    t0 = +590.536232
    x0 = +0.000000
    x1 = -1.211130
     c = +0.983095
Original python exception in user function:
ValueError: Error code returned by bispev: 10
  File ""/anaconda3/envs/sdss_classification_3.7/lib/python3.7/site-packages/sncosmo/fitting.py"", line 46, in chisq
    zp=data.zp, zpsys=data.zpsys)
  File ""/anaconda3/envs/sdss_classification_3.7/lib/python3.7/site-packages/sncosmo/models.py"", line 1400, in bandflux
    raise e
  File ""/anaconda3/envs/sdss_classification_3.7/lib/python3.7/site-packages/sncosmo/models.py"", line 1397, in bandflux
    return _bandflux(self, band, time, zp, zpsys)
  File ""/anaconda3/envs/sdss_classification_3.7/lib/python3.7/site-packages/sncosmo/models.py"", line 154, in _bandflux
    fsum = _bandflux_single(model, b, time_or_phase[mask])
  File ""/anaconda3/envs/sdss_classification_3.7/lib/python3.7/site-packages/sncosmo/models.py"", line 116, in _bandflux_single
    f = model._flux(time_or_phase, wave)
  File ""/anaconda3/envs/sdss_classification_3.7/lib/python3.7/site-packages/sncosmo/models.py"", line 1272, in _flux
    f = a * self._source._flux(phase, restwave)
  File ""/Users/daniel/Github/SDSS-Classification/analysis_pipeline/_sn91bg_model/_model.py"", line 135, in _flux
    y = [self._model_flux[c1](phase / (st / 0.65), wave),
  File ""/anaconda3/envs/sdss_classification_3.7/lib/python3.7/site-packages/scipy/interpolate/fitpack2.py"", line 848, in __call__
    raise ValueError(""Error code returned by bispev: %s"" % ier)"
2008gg 18 26 26 26 26 0 0 26 20 14 12 0 4 0 0 nan nan nan nan nan nan nan nan nan nan nan nan "exception was raised in user function
User function arguments:
     z = +0.002000
    t0 = +1729.390147
    x0 = +0.000000
    x1 = -0.892985
     c = +0.996773
Original python exception in user function:
ValueError: Error code returned by bispev: 10
  File ""/anaconda3/envs/sdss_classification_3.7/lib/python3.7/site-packages/sncosmo/fitting.py"", line 46, in chisq
    zp=data.zp, zpsys=data.zpsys)
  File ""/anaconda3/envs/sdss_classification_3.7/lib/python3.7/site-packages/sncosmo/models.py"", line 1400, in bandflux
    raise e
  File ""/anaconda3/envs/sdss_classification_3.7/lib/python3.7/site-packages/sncosmo/models.py"", line 1397, in bandflux
    return _bandflux(self, band, time, zp, zpsys)
  File ""/anaconda3/envs/sdss_classification_3.7/lib/python3.7/site-packages/sncosmo/models.py"", line 154, in _bandflux
    fsum = _bandflux_single(model, b, time_or_phase[mask])
  File ""/anaconda3/envs/sdss_classification_3.7/lib/python3.7/site-packages/sncosmo/models.py"", line 116, in _bandflux_single
    f = model._flux(time_or_phase, wave)
  File ""/anaconda3/envs/sdss_classification_3.7/lib/python3.7/site-packages/sncosmo/models.py"", line 1272, in _flux
    f = a * self._source._flux(phase, restwave)
  File ""/Users/daniel/Github/SDSS-Classification/analysis_pipeline/_sn91bg_model/_model.py"", line 135, in _flux
    y = [self._model_flux[c1](phase / (st / 0.65), wave),
  File ""/anaconda3/envs/sdss_classification_3.7/lib/python3.7/site-packages/scipy/interpolate/fitpack2.py"", line 848, in __call__
    raise ValueError(""Error code returned by bispev: %s"" % ier)"
2004ey 25 26 32 32 30 30 0 0 0 14 14 0 10 0 0 nan nan nan nan nan nan nan nan nan nan nan nan "exception was raised in user function
User function arguments:
     z = +0.002000
    t0 = +300.355178
    x0 = +0.000000
    x1 = -4.084281
     c = +0.998764
Original python exception in user function:
ValueError: Error code returned by bispev: 10
  File ""/anaconda3/envs/sdss_classification_3.7/lib/python3.7/site-packages/sncosmo/fitting.py"", line 46, in chisq
    zp=data.zp, zpsys=data.zpsys)
  File ""/anaconda3/envs/sdss_classification_3.7/lib/python3.7/site-packages/sncosmo/models.py"", line 1400, in bandflux
    raise e
  File ""/anaconda3/envs/sdss_classification_3.7/lib/python3.7/site-packages/sncosmo/models.py"", line 1397, in bandflux
    return _bandflux(self, band, time, zp, zpsys)
  File ""/anaconda3/envs/sdss_classification_3.7/lib/python3.7/site-packages/sncosmo/models.py"", line 154, in _bandflux
    fsum = _bandflux_single(model, b, time_or_phase[mask])
  File ""/anaconda3/envs/sdss_classification_3.7/lib/python3.7/site-packages/sncosmo/models.py"", line 116, in _bandflux_single
    f = model._flux(time_or_phase, wave)
  File ""/anaconda3/envs/sdss_classification_3.7/lib/python3.7/site-packages/sncosmo/models.py"", line 1272, in _flux
    f = a * self._source._flux(phase, restwave)
  File ""/Users/daniel/Github/SDSS-Classification/analysis_pipeline/_sn91bg_model/_model.py"", line 135, in _flux
    y = [self._model_flux[c1](phase / (st / 0.65), wave),
  File ""/anaconda3/envs/sdss_classification_3.7/lib/python3.7/site-packages/scipy/interpolate/fitpack2.py"", line 848, in __call__
    raise ValueError(""Error code returned by bispev: %s"" % ier)"
2010ae 0 2 2 2 1 0 0 2 9 14 8 9 8 0 0 0.013948191686217934 2252.353047661364 1.983267086799076e-14 0.8395439858905727 0.9999991354728818 0.017256217530124296 0.10401027032457932 1.2665320168630082e-15 0.023782665028824323 0.0032227699159576573 276.1487811158843 12 "Covariance may not be accurate. Covariance not positive definite. Covariance forced positive definite."
2007ux 7 17 17 16 17 0 0 22 15 16 10 0 14 0 0 nan nan nan nan nan nan nan nan nan nan nan nan "exception was raised in user function
User function arguments:
     z = +0.056663
    t0 = +1449.365855
    x0 = +0.000000
    x1 = -4.619474
     c = +0.997199
Original python exception in user function:
ValueError: Error code returned by bispev: 10
  File ""/anaconda3/envs/sdss_classification_3.7/lib/python3.7/site-packages/sncosmo/fitting.py"", line 46, in chisq
    zp=data.zp, zpsys=data.zpsys)
  File ""/anaconda3/envs/sdss_classification_3.7/lib/python3.7/site-packages/sncosmo/models.py"", line 1400, in bandflux
    raise e
  File ""/anaconda3/envs/sdss_classification_3.7/lib/python3.7/site-packages/sncosmo/models.py"", line 1397, in bandflux
    return _bandflux(self, band, time, zp, zpsys)
  File ""/anaconda3/envs/sdss_classification_3.7/lib/python3.7/site-packages/sncosmo/models.py"", line 154, in _bandflux
    fsum = _bandflux_single(model, b, time_or_phase[mask])
  File ""/anaconda3/envs/sdss_classification_3.7/lib/python3.7/site-packages/sncosmo/models.py"", line 116, in _bandflux_single
    f = model._flux(time_or_phase, wave)
  File ""/anaconda3/envs/sdss_classification_3.7/lib/python3.7/site-packages/sncosmo/models.py"", line 1272, in _flux
    f = a * self._source._flux(phase, restwave)
  File ""/Users/daniel/Github/SDSS-Classification/analysis_pipeline/_sn91bg_model/_model.py"", line 135, in _flux
    y = [self._model_flux[c1](phase / (st / 0.65), wave),
  File ""/anaconda3/envs/sdss_classification_3.7/lib/python3.7/site-packages/scipy/interpolate/fitpack2.py"", line 848, in __call__
    raise ValueError(""Error code returned by bispev: %s"" % ier)"
2005W 16 20 21 19 20 21 0 0 0 0 0 0 0 0 0 nan nan nan nan nan nan nan nan nan nan nan nan "exception was raised in user function
User function arguments:
     z = +0.002051
    t0 = +417.426834
    x0 = +0.000000
    x1 = -1.071500
     c = +0.550000
Original python exception in user function:
ValueError: Error code returned by bispev: 10
  File ""/anaconda3/envs/sdss_classification_3.7/lib/python3.7/site-packages/sncosmo/fitting.py"", line 46, in chisq
    zp=data.zp, zpsys=data.zpsys)
  File ""/anaconda3/envs/sdss_classification_3.7/lib/python3.7/site-packages/sncosmo/models.py"", line 1400, in bandflux
    raise e
  File ""/anaconda3/envs/sdss_classification_3.7/lib/python3.7/site-packages/sncosmo/models.py"", line 1397, in bandflux
    return _bandflux(self, band, time, zp, zpsys)
  File ""/anaconda3/envs/sdss_classification_3.7/lib/python3.7/site-packages/sncosmo/models.py"", line 154, in _bandflux
    fsum = _bandflux_single(model, b, time_or_phase[mask])
  File ""/anaconda3/envs/sdss_classification_3.7/lib/python3.7/site-packages/sncosmo/models.py"", line 116, in _bandflux_single
    f = model._flux(time_or_phase, wave)
  File ""/anaconda3/envs/sdss_classification_3.7/lib/python3.7/site-packages/sncosmo/models.py"", line 1272, in _flux
    f = a * self._source._flux(phase, restwave)
  File ""/Users/daniel/Github/SDSS-Classification/analysis_pipeline/_sn91bg_model/_model.py"", line 135, in _flux
    y = [self._model_flux[c1](phase / (st / 0.65), wave),
  File ""/anaconda3/envs/sdss_classification_3.7/lib/python3.7/site-packages/scipy/interpolate/fitpack2.py"", line 848, in __call__
    raise ValueError(""Error code returned by bispev: %s"" % ier)"
2007on 33 17 26 23 31 0 0 23 38 49 49 0 19 0 0 0.002000000000211619 1418.9483275459108 3.002063539955325e-13 0.9564590299934498 6.5597527409977374e-12 5.139636410002747e-07 0.009684173241112148 6.987461691670816e-16 0.0014790978808162081 4.802520960522916e-06 107783.95581800892 167 "Minimization exited successfully."
2005ku 3 6 7 7 5 6 0 0 3 0 0 0 0 0 0 nan nan nan nan nan nan nan nan nan nan nan nan "exception was raised in user function
User function arguments:
     z = +0.081000
    t0 = +694.034014
    x0 = +0.000000
    x1 = -0.466449
     c = +0.550000
Original python exception in user function:
ValueError: Error code returned by bispev: 10
  File ""/anaconda3/envs/sdss_classification_3.7/lib/python3.7/site-packages/sncosmo/fitting.py"", line 46, in chisq
    zp=data.zp, zpsys=data.zpsys)
  File ""/anaconda3/envs/sdss_classification_3.7/lib/python3.7/site-packages/sncosmo/models.py"", line 1400, in bandflux
    raise e
  File ""/anaconda3/envs/sdss_classification_3.7/lib/python3.7/site-packages/sncosmo/models.py"", line 1397, in bandflux
    return _bandflux(self, band, time, zp, zpsys)
  File ""/anaconda3/envs/sdss_classification_3.7/lib/python3.7/site-packages/sncosmo/models.py"", line 154, in _bandflux
    fsum = _bandflux_single(model, b, time_or_phase[mask])
  File ""/anaconda3/envs/sdss_classification_3.7/lib/python3.7/site-packages/sncosmo/models.py"", line 116, in _bandflux_single
    f = model._flux(time_or_phase, wave)
  File ""/anaconda3/envs/sdss_classification_3.7/lib/python3.7/site-packages/sncosmo/models.py"", line 1272, in _flux
    f = a * self._source._flux(phase, restwave)
  File ""/Users/daniel/Github/SDSS-Classification/analysis_pipeline/_sn91bg_model/_model.py"", line 135, in _flux
    y = [self._model_flux[c1](phase / (st / 0.65), wave),
  File ""/anaconda3/envs/sdss_classification_3.7/lib/python3.7/site-packages/scipy/interpolate/fitpack2.py"", line 848, in __call__
    raise ValueError(""Error code returned by bispev: %s"" % ier)"
2008fu 3 14 19 17 8 0 0 20 10 4 3 0 5 0 0 nan nan nan nan nan nan nan nan nan nan nan nan "exception was raised in user function
User function arguments:
     z = +0.073229
    t0 = +1692.529312
    x0 = +0.000000
    x1 = -0.296808
     c = +0.964342
Original python exception in user function:
ValueError: Error code returned by bispev: 10
  File ""/anaconda3/envs/sdss_classification_3.7/lib/python3.7/site-packages/sncosmo/fitting.py"", line 46, in chisq
    zp=data.zp, zpsys=data.zpsys)
  File ""/anaconda3/envs/sdss_classification_3.7/lib/python3.7/site-packages/sncosmo/models.py"", line 1400, in bandflux
    raise e
  File ""/anaconda3/envs/sdss_classification_3.7/lib/python3.7/site-packages/sncosmo/models.py"", line 1397, in bandflux
    return _bandflux(self, band, time, zp, zpsys)
  File ""/anaconda3/envs/sdss_classification_3.7/lib/python3.7/site-packages/sncosmo/models.py"", line 154, in _bandflux
    fsum = _bandflux_single(model, b, time_or_phase[mask])
  File ""/anaconda3/envs/sdss_classification_3.7/lib/python3.7/site-packages/sncosmo/models.py"", line 116, in _bandflux_single
    f = model._flux(time_or_phase, wave)
  File ""/anaconda3/envs/sdss_classification_3.7/lib/python3.7/site-packages/sncosmo/models.py"", line 1272, in _flux
    f = a * self._source._flux(phase, restwave)
  File ""/Users/daniel/Github/SDSS-Classification/analysis_pipeline/_sn91bg_model/_model.py"", line 135, in _flux
    y = [self._model_flux[c1](phase / (st / 0.65), wave),
  File ""/anaconda3/envs/sdss_classification_3.7/lib/python3.7/site-packages/scipy/interpolate/fitpack2.py"", line 848, in __call__
    raise ValueError(""Error code returned by bispev: %s"" % ier)"
2007bd 8 12 12 12 12 0 0 12 20 9 10 0 3 0 0 nan nan nan nan nan nan nan nan nan nan nan nan "exception was raised in user function
User function arguments:
     z = +0.067712
    t0 = +1200.548577
    x0 = +0.000000
    x1 = -1.269528
     c = +0.998462
Original python exception in user function:
ValueError: Error code returned by bispev: 10
  File ""/anaconda3/envs/sdss_classification_3.7/lib/python3.7/site-packages/sncosmo/fitting.py"", line 46, in chisq
    zp=data.zp, zpsys=data.zpsys)
  File ""/anaconda3/envs/sdss_classification_3.7/lib/python3.7/site-packages/sncosmo/models.py"", line 1400, in bandflux
    raise e
  File ""/anaconda3/envs/sdss_classification_3.7/lib/python3.7/site-packages/sncosmo/models.py"", line 1397, in bandflux
    return _bandflux(self, band, time, zp, zpsys)
  File ""/anaconda3/envs/sdss_classification_3.7/lib/python3.7/site-packages/sncosmo/models.py"", line 154, in _bandflux
    fsum = _bandflux_single(model, b, time_or_phase[mask])
  File ""/anaconda3/envs/sdss_classification_3.7/lib/python3.7/site-packages/sncosmo/models.py"", line 116, in _bandflux_single
    f = model._flux(time_or_phase, wave)
  File ""/anaconda3/envs/sdss_classification_3.7/lib/python3.7/site-packages/sncosmo/models.py"", line 1272, in _flux
    f = a * self._source._flux(phase, restwave)
  File ""/Users/daniel/Github/SDSS-Classification/analysis_pipeline/_sn91bg_model/_model.py"", line 135, in _flux
    y = [self._model_flux[c1](phase / (st / 0.65), wave),
  File ""/anaconda3/envs/sdss_classification_3.7/lib/python3.7/site-packages/scipy/interpolate/fitpack2.py"", line 848, in __call__
    raise ValueError(""Error code returned by bispev: %s"" % ier)"
2006is 13 27 26 25 28 0 0 28 5 9 9 0 6 0 0 0.002000000002192434 1013.3909821307843 8.983233131890456e-15 1.7382418682062846 2.3457180642338926e-11 1.2078231972131176e-07 0.11125157644863748 7.355203297340355e-17 0.010784533190042335 1.067160879747453e-06 175252.58459030685 148 "Covariance may not be accurate. Covariance not positive definite. Covariance forced positive definite."
2008bc 29 22 16 22 30 0 0 23 14 18 21 0 10 0 0 0.002000000000007496 1549.631984987165 2.6422106083674787e-14 1.5280765389566349 1.0337841693797145e-12 2.4438500228476587e-07 0.019909093900764674 2.1331975513582373e-16 0.01484514693688774 1.561810727968016e-06 171763.0037593199 147 "Covariance may not be accurate. Covariance not positive definite. Covariance forced positive definite."
2007mm 0 8 9 8 6 0 0 8 0 0 0 0 0 0 0 0.012729240105046606 1391.6149832700821 8.472974068954206e-16 1.043889537724752 0.19991872242896364 0.0006929703725170903 0.023247983273563477 1.2382722361529073e-17 0.01215143056319691 0.010915932692573155 351.68966223555196 34 "Covariance may not be accurate. Covariance not positive definite. Covariance forced positive definite."
2008C 6 16 20 18 11 0 0 15 3 12 14 0 6 0 0 0.002000000003602454 1469.5791257700844 1.7793201317526502e-14 1.4812703679348307 9.982030757527127e-10 2.3134295249935787e-06 0.20270092013458907 3.5679310772677006e-16 0.03029906940341777 6.151300114295988e-05 36573.559125980595 87 "Covariance may not be accurate. Covariance not positive definite. Covariance forced positive definite."
2004dt 43 46 45 43 46 46 0 0 0 0 0 0 0 0 0 0.0020000000006820695 247.472876073784 1.9780255437412196e-14 1.656766853754486 6.039058142448539e-13 6.083066776208304e-07 0.07486360194550912 1.1976246937856915e-16 0.006561605594181365 3.385884376677639e-06 101700.61782879592 264 "Covariance may not be accurate. Covariance not positive definite. Covariance forced positive definite."
2006br 0 8 10 10 7 0 0 8 7 4 10 0 0 0 0 0.0020000021231226122 852.5283261775587 2.5104917350816053e-15 1.8304370291055636 0.4386563215987375 9.611350199666439e-06 0.2217119878279732 4.2397630815673915e-17 0.02491689244120531 0.010436544561048783 1171.6161438757817 38 "Covariance may not be accurate. Covariance not positive definite. Covariance forced positive definite."
2005ag 0 41 0 36 35 43 0 0 0 0 0 0 5 0 0 nan nan nan nan nan nan nan nan nan nan nan nan "exception was raised in user function
User function arguments:
     z = +0.002000
    t0 = +400.757763
    x0 = +0.000000
    x1 = -0.381432
     c = +0.825324
Original python exception in user function:
ValueError: Error code returned by bispev: 10
  File ""/anaconda3/envs/sdss_classification_3.7/lib/python3.7/site-packages/sncosmo/fitting.py"", line 46, in chisq
    zp=data.zp, zpsys=data.zpsys)
  File ""/anaconda3/envs/sdss_classification_3.7/lib/python3.7/site-packages/sncosmo/models.py"", line 1400, in bandflux
    raise e
  File ""/anaconda3/envs/sdss_classification_3.7/lib/python3.7/site-packages/sncosmo/models.py"", line 1397, in bandflux
    return _bandflux(self, band, time, zp, zpsys)
  File ""/anaconda3/envs/sdss_classification_3.7/lib/python3.7/site-packages/sncosmo/models.py"", line 154, in _bandflux
    fsum = _bandflux_single(model, b, time_or_phase[mask])
  File ""/anaconda3/envs/sdss_classification_3.7/lib/python3.7/site-packages/sncosmo/models.py"", line 116, in _bandflux_single
    f = model._flux(time_or_phase, wave)
  File ""/anaconda3/envs/sdss_classification_3.7/lib/python3.7/site-packages/sncosmo/models.py"", line 1272, in _flux
    f = a * self._source._flux(phase, restwave)
  File ""/Users/daniel/Github/SDSS-Classification/analysis_pipeline/_sn91bg_model/_model.py"", line 135, in _flux
    y = [self._model_flux[c1](phase / (st / 0.65), wave),
  File ""/anaconda3/envs/sdss_classification_3.7/lib/python3.7/site-packages/scipy/interpolate/fitpack2.py"", line 848, in __call__
    raise ValueError(""Error code returned by bispev: %s"" % ier)"
2007sr 15 29 29 29 29 0 0 30 23 31 35 0 9 0 0 nan nan nan nan nan nan nan nan nan nan nan nan "exception was raised in user function
User function arguments:
     z = +0.002000
    t0 = +1422.196742
    x0 = +0.000000
    x1 = -0.238857
     c = +0.996419
Original python exception in user function:
ValueError: Error code returned by bispev: 10
  File ""/anaconda3/envs/sdss_classification_3.7/lib/python3.7/site-packages/sncosmo/fitting.py"", line 46, in chisq
    zp=data.zp, zpsys=data.zpsys)
  File ""/anaconda3/envs/sdss_classification_3.7/lib/python3.7/site-packages/sncosmo/models.py"", line 1400, in bandflux
    raise e
  File ""/anaconda3/envs/sdss_classification_3.7/lib/python3.7/site-packages/sncosmo/models.py"", line 1397, in bandflux
    return _bandflux(self, band, time, zp, zpsys)
  File ""/anaconda3/envs/sdss_classification_3.7/lib/python3.7/site-packages/sncosmo/models.py"", line 154, in _bandflux
    fsum = _bandflux_single(model, b, time_or_phase[mask])
  File ""/anaconda3/envs/sdss_classification_3.7/lib/python3.7/site-packages/sncosmo/models.py"", line 116, in _bandflux_single
    f = model._flux(time_or_phase, wave)
  File ""/anaconda3/envs/sdss_classification_3.7/lib/python3.7/site-packages/sncosmo/models.py"", line 1272, in _flux
    f = a * self._source._flux(phase, restwave)
  File ""/Users/daniel/Github/SDSS-Classification/analysis_pipeline/_sn91bg_model/_model.py"", line 135, in _flux
    y = [self._model_flux[c1](phase / (st / 0.65), wave),
  File ""/anaconda3/envs/sdss_classification_3.7/lib/python3.7/site-packages/scipy/interpolate/fitpack2.py"", line 848, in __call__
    raise ValueError(""Error code returned by bispev: %s"" % ier)"
2009ad 12 12 12 12 12 0 0 12 22 17 0 17 0 0 0 nan nan nan nan nan nan nan nan nan nan nan nan "exception was raised in user function
User function arguments:
     z = +0.002000
    t0 = +1900.604300
    x0 = +0.000000
    x1 = -0.253664
     c = +0.990308
Original python exception in user function:
ValueError: Error code returned by bispev: 10
  File ""/anaconda3/envs/sdss_classification_3.7/lib/python3.7/site-packages/sncosmo/fitting.py"", line 46, in chisq
    zp=data.zp, zpsys=data.zpsys)
  File ""/anaconda3/envs/sdss_classification_3.7/lib/python3.7/site-packages/sncosmo/models.py"", line 1400, in bandflux
    raise e
  File ""/anaconda3/envs/sdss_classification_3.7/lib/python3.7/site-packages/sncosmo/models.py"", line 1397, in bandflux
    return _bandflux(self, band, time, zp, zpsys)
  File ""/anaconda3/envs/sdss_classification_3.7/lib/python3.7/site-packages/sncosmo/models.py"", line 154, in _bandflux
    fsum = _bandflux_single(model, b, time_or_phase[mask])
  File ""/anaconda3/envs/sdss_classification_3.7/lib/python3.7/site-packages/sncosmo/models.py"", line 116, in _bandflux_single
    f = model._flux(time_or_phase, wave)
  File ""/anaconda3/envs/sdss_classification_3.7/lib/python3.7/site-packages/sncosmo/models.py"", line 1272, in _flux
    f = a * self._source._flux(phase, restwave)
  File ""/Users/daniel/Github/SDSS-Classification/analysis_pipeline/_sn91bg_model/_model.py"", line 135, in _flux
    y = [self._model_flux[c1](phase / (st / 0.65), wave),
  File ""/anaconda3/envs/sdss_classification_3.7/lib/python3.7/site-packages/scipy/interpolate/fitpack2.py"", line 848, in __call__
    raise ValueError(""Error code returned by bispev: %s"" % ier)"
2006et 17 24 24 22 21 0 0 23 35 32 34 0 4 0 0 nan nan nan nan nan nan nan nan nan nan nan nan "exception was raised in user function
User function arguments:
     z = +0.002000
    t0 = +992.002322
    x0 = +0.000000
    x1 = -0.572635
     c = +0.995506
Original python exception in user function:
ValueError: Error code returned by bispev: 10
  File ""/anaconda3/envs/sdss_classification_3.7/lib/python3.7/site-packages/sncosmo/fitting.py"", line 46, in chisq
    zp=data.zp, zpsys=data.zpsys)
  File ""/anaconda3/envs/sdss_classification_3.7/lib/python3.7/site-packages/sncosmo/models.py"", line 1400, in bandflux
    raise e
  File ""/anaconda3/envs/sdss_classification_3.7/lib/python3.7/site-packages/sncosmo/models.py"", line 1397, in bandflux
    return _bandflux(self, band, time, zp, zpsys)
  File ""/anaconda3/envs/sdss_classification_3.7/lib/python3.7/site-packages/sncosmo/models.py"", line 154, in _bandflux
    fsum = _bandflux_single(model, b, time_or_phase[mask])
  File ""/anaconda3/envs/sdss_classification_3.7/lib/python3.7/site-packages/sncosmo/models.py"", line 116, in _bandflux_single
    f = model._flux(time_or_phase, wave)
  File ""/anaconda3/envs/sdss_classification_3.7/lib/python3.7/site-packages/sncosmo/models.py"", line 1272, in _flux
    f = a * self._source._flux(phase, restwave)
  File ""/Users/daniel/Github/SDSS-Classification/analysis_pipeline/_sn91bg_model/_model.py"", line 135, in _flux
    y = [self._model_flux[c1](phase / (st / 0.65), wave),
  File ""/anaconda3/envs/sdss_classification_3.7/lib/python3.7/site-packages/scipy/interpolate/fitpack2.py"", line 848, in __call__
    raise ValueError(""Error code returned by bispev: %s"" % ier)"
2009P 10 14 15 14 15 0 0 14 11 0 0 6 0 0 0 nan nan nan nan nan nan nan nan nan nan nan nan "exception was raised in user function
User function arguments:
     z = +0.002000
    t0 = +1854.762893
    x0 = +0.000000
    x1 = -0.064031
     c = +0.961141
Original python exception in user function:
ValueError: Error code returned by bispev: 10
  File ""/anaconda3/envs/sdss_classification_3.7/lib/python3.7/site-packages/sncosmo/fitting.py"", line 46, in chisq
    zp=data.zp, zpsys=data.zpsys)
  File ""/anaconda3/envs/sdss_classification_3.7/lib/python3.7/site-packages/sncosmo/models.py"", line 1400, in bandflux
    raise e
  File ""/anaconda3/envs/sdss_classification_3.7/lib/python3.7/site-packages/sncosmo/models.py"", line 1397, in bandflux
    return _bandflux(self, band, time, zp, zpsys)
  File ""/anaconda3/envs/sdss_classification_3.7/lib/python3.7/site-packages/sncosmo/models.py"", line 154, in _bandflux
    fsum = _bandflux_single(model, b, time_or_phase[mask])
  File ""/anaconda3/envs/sdss_classification_3.7/lib/python3.7/site-packages/sncosmo/models.py"", line 116, in _bandflux_single
    f = model._flux(time_or_phase, wave)
  File ""/anaconda3/envs/sdss_classification_3.7/lib/python3.7/site-packages/sncosmo/models.py"", line 1272, in _flux
    f = a * self._source._flux(phase, restwave)
  File ""/Users/daniel/Github/SDSS-Classification/analysis_pipeline/_sn91bg_model/_model.py"", line 135, in _flux
    y = [self._model_flux[c1](phase / (st / 0.65), wave),
  File ""/anaconda3/envs/sdss_classification_3.7/lib/python3.7/site-packages/scipy/interpolate/fitpack2.py"", line 848, in __call__
    raise ValueError(""Error code returned by bispev: %s"" % ier)"
2004ef 34 47 47 47 42 44 0 0 0 5 6 0 6 0 0 nan nan nan nan nan nan nan nan nan nan nan nan "exception was raised in user function
User function arguments:
     z = +0.002028
    t0 = +265.998240
    x0 = +0.000000
    x1 = -0.547586
     c = +0.998203
Original python exception in user function:
ValueError: Error code returned by bispev: 10
  File ""/anaconda3/envs/sdss_classification_3.7/lib/python3.7/site-packages/sncosmo/fitting.py"", line 46, in chisq
    zp=data.zp, zpsys=data.zpsys)
  File ""/anaconda3/envs/sdss_classification_3.7/lib/python3.7/site-packages/sncosmo/models.py"", line 1400, in bandflux
    raise e
  File ""/anaconda3/envs/sdss_classification_3.7/lib/python3.7/site-packages/sncosmo/models.py"", line 1397, in bandflux
    return _bandflux(self, band, time, zp, zpsys)
  File ""/anaconda3/envs/sdss_classification_3.7/lib/python3.7/site-packages/sncosmo/models.py"", line 154, in _bandflux
    fsum = _bandflux_single(model, b, time_or_phase[mask])
  File ""/anaconda3/envs/sdss_classification_3.7/lib/python3.7/site-packages/sncosmo/models.py"", line 116, in _bandflux_single
    f = model._flux(time_or_phase, wave)
  File ""/anaconda3/envs/sdss_classification_3.7/lib/python3.7/site-packages/sncosmo/models.py"", line 1272, in _flux
    f = a * self._source._flux(phase, restwave)
  File ""/Users/daniel/Github/SDSS-Classification/analysis_pipeline/_sn91bg_model/_model.py"", line 135, in _flux
    y = [self._model_flux[c1](phase / (st / 0.65), wave),
  File ""/anaconda3/envs/sdss_classification_3.7/lib/python3.7/site-packages/scipy/interpolate/fitpack2.py"", line 848, in __call__
    raise ValueError(""Error code returned by bispev: %s"" % ier)"
2006os 4 13 16 15 9 0 0 14 15 7 9 0 4 0 0 0.00871152519074702 1064.4890879698055 3.6912249709799916e-15 1.4793801176443173 0.10423727507595482 0.000403861187887029 0.12219312480465305 4.255545789696694e-17 0.011941387094601914 0.008346311603693118 4854.578435523136 70 "Covariance may not be accurate. Covariance not positive definite. Covariance forced positive definite."
2008bi 4 10 14 17 7 0 0 14 5 4 4 0 4 0 0 nan nan nan nan nan nan nan nan nan nan nan nan "exception was raised in user function
User function arguments:
     z = +0.016700
    t0 = +1563.729696
    x0 = +0.000000
    x1 = -0.003527
     c = +0.999789
Original python exception in user function:
ValueError: Error code returned by bispev: 10
  File ""/anaconda3/envs/sdss_classification_3.7/lib/python3.7/site-packages/sncosmo/fitting.py"", line 46, in chisq
    zp=data.zp, zpsys=data.zpsys)
  File ""/anaconda3/envs/sdss_classification_3.7/lib/python3.7/site-packages/sncosmo/models.py"", line 1400, in bandflux
    raise e
  File ""/anaconda3/envs/sdss_classification_3.7/lib/python3.7/site-packages/sncosmo/models.py"", line 1397, in bandflux
    return _bandflux(self, band, time, zp, zpsys)
  File ""/anaconda3/envs/sdss_classification_3.7/lib/python3.7/site-packages/sncosmo/models.py"", line 154, in _bandflux
    fsum = _bandflux_single(model, b, time_or_phase[mask])
  File ""/anaconda3/envs/sdss_classification_3.7/lib/python3.7/site-packages/sncosmo/models.py"", line 116, in _bandflux_single
    f = model._flux(time_or_phase, wave)
  File ""/anaconda3/envs/sdss_classification_3.7/lib/python3.7/site-packages/sncosmo/models.py"", line 1272, in _flux
    f = a * self._source._flux(phase, restwave)
  File ""/Users/daniel/Github/SDSS-Classification/analysis_pipeline/_sn91bg_model/_model.py"", line 135, in _flux
    y = [self._model_flux[c1](phase / (st / 0.65), wave),
  File ""/anaconda3/envs/sdss_classification_3.7/lib/python3.7/site-packages/scipy/interpolate/fitpack2.py"", line 848, in __call__
    raise ValueError(""Error code returned by bispev: %s"" % ier)"
2009le 9 9 9 9 9 0 0 9 4 4 0 4 0 0 0 0.0020000000001110436 2187.2717244455926 5.082992684774741e-14 4.350454685587774 7.646105970593453e-13 1.8203359560011161e-06 0.1644481621765408 7.717758143532512e-16 0.01675143223826799 8.931918865168198e-06 20889.629965953285 49 "Covariance may not be accurate. Covariance not positive definite. Covariance forced positive definite."
2005al 35 35 35 35 35 35 0 0 0 10 10 0 8 0 0 0.0020000000001789203 416.1755814589396 1.315297887015023e-13 0.6842250337859752 7.155387393709134e-14 6.936334583621147e-07 0.04314224812998191 1.2830593030322708e-15 0.003063154567244123 5.648546133829591e-06 385627.6155025223 213 "Covariance may not be accurate. Covariance not positive definite. Covariance forced positive definite."
2005am 37 34 21 23 35 31 0 0 0 9 4 0 9 0 0 0.002000000030476816 422.15086532864717 5.038491983026211e-13 0.6287345657690372 0.03266741317583183 1.3645724062801533e-06 0.03651693260707134 4.19354720287439e-15 0.001209569075866986 0.00395206500243489 453253.7300183354 185 "Covariance may not be accurate. Covariance not positive definite. Covariance forced positive definite."
2005iq 14 20 20 19 18 18 0 0 21 12 12 0 0 0 0 nan nan nan nan nan nan nan nan nan nan nan nan "exception was raised in user function
User function arguments:
     z = +0.002000
    t0 = +676.560822
    x0 = +0.000000
    x1 = -32.509002
     c = +0.972550
Original python exception in user function:
ValueError: Error code returned by bispev: 10
  File ""/anaconda3/envs/sdss_classification_3.7/lib/python3.7/site-packages/sncosmo/fitting.py"", line 46, in chisq
    zp=data.zp, zpsys=data.zpsys)
  File ""/anaconda3/envs/sdss_classification_3.7/lib/python3.7/site-packages/sncosmo/models.py"", line 1400, in bandflux
    raise e
  File ""/anaconda3/envs/sdss_classification_3.7/lib/python3.7/site-packages/sncosmo/models.py"", line 1397, in bandflux
    return _bandflux(self, band, time, zp, zpsys)
  File ""/anaconda3/envs/sdss_classification_3.7/lib/python3.7/site-packages/sncosmo/models.py"", line 154, in _bandflux
    fsum = _bandflux_single(model, b, time_or_phase[mask])
  File ""/anaconda3/envs/sdss_classification_3.7/lib/python3.7/site-packages/sncosmo/models.py"", line 116, in _bandflux_single
    f = model._flux(time_or_phase, wave)
  File ""/anaconda3/envs/sdss_classification_3.7/lib/python3.7/site-packages/sncosmo/models.py"", line 1272, in _flux
    f = a * self._source._flux(phase, restwave)
  File ""/Users/daniel/Github/SDSS-Classification/analysis_pipeline/_sn91bg_model/_model.py"", line 135, in _flux
    y = [self._model_flux[c1](phase / (st / 0.65), wave),
  File ""/anaconda3/envs/sdss_classification_3.7/lib/python3.7/site-packages/scipy/interpolate/fitpack2.py"", line 848, in __call__
    raise ValueError(""Error code returned by bispev: %s"" % ier)"
2008bd 0 10 9 16 11 0 0 10 6 1 1 0 2 0 0 0.002000000017444478 1533.7747264964323 3.2789208247757993e-15 1.0295822453113765 0.3923221497601593 1.8535748362150974e-05 0.15226867519947973 6.956339658794859e-17 0.012026628979057407 0.014091628955543944 528.4644844739407 53 "Covariance may not be accurate. Covariance not positive definite. Covariance forced positive definite."
2007S 12 18 19 18 18 0 0 17 20 33 32 0 5 0 0 0.0020000000000152183 1144.1460317711183 2.2189234323717125e-14 1.8797784678049785 1.61009539034751e-11 8.661883153231621e-07 0.07684893562532125 2.5256202724503866e-16 0.02090140352725336 1.1985704066352909e-05 54631.707576521345 102 "Covariance may not be accurate. Covariance not positive definite. Covariance forced positive definite."
2005bo 8 9 9 9 9 10 0 0 0 0 0 0 0 0 0 nan nan nan nan nan nan nan nan nan nan nan nan "exception was raised in user function
User function arguments:
     z = +0.002000
    t0 = +464.787397
    x0 = +0.000000
    x1 = -0.897810
     c = +0.998534
Original python exception in user function:
ValueError: Error code returned by bispev: 10
  File ""/anaconda3/envs/sdss_classification_3.7/lib/python3.7/site-packages/sncosmo/fitting.py"", line 46, in chisq
    zp=data.zp, zpsys=data.zpsys)
  File ""/anaconda3/envs/sdss_classification_3.7/lib/python3.7/site-packages/sncosmo/models.py"", line 1400, in bandflux
    raise e
  File ""/anaconda3/envs/sdss_classification_3.7/lib/python3.7/site-packages/sncosmo/models.py"", line 1397, in bandflux
    return _bandflux(self, band, time, zp, zpsys)
  File ""/anaconda3/envs/sdss_classification_3.7/lib/python3.7/site-packages/sncosmo/models.py"", line 154, in _bandflux
    fsum = _bandflux_single(model, b, time_or_phase[mask])
  File ""/anaconda3/envs/sdss_classification_3.7/lib/python3.7/site-packages/sncosmo/models.py"", line 116, in _bandflux_single
    f = model._flux(time_or_phase, wave)
  File ""/anaconda3/envs/sdss_classification_3.7/lib/python3.7/site-packages/sncosmo/models.py"", line 1272, in _flux
    f = a * self._source._flux(phase, restwave)
  File ""/Users/daniel/Github/SDSS-Classification/analysis_pipeline/_sn91bg_model/_model.py"", line 135, in _flux
    y = [self._model_flux[c1](phase / (st / 0.65), wave),
  File ""/anaconda3/envs/sdss_classification_3.7/lib/python3.7/site-packages/scipy/interpolate/fitpack2.py"", line 848, in __call__
    raise ValueError(""Error code returned by bispev: %s"" % ier)"
2006bt 9 11 11 11 8 0 0 11 9 9 9 0 0 0 0 0.002000000001869113 820.7987541171296 7.385143963642904e-14 0.7914606707750619 3.5138558729386205e-13 1.6696505145293288e-06 0.1895844113126941 1.2746786892856209e-15 0.005239257649004647 1.223684164672334e-05 67864.49233767847 56 "Covariance may not be accurate. Covariance not positive definite. Covariance forced positive definite."
2008fl 20 23 23 23 23 0 0 23 13 15 16 0 7 0 0 nan nan nan nan nan nan nan nan nan nan nan nan "exception was raised in user function
User function arguments:
     z = +0.002000
    t0 = +1694.353437
    x0 = +0.000000
    x1 = -0.820900
     c = +0.620030
Original python exception in user function:
ValueError: Error code returned by bispev: 10
  File ""/anaconda3/envs/sdss_classification_3.7/lib/python3.7/site-packages/sncosmo/fitting.py"", line 46, in chisq
    zp=data.zp, zpsys=data.zpsys)
  File ""/anaconda3/envs/sdss_classification_3.7/lib/python3.7/site-packages/sncosmo/models.py"", line 1400, in bandflux
    raise e
  File ""/anaconda3/envs/sdss_classification_3.7/lib/python3.7/site-packages/sncosmo/models.py"", line 1397, in bandflux
    return _bandflux(self, band, time, zp, zpsys)
  File ""/anaconda3/envs/sdss_classification_3.7/lib/python3.7/site-packages/sncosmo/models.py"", line 154, in _bandflux
    fsum = _bandflux_single(model, b, time_or_phase[mask])
  File ""/anaconda3/envs/sdss_classification_3.7/lib/python3.7/site-packages/sncosmo/models.py"", line 116, in _bandflux_single
    f = model._flux(time_or_phase, wave)
  File ""/anaconda3/envs/sdss_classification_3.7/lib/python3.7/site-packages/sncosmo/models.py"", line 1272, in _flux
    f = a * self._source._flux(phase, restwave)
  File ""/Users/daniel/Github/SDSS-Classification/analysis_pipeline/_sn91bg_model/_model.py"", line 135, in _flux
    y = [self._model_flux[c1](phase / (st / 0.65), wave),
  File ""/anaconda3/envs/sdss_classification_3.7/lib/python3.7/site-packages/scipy/interpolate/fitpack2.py"", line 848, in __call__
    raise ValueError(""Error code returned by bispev: %s"" % ier)"
2007st 12 13 13 13 11 0 0 8 18 10 14 0 6 0 0 nan nan nan nan nan nan nan nan nan nan nan nan "exception was raised in user function
User function arguments:
     z = +0.002000
    t0 = +1428.158145
    x0 = +0.000000
    x1 = -0.207196
     c = +0.994435
Original python exception in user function:
ValueError: Error code returned by bispev: 10
  File ""/anaconda3/envs/sdss_classification_3.7/lib/python3.7/site-packages/sncosmo/fitting.py"", line 46, in chisq
    zp=data.zp, zpsys=data.zpsys)
  File ""/anaconda3/envs/sdss_classification_3.7/lib/python3.7/site-packages/sncosmo/models.py"", line 1400, in bandflux
    raise e
  File ""/anaconda3/envs/sdss_classification_3.7/lib/python3.7/site-packages/sncosmo/models.py"", line 1397, in bandflux
    return _bandflux(self, band, time, zp, zpsys)
  File ""/anaconda3/envs/sdss_classification_3.7/lib/python3.7/site-packages/sncosmo/models.py"", line 154, in _bandflux
    fsum = _bandflux_single(model, b, time_or_phase[mask])
  File ""/anaconda3/envs/sdss_classification_3.7/lib/python3.7/site-packages/sncosmo/models.py"", line 116, in _bandflux_single
    f = model._flux(time_or_phase, wave)
  File ""/anaconda3/envs/sdss_classification_3.7/lib/python3.7/site-packages/sncosmo/models.py"", line 1272, in _flux
    f = a * self._source._flux(phase, restwave)
  File ""/Users/daniel/Github/SDSS-Classification/analysis_pipeline/_sn91bg_model/_model.py"", line 135, in _flux
    y = [self._model_flux[c1](phase / (st / 0.65), wave),
  File ""/anaconda3/envs/sdss_classification_3.7/lib/python3.7/site-packages/scipy/interpolate/fitpack2.py"", line 848, in __call__
    raise ValueError(""Error code returned by bispev: %s"" % ier)"
2005hc 10 23 23 22 23 23 0 0 26 3 10 0 0 0 0 nan nan nan nan nan nan nan nan nan nan nan nan "exception was raised in user function
User function arguments:
     z = +0.002000
    t0 = +619.713631
    x0 = +0.000000
    x1 = -22.581092
     c = +0.983558
Original python exception in user function:
ValueError: Error code returned by bispev: 10
  File ""/anaconda3/envs/sdss_classification_3.7/lib/python3.7/site-packages/sncosmo/fitting.py"", line 46, in chisq
    zp=data.zp, zpsys=data.zpsys)
  File ""/anaconda3/envs/sdss_classification_3.7/lib/python3.7/site-packages/sncosmo/models.py"", line 1400, in bandflux
    raise e
  File ""/anaconda3/envs/sdss_classification_3.7/lib/python3.7/site-packages/sncosmo/models.py"", line 1397, in bandflux
    return _bandflux(self, band, time, zp, zpsys)
  File ""/anaconda3/envs/sdss_classification_3.7/lib/python3.7/site-packages/sncosmo/models.py"", line 154, in _bandflux
    fsum = _bandflux_single(model, b, time_or_phase[mask])
  File ""/anaconda3/envs/sdss_classification_3.7/lib/python3.7/site-packages/sncosmo/models.py"", line 116, in _bandflux_single
    f = model._flux(time_or_phase, wave)
  File ""/anaconda3/envs/sdss_classification_3.7/lib/python3.7/site-packages/sncosmo/models.py"", line 1272, in _flux
    f = a * self._source._flux(phase, restwave)
  File ""/Users/daniel/Github/SDSS-Classification/analysis_pipeline/_sn91bg_model/_model.py"", line 135, in _flux
    y = [self._model_flux[c1](phase / (st / 0.65), wave),
  File ""/anaconda3/envs/sdss_classification_3.7/lib/python3.7/site-packages/scipy/interpolate/fitpack2.py"", line 848, in __call__
    raise ValueError(""Error code returned by bispev: %s"" % ier)"
2009ab 10 10 10 10 10 0 0 10 14 14 0 14 0 0 0 nan nan nan nan nan nan nan nan nan nan nan nan "exception was raised in user function
User function arguments:
     z = +0.002000
    t0 = +1889.545164
    x0 = +0.000000
    x1 = -4.564611
     c = +0.990270
Original python exception in user function:
ValueError: Error code returned by bispev: 10
  File ""/anaconda3/envs/sdss_classification_3.7/lib/python3.7/site-packages/sncosmo/fitting.py"", line 46, in chisq
    zp=data.zp, zpsys=data.zpsys)
  File ""/anaconda3/envs/sdss_classification_3.7/lib/python3.7/site-packages/sncosmo/models.py"", line 1400, in bandflux
    raise e
  File ""/anaconda3/envs/sdss_classification_3.7/lib/python3.7/site-packages/sncosmo/models.py"", line 1397, in bandflux
    return _bandflux(self, band, time, zp, zpsys)
  File ""/anaconda3/envs/sdss_classification_3.7/lib/python3.7/site-packages/sncosmo/models.py"", line 154, in _bandflux
    fsum = _bandflux_single(model, b, time_or_phase[mask])
  File ""/anaconda3/envs/sdss_classification_3.7/lib/python3.7/site-packages/sncosmo/models.py"", line 116, in _bandflux_single
    f = model._flux(time_or_phase, wave)
  File ""/anaconda3/envs/sdss_classification_3.7/lib/python3.7/site-packages/sncosmo/models.py"", line 1272, in _flux
    f = a * self._source._flux(phase, restwave)
  File ""/Users/daniel/Github/SDSS-Classification/analysis_pipeline/_sn91bg_model/_model.py"", line 135, in _flux
    y = [self._model_flux[c1](phase / (st / 0.65), wave),
  File ""/anaconda3/envs/sdss_classification_3.7/lib/python3.7/site-packages/scipy/interpolate/fitpack2.py"", line 848, in __call__
    raise ValueError(""Error code returned by bispev: %s"" % ier)"
2007as 9 19 19 19 18 0 0 19 18 13 15 0 4 0 0 nan nan nan nan nan nan nan nan nan nan nan nan "exception was raised in user function
User function arguments:
     z = +0.002000
    t0 = +1165.350642
    x0 = +0.000000
    x1 = -0.168218
     c = +0.999758
Original python exception in user function:
ValueError: Error code returned by bispev: 10
  File ""/anaconda3/envs/sdss_classification_3.7/lib/python3.7/site-packages/sncosmo/fitting.py"", line 46, in chisq
    zp=data.zp, zpsys=data.zpsys)
  File ""/anaconda3/envs/sdss_classification_3.7/lib/python3.7/site-packages/sncosmo/models.py"", line 1400, in bandflux
    raise e
  File ""/anaconda3/envs/sdss_classification_3.7/lib/python3.7/site-packages/sncosmo/models.py"", line 1397, in bandflux
    return _bandflux(self, band, time, zp, zpsys)
  File ""/anaconda3/envs/sdss_classification_3.7/lib/python3.7/site-packages/sncosmo/models.py"", line 154, in _bandflux
    fsum = _bandflux_single(model, b, time_or_phase[mask])
  File ""/anaconda3/envs/sdss_classification_3.7/lib/python3.7/site-packages/sncosmo/models.py"", line 116, in _bandflux_single
    f = model._flux(time_or_phase, wave)
  File ""/anaconda3/envs/sdss_classification_3.7/lib/python3.7/site-packages/sncosmo/models.py"", line 1272, in _flux
    f = a * self._source._flux(phase, restwave)
  File ""/Users/daniel/Github/SDSS-Classification/analysis_pipeline/_sn91bg_model/_model.py"", line 135, in _flux
    y = [self._model_flux[c1](phase / (st / 0.65), wave),
  File ""/anaconda3/envs/sdss_classification_3.7/lib/python3.7/site-packages/scipy/interpolate/fitpack2.py"", line 848, in __call__
    raise ValueError(""Error code returned by bispev: %s"" % ier)"
2006hx 4 10 10 8 8 0 0 9 0 8 6 0 7 0 0 0.0020000000009542255 1021.1481316260705 4.086914137063164e-15 1.5271412111815743 1.0174860953782172e-10 2.606930582773649e-06 0.12722915465724327 1.0480310624145416e-16 0.03834010902312144 3.206245939371688e-05 6368.62439775432 51 "Covariance may not be accurate. Covariance not positive definite. Covariance forced positive definite."
2008ff 17 23 24 23 23 0 0 23 23 31 29 0 14 0 0 0.002000000000026396 1715.448187231958 1.4033063774560291e-14 1.8961900707432358 6.410594277639348e-12 3.193346158507967e-07 0.10594956295051361 9.387626566542476e-17 0.007491060064282135 0.0001427543355209393 89346.94072508193 142 "Covariance may not be accurate. Covariance not positive definite. Covariance forced positive definite."
2009ds 9 9 9 9 9 0 0 9 11 12 2 12 1 0 0 nan nan nan nan nan nan nan nan nan nan nan nan "exception was raised in user function
User function arguments:
     z = +0.002437
    t0 = +1984.989149
    x0 = +0.000000
    x1 = -0.932982
     c = +0.908293
Original python exception in user function:
ValueError: Error code returned by bispev: 10
  File ""/anaconda3/envs/sdss_classification_3.7/lib/python3.7/site-packages/sncosmo/fitting.py"", line 46, in chisq
    zp=data.zp, zpsys=data.zpsys)
  File ""/anaconda3/envs/sdss_classification_3.7/lib/python3.7/site-packages/sncosmo/models.py"", line 1400, in bandflux
    raise e
  File ""/anaconda3/envs/sdss_classification_3.7/lib/python3.7/site-packages/sncosmo/models.py"", line 1397, in bandflux
    return _bandflux(self, band, time, zp, zpsys)
  File ""/anaconda3/envs/sdss_classification_3.7/lib/python3.7/site-packages/sncosmo/models.py"", line 154, in _bandflux
    fsum = _bandflux_single(model, b, time_or_phase[mask])
  File ""/anaconda3/envs/sdss_classification_3.7/lib/python3.7/site-packages/sncosmo/models.py"", line 116, in _bandflux_single
    f = model._flux(time_or_phase, wave)
  File ""/anaconda3/envs/sdss_classification_3.7/lib/python3.7/site-packages/sncosmo/models.py"", line 1272, in _flux
    f = a * self._source._flux(phase, restwave)
  File ""/Users/daniel/Github/SDSS-Classification/analysis_pipeline/_sn91bg_model/_model.py"", line 135, in _flux
    y = [self._model_flux[c1](phase / (st / 0.65), wave),
  File ""/anaconda3/envs/sdss_classification_3.7/lib/python3.7/site-packages/scipy/interpolate/fitpack2.py"", line 848, in __call__
    raise ValueError(""Error code returned by bispev: %s"" % ier)"
2008O 6 10 14 9 16 0 0 18 16 5 5 0 4 0 0 0.006712951906326858 1491.7010900574683 2.8046192216938535e-15 1.1408861096199663 0.14005062132472101 0.0002343149532568617 0.06712347201516877 3.607321289308649e-17 0.011678569527002816 0.009103785044558305 3676.176856505292 72 "Covariance may not be accurate. Covariance not positive definite. Covariance forced positive definite."
2006ot 5 11 17 16 13 0 0 14 23 4 11 0 4 0 0 nan nan nan nan nan nan nan nan nan nan nan nan "exception was raised in user function
User function arguments:
     z = +0.082778
    t0 = +1060.882097
    x0 = +0.000000
    x1 = -0.236348
     c = +0.550000
Original python exception in user function:
ValueError: Error code returned by bispev: 10
  File ""/anaconda3/envs/sdss_classification_3.7/lib/python3.7/site-packages/sncosmo/fitting.py"", line 46, in chisq
    zp=data.zp, zpsys=data.zpsys)
  File ""/anaconda3/envs/sdss_classification_3.7/lib/python3.7/site-packages/sncosmo/models.py"", line 1400, in bandflux
    raise e
  File ""/anaconda3/envs/sdss_classification_3.7/lib/python3.7/site-packages/sncosmo/models.py"", line 1397, in bandflux
    return _bandflux(self, band, time, zp, zpsys)
  File ""/anaconda3/envs/sdss_classification_3.7/lib/python3.7/site-packages/sncosmo/models.py"", line 154, in _bandflux
    fsum = _bandflux_single(model, b, time_or_phase[mask])
  File ""/anaconda3/envs/sdss_classification_3.7/lib/python3.7/site-packages/sncosmo/models.py"", line 116, in _bandflux_single
    f = model._flux(time_or_phase, wave)
  File ""/anaconda3/envs/sdss_classification_3.7/lib/python3.7/site-packages/sncosmo/models.py"", line 1272, in _flux
    f = a * self._source._flux(phase, restwave)
  File ""/Users/daniel/Github/SDSS-Classification/analysis_pipeline/_sn91bg_model/_model.py"", line 135, in _flux
    y = [self._model_flux[c1](phase / (st / 0.65), wave),
  File ""/anaconda3/envs/sdss_classification_3.7/lib/python3.7/site-packages/scipy/interpolate/fitpack2.py"", line 848, in __call__
    raise ValueError(""Error code returned by bispev: %s"" % ier)"
2006py 3 6 7 7 6 0 0 6 0 0 0 0 0 0 0 nan nan nan nan nan nan nan nan nan nan nan nan "exception was raised in user function
User function arguments:
     z = +0.078926
    t0 = +1053.619182
    x0 = +0.000000
    x1 = -0.262667
     c = +0.998368
Original python exception in user function:
ValueError: Error code returned by bispev: 10
  File ""/anaconda3/envs/sdss_classification_3.7/lib/python3.7/site-packages/sncosmo/fitting.py"", line 46, in chisq
    zp=data.zp, zpsys=data.zpsys)
  File ""/anaconda3/envs/sdss_classification_3.7/lib/python3.7/site-packages/sncosmo/models.py"", line 1400, in bandflux
    raise e
  File ""/anaconda3/envs/sdss_classification_3.7/lib/python3.7/site-packages/sncosmo/models.py"", line 1397, in bandflux
    return _bandflux(self, band, time, zp, zpsys)
  File ""/anaconda3/envs/sdss_classification_3.7/lib/python3.7/site-packages/sncosmo/models.py"", line 154, in _bandflux
    fsum = _bandflux_single(model, b, time_or_phase[mask])
  File ""/anaconda3/envs/sdss_classification_3.7/lib/python3.7/site-packages/sncosmo/models.py"", line 116, in _bandflux_single
    f = model._flux(time_or_phase, wave)
  File ""/anaconda3/envs/sdss_classification_3.7/lib/python3.7/site-packages/sncosmo/models.py"", line 1272, in _flux
    f = a * self._source._flux(phase, restwave)
  File ""/Users/daniel/Github/SDSS-Classification/analysis_pipeline/_sn91bg_model/_model.py"", line 135, in _flux
    y = [self._model_flux[c1](phase / (st / 0.65), wave),
  File ""/anaconda3/envs/sdss_classification_3.7/lib/python3.7/site-packages/scipy/interpolate/fitpack2.py"", line 848, in __call__
    raise ValueError(""Error code returned by bispev: %s"" % ier)"
2005be 7 12 12 11 13 13 0 0 0 0 0 0 0 0 0 nan nan nan nan nan nan nan nan nan nan nan nan "exception was raised in user function
User function arguments:
     z = +0.002000
    t0 = +451.765265
    x0 = +0.000000
    x1 = -0.215960
     c = +0.999766
Original python exception in user function:
ValueError: Error code returned by bispev: 10
  File ""/anaconda3/envs/sdss_classification_3.7/lib/python3.7/site-packages/sncosmo/fitting.py"", line 46, in chisq
    zp=data.zp, zpsys=data.zpsys)
  File ""/anaconda3/envs/sdss_classification_3.7/lib/python3.7/site-packages/sncosmo/models.py"", line 1400, in bandflux
    raise e
  File ""/anaconda3/envs/sdss_classification_3.7/lib/python3.7/site-packages/sncosmo/models.py"", line 1397, in bandflux
    return _bandflux(self, band, time, zp, zpsys)
  File ""/anaconda3/envs/sdss_classification_3.7/lib/python3.7/site-packages/sncosmo/models.py"", line 154, in _bandflux
    fsum = _bandflux_single(model, b, time_or_phase[mask])
  File ""/anaconda3/envs/sdss_classification_3.7/lib/python3.7/site-packages/sncosmo/models.py"", line 116, in _bandflux_single
    f = model._flux(time_or_phase, wave)
  File ""/anaconda3/envs/sdss_classification_3.7/lib/python3.7/site-packages/sncosmo/models.py"", line 1272, in _flux
    f = a * self._source._flux(phase, restwave)
  File ""/Users/daniel/Github/SDSS-Classification/analysis_pipeline/_sn91bg_model/_model.py"", line 135, in _flux
    y = [self._model_flux[c1](phase / (st / 0.65), wave),
  File ""/anaconda3/envs/sdss_classification_3.7/lib/python3.7/site-packages/scipy/interpolate/fitpack2.py"", line 848, in __call__
    raise ValueError(""Error code returned by bispev: %s"" % ier)"
2006fw 2 6 0 6 5 0 0 6 0 0 0 0 0 0 0 0.00923129118799635 1004.3255207626149 1.251154519444062e-15 1.2825622667923253 1.1988883219515856e-09 0.0012989622621426685 0.07649853364790715 2.954339327832138e-17 0.05649724774734165 5.060054272809644e-05 1150.6440783490732 20 "Covariance may not be accurate. Covariance not positive definite. Covariance forced positive definite."
2007ax 5 11 12 12 12 0 0 12 13 7 11 0 2 0 0 0.0020000002544307565 1188.5055169557984 3.1361193663984e-14 0.904963118899335 0.3763995473084977 1.1144490698942458e-05 0.011964184802536693 5.223968638013529e-16 0.010558203253032908 0.011318908172659542 3132.100620019418 61 "Covariance may not be accurate. Covariance not positive definite. Covariance forced positive definite."
2007jg 7 15 13 19 17 0 0 18 8 1 8 0 7 0 0 nan nan nan nan nan nan nan nan nan nan nan nan "exception was raised in user function
User function arguments:
     z = +0.002000
    t0 = +1369.100858
    x0 = +0.000000
    x1 = -1.300105
     c = +0.987698
Original python exception in user function:
ValueError: Error code returned by bispev: 10
  File ""/anaconda3/envs/sdss_classification_3.7/lib/python3.7/site-packages/sncosmo/fitting.py"", line 46, in chisq
    zp=data.zp, zpsys=data.zpsys)
  File ""/anaconda3/envs/sdss_classification_3.7/lib/python3.7/site-packages/sncosmo/models.py"", line 1400, in bandflux
    raise e
  File ""/anaconda3/envs/sdss_classification_3.7/lib/python3.7/site-packages/sncosmo/models.py"", line 1397, in bandflux
    return _bandflux(self, band, time, zp, zpsys)
  File ""/anaconda3/envs/sdss_classification_3.7/lib/python3.7/site-packages/sncosmo/models.py"", line 154, in _bandflux
    fsum = _bandflux_single(model, b, time_or_phase[mask])
  File ""/anaconda3/envs/sdss_classification_3.7/lib/python3.7/site-packages/sncosmo/models.py"", line 116, in _bandflux_single
    f = model._flux(time_or_phase, wave)
  File ""/anaconda3/envs/sdss_classification_3.7/lib/python3.7/site-packages/sncosmo/models.py"", line 1272, in _flux
    f = a * self._source._flux(phase, restwave)
  File ""/Users/daniel/Github/SDSS-Classification/analysis_pipeline/_sn91bg_model/_model.py"", line 135, in _flux
    y = [self._model_flux[c1](phase / (st / 0.65), wave),
  File ""/anaconda3/envs/sdss_classification_3.7/lib/python3.7/site-packages/scipy/interpolate/fitpack2.py"", line 848, in __call__
    raise ValueError(""Error code returned by bispev: %s"" % ier)"
2007af 24 24 27 28 27 0 0 27 40 48 50 0 12 0 0 nan nan nan nan nan nan nan nan nan nan nan nan "exception was raised in user function
User function arguments:
     z = +0.002000
    t0 = +1169.652090
    x0 = +0.000000
    x1 = -0.640394
     c = +0.987259
Original python exception in user function:
ValueError: Error code returned by bispev: 10
  File ""/anaconda3/envs/sdss_classification_3.7/lib/python3.7/site-packages/sncosmo/fitting.py"", line 46, in chisq
    zp=data.zp, zpsys=data.zpsys)
  File ""/anaconda3/envs/sdss_classification_3.7/lib/python3.7/site-packages/sncosmo/models.py"", line 1400, in bandflux
    raise e
  File ""/anaconda3/envs/sdss_classification_3.7/lib/python3.7/site-packages/sncosmo/models.py"", line 1397, in bandflux
    return _bandflux(self, band, time, zp, zpsys)
  File ""/anaconda3/envs/sdss_classification_3.7/lib/python3.7/site-packages/sncosmo/models.py"", line 154, in _bandflux
    fsum = _bandflux_single(model, b, time_or_phase[mask])
  File ""/anaconda3/envs/sdss_classification_3.7/lib/python3.7/site-packages/sncosmo/models.py"", line 116, in _bandflux_single
    f = model._flux(time_or_phase, wave)
  File ""/anaconda3/envs/sdss_classification_3.7/lib/python3.7/site-packages/sncosmo/models.py"", line 1272, in _flux
    f = a * self._source._flux(phase, restwave)
  File ""/Users/daniel/Github/SDSS-Classification/analysis_pipeline/_sn91bg_model/_model.py"", line 135, in _flux
    y = [self._model_flux[c1](phase / (st / 0.65), wave),
  File ""/anaconda3/envs/sdss_classification_3.7/lib/python3.7/site-packages/scipy/interpolate/fitpack2.py"", line 848, in __call__
    raise ValueError(""Error code returned by bispev: %s"" % ier)"
2008cc 21 19 21 21 20 0 0 21 17 13 12 0 2 0 0 0.002000000000577057 1564.6994947329576 1.7377217247790336e-13 0.8303046779135212 1.650829473121007e-11 4.0370103543689757e-07 0.07219350148420745 1.7900780129378273e-15 0.004118879086952382 3.322753588635985e-06 297147.04067910596 120 "Covariance may not be accurate. Covariance not positive definite. Covariance forced positive definite."
2006ef 6 10 10 10 10 0 0 10 0 0 0 0 0 0 0 nan nan nan nan nan nan nan nan nan nan nan nan "exception was raised in user function
User function arguments:
     z = +0.002000
    t0 = +961.841529
    x0 = +0.000000
    x1 = -0.067035
     c = +0.996650
Original python exception in user function:
ValueError: Error code returned by bispev: 10
  File ""/anaconda3/envs/sdss_classification_3.7/lib/python3.7/site-packages/sncosmo/fitting.py"", line 46, in chisq
    zp=data.zp, zpsys=data.zpsys)
  File ""/anaconda3/envs/sdss_classification_3.7/lib/python3.7/site-packages/sncosmo/models.py"", line 1400, in bandflux
    raise e
  File ""/anaconda3/envs/sdss_classification_3.7/lib/python3.7/site-packages/sncosmo/models.py"", line 1397, in bandflux
    return _bandflux(self, band, time, zp, zpsys)
  File ""/anaconda3/envs/sdss_classification_3.7/lib/python3.7/site-packages/sncosmo/models.py"", line 154, in _bandflux
    fsum = _bandflux_single(model, b, time_or_phase[mask])
  File ""/anaconda3/envs/sdss_classification_3.7/lib/python3.7/site-packages/sncosmo/models.py"", line 116, in _bandflux_single
    f = model._flux(time_or_phase, wave)
  File ""/anaconda3/envs/sdss_classification_3.7/lib/python3.7/site-packages/sncosmo/models.py"", line 1272, in _flux
    f = a * self._source._flux(phase, restwave)
  File ""/Users/daniel/Github/SDSS-Classification/analysis_pipeline/_sn91bg_model/_model.py"", line 135, in _flux
    y = [self._model_flux[c1](phase / (st / 0.65), wave),
  File ""/anaconda3/envs/sdss_classification_3.7/lib/python3.7/site-packages/scipy/interpolate/fitpack2.py"", line 848, in __call__
    raise ValueError(""Error code returned by bispev: %s"" % ier)"
2007nq 6 23 25 25 21 0 0 25 27 3 9 0 10 0 0 nan nan nan nan nan nan nan nan nan nan nan nan "exception was raised in user function
User function arguments:
     z = +0.079293
    t0 = +1376.663905
    x0 = +0.000000
    x1 = -0.534004
     c = +0.994315
Original python exception in user function:
ValueError: Error code returned by bispev: 10
  File ""/anaconda3/envs/sdss_classification_3.7/lib/python3.7/site-packages/sncosmo/fitting.py"", line 46, in chisq
    zp=data.zp, zpsys=data.zpsys)
  File ""/anaconda3/envs/sdss_classification_3.7/lib/python3.7/site-packages/sncosmo/models.py"", line 1400, in bandflux
    raise e
  File ""/anaconda3/envs/sdss_classification_3.7/lib/python3.7/site-packages/sncosmo/models.py"", line 1397, in bandflux
    return _bandflux(self, band, time, zp, zpsys)
  File ""/anaconda3/envs/sdss_classification_3.7/lib/python3.7/site-packages/sncosmo/models.py"", line 154, in _bandflux
    fsum = _bandflux_single(model, b, time_or_phase[mask])
  File ""/anaconda3/envs/sdss_classification_3.7/lib/python3.7/site-packages/sncosmo/models.py"", line 116, in _bandflux_single
    f = model._flux(time_or_phase, wave)
  File ""/anaconda3/envs/sdss_classification_3.7/lib/python3.7/site-packages/sncosmo/models.py"", line 1272, in _flux
    f = a * self._source._flux(phase, restwave)
  File ""/Users/daniel/Github/SDSS-Classification/analysis_pipeline/_sn91bg_model/_model.py"", line 135, in _flux
    y = [self._model_flux[c1](phase / (st / 0.65), wave),
  File ""/anaconda3/envs/sdss_classification_3.7/lib/python3.7/site-packages/scipy/interpolate/fitpack2.py"", line 848, in __call__
    raise ValueError(""Error code returned by bispev: %s"" % ier)"
2008bq 15 17 16 16 16 0 0 16 8 3 7 0 0 0 0 nan nan nan nan nan nan nan nan nan nan nan nan "exception was raised in user function
User function arguments:
     z = +0.002000
    t0 = +1488.539239
    x0 = +0.000000
    x1 = -103.682901
     c = +0.997064
Original python exception in user function:
ValueError: Error code returned by bispev: 10
  File ""/anaconda3/envs/sdss_classification_3.7/lib/python3.7/site-packages/sncosmo/fitting.py"", line 46, in chisq
    zp=data.zp, zpsys=data.zpsys)
  File ""/anaconda3/envs/sdss_classification_3.7/lib/python3.7/site-packages/sncosmo/models.py"", line 1400, in bandflux
    raise e
  File ""/anaconda3/envs/sdss_classification_3.7/lib/python3.7/site-packages/sncosmo/models.py"", line 1397, in bandflux
    return _bandflux(self, band, time, zp, zpsys)
  File ""/anaconda3/envs/sdss_classification_3.7/lib/python3.7/site-packages/sncosmo/models.py"", line 154, in _bandflux
    fsum = _bandflux_single(model, b, time_or_phase[mask])
  File ""/anaconda3/envs/sdss_classification_3.7/lib/python3.7/site-packages/sncosmo/models.py"", line 116, in _bandflux_single
    f = model._flux(time_or_phase, wave)
  File ""/anaconda3/envs/sdss_classification_3.7/lib/python3.7/site-packages/sncosmo/models.py"", line 1272, in _flux
    f = a * self._source._flux(phase, restwave)
  File ""/Users/daniel/Github/SDSS-Classification/analysis_pipeline/_sn91bg_model/_model.py"", line 135, in _flux
    y = [self._model_flux[c1](phase / (st / 0.65), wave),
  File ""/anaconda3/envs/sdss_classification_3.7/lib/python3.7/site-packages/scipy/interpolate/fitpack2.py"", line 848, in __call__
    raise ValueError(""Error code returned by bispev: %s"" % ier)"
2008hv 21 24 24 24 24 0 0 24 31 23 18 8 4 0 0 nan nan nan nan nan nan nan nan nan nan nan nan "exception was raised in user function
User function arguments:
     z = +0.084801
    t0 = +1732.738826
    x0 = -11438061700141398016.000000
    x1 = -151310.247761
     c = +0.032358
Original python exception in user function:
ValueError: Error code returned by bispev: 10
  File ""/anaconda3/envs/sdss_classification_3.7/lib/python3.7/site-packages/sncosmo/fitting.py"", line 46, in chisq
    zp=data.zp, zpsys=data.zpsys)
  File ""/anaconda3/envs/sdss_classification_3.7/lib/python3.7/site-packages/sncosmo/models.py"", line 1400, in bandflux
    raise e
  File ""/anaconda3/envs/sdss_classification_3.7/lib/python3.7/site-packages/sncosmo/models.py"", line 1397, in bandflux
    return _bandflux(self, band, time, zp, zpsys)
  File ""/anaconda3/envs/sdss_classification_3.7/lib/python3.7/site-packages/sncosmo/models.py"", line 154, in _bandflux
    fsum = _bandflux_single(model, b, time_or_phase[mask])
  File ""/anaconda3/envs/sdss_classification_3.7/lib/python3.7/site-packages/sncosmo/models.py"", line 116, in _bandflux_single
    f = model._flux(time_or_phase, wave)
  File ""/anaconda3/envs/sdss_classification_3.7/lib/python3.7/site-packages/sncosmo/models.py"", line 1272, in _flux
    f = a * self._source._flux(phase, restwave)
  File ""/Users/daniel/Github/SDSS-Classification/analysis_pipeline/_sn91bg_model/_model.py"", line 135, in _flux
    y = [self._model_flux[c1](phase / (st / 0.65), wave),
  File ""/anaconda3/envs/sdss_classification_3.7/lib/python3.7/site-packages/scipy/interpolate/fitpack2.py"", line 848, in __call__
    raise ValueError(""Error code returned by bispev: %s"" % ier)"
2009I 3 5 5 5 5 0 0 5 10 7 0 10 0 0 0 0.002000000106521942 1849.7825383310746 4.640205128861377e-15 1.5467347654726828 0.24802582046688182 4.277159617966427e-06 0.13376914228103942 7.558113027341351e-17 0.040653692985434926 0.00861218231814126 3244.884852872522 23 "Covariance may not be accurate. Covariance not positive definite. Covariance forced positive definite."
2004gc 0 26 28 26 26 28 0 0 0 0 0 0 0 0 0 0.005571827702927152 329.9364490938781 4.5455687966661835e-15 1.3304075614277167 6.177812705843166e-10 0.00015498064389071406 0.1047230301812192 3.906953348187094e-17 0.010435112701715866 1.337696931735799e-05 14183.112184980408 129 "Covariance may not be accurate. Covariance not positive definite. Covariance forced positive definite."
2005lu 6 10 17 17 17 8 0 8 5 0 0 0 0 0 0 0.002000000000779678 718.729290414647 3.941108092356743e-15 1.7321250996706112 5.209327413879805e-11 1.2511974596966704e-06 0.26991824541767073 6.140353270430597e-17 0.02026860538427833 9.303373136732018e-06 7072.94345869644 78 "Covariance may not be accurate. Covariance not positive definite. Covariance forced positive definite."
2007al 4 15 16 14 14 0 0 15 14 10 12 0 6 0 0 0.002000000010300471 1171.164873676125 1.2165527841700182e-14 0.8954689662067012 0.43546164443410473 7.912449001782262e-06 0.07089753901095719 2.2206150420713886e-16 0.009211353162838842 0.011538144508938475 3629.9443354147006 79 "Covariance may not be accurate. Covariance not positive definite. Covariance forced positive definite."
2005gj 13 23 23 23 23 12 0 10 24 25 0 0 17 0 0 0.08499999955189182 672.7786766321916 4.602088626092972e-15 6.517288708657893 4.5751707977714773e-10 9.332352762826679e-06 0.5090029385543176 4.070546369195966e-17 0.047250144416198785 9.526257515463099e-06 21341.088438158302 139 "Covariance may not be accurate. Covariance not positive definite. Covariance forced positive definite."
2008bz 7 14 14 12 12 0 0 11 0 0 0 0 0 0 0 nan nan nan nan nan nan nan nan nan nan nan nan "exception was raised in user function
User function arguments:
     z = +0.079014
    t0 = +1566.666747
    x0 = +0.000000
    x1 = -1.419394
     c = +0.997709
Original python exception in user function:
ValueError: Error code returned by bispev: 10
  File ""/anaconda3/envs/sdss_classification_3.7/lib/python3.7/site-packages/sncosmo/fitting.py"", line 46, in chisq
    zp=data.zp, zpsys=data.zpsys)
  File ""/anaconda3/envs/sdss_classification_3.7/lib/python3.7/site-packages/sncosmo/models.py"", line 1400, in bandflux
    raise e
  File ""/anaconda3/envs/sdss_classification_3.7/lib/python3.7/site-packages/sncosmo/models.py"", line 1397, in bandflux
    return _bandflux(self, band, time, zp, zpsys)
  File ""/anaconda3/envs/sdss_classification_3.7/lib/python3.7/site-packages/sncosmo/models.py"", line 154, in _bandflux
    fsum = _bandflux_single(model, b, time_or_phase[mask])
  File ""/anaconda3/envs/sdss_classification_3.7/lib/python3.7/site-packages/sncosmo/models.py"", line 116, in _bandflux_single
    f = model._flux(time_or_phase, wave)
  File ""/anaconda3/envs/sdss_classification_3.7/lib/python3.7/site-packages/sncosmo/models.py"", line 1272, in _flux
    f = a * self._source._flux(phase, restwave)
  File ""/Users/daniel/Github/SDSS-Classification/analysis_pipeline/_sn91bg_model/_model.py"", line 135, in _flux
    y = [self._model_flux[c1](phase / (st / 0.65), wave),
  File ""/anaconda3/envs/sdss_classification_3.7/lib/python3.7/site-packages/scipy/interpolate/fitpack2.py"", line 848, in __call__
    raise ValueError(""Error code returned by bispev: %s"" % ier)"
2007bc 7 15 15 15 11 0 0 14 11 8 11 0 4 0 0 nan nan nan nan nan nan nan nan nan nan nan nan "exception was raised in user function
User function arguments:
     z = +0.072214
    t0 = +1177.107425
    x0 = +0.000000
    x1 = -4.389362
     c = +0.994068
Original python exception in user function:
ValueError: Error code returned by bispev: 10
  File ""/anaconda3/envs/sdss_classification_3.7/lib/python3.7/site-packages/sncosmo/fitting.py"", line 46, in chisq
    zp=data.zp, zpsys=data.zpsys)
  File ""/anaconda3/envs/sdss_classification_3.7/lib/python3.7/site-packages/sncosmo/models.py"", line 1400, in bandflux
    raise e
  File ""/anaconda3/envs/sdss_classification_3.7/lib/python3.7/site-packages/sncosmo/models.py"", line 1397, in bandflux
    return _bandflux(self, band, time, zp, zpsys)
  File ""/anaconda3/envs/sdss_classification_3.7/lib/python3.7/site-packages/sncosmo/models.py"", line 154, in _bandflux
    fsum = _bandflux_single(model, b, time_or_phase[mask])
  File ""/anaconda3/envs/sdss_classification_3.7/lib/python3.7/site-packages/sncosmo/models.py"", line 116, in _bandflux_single
    f = model._flux(time_or_phase, wave)
  File ""/anaconda3/envs/sdss_classification_3.7/lib/python3.7/site-packages/sncosmo/models.py"", line 1272, in _flux
    f = a * self._source._flux(phase, restwave)
  File ""/Users/daniel/Github/SDSS-Classification/analysis_pipeline/_sn91bg_model/_model.py"", line 135, in _flux
    y = [self._model_flux[c1](phase / (st / 0.65), wave),
  File ""/anaconda3/envs/sdss_classification_3.7/lib/python3.7/site-packages/scipy/interpolate/fitpack2.py"", line 848, in __call__
    raise ValueError(""Error code returned by bispev: %s"" % ier)"
2008fr 8 19 19 18 20 0 0 21 23 8 6 0 8 0 0 0.002000000000600486 1712.8823963822674 3.2816475889595435e-14 0.7801316247320527 5.551115123125783e-17 1.1436022214329853e-05 0.13170318538254833 6.261744790188941e-16 0.0053813805320312505 2.135766942040762e-05 75805.75584704697 108 "Covariance may not be accurate. Covariance not positive definite. Covariance forced positive definite."
