# %ECSV 0.9
# ---
# datatype:
# - {name: cid, datatype: object}
# - {name: num_points_desg, datatype: object}
# - {name: num_points_desr, datatype: object}
# - {name: num_points_desi, datatype: object}
# - {name: num_points_desz, datatype: object}
# - {name: num_points_desy, datatype: object}
# - {name: z, datatype: object}
# - {name: t0, datatype: object}
# - {name: x0, datatype: object}
# - {name: x1, datatype: object}
# - {name: c, datatype: object}
# - {name: z_err, datatype: object}
# - {name: t0_err, datatype: object}
# - {name: x0_err, datatype: object}
# - {name: x1_err, datatype: object}
# - {name: c_err, datatype: object}
# - {name: chi, datatype: object}
# - {name: dof, datatype: object}
# - {name: message, datatype: object}
# meta: !!omap
# - bounds:
#     c: [0, 1]
#     x1': [0.65, 1.25]
#     z: [0.01, 0.9]
# - {warn: false}
# schema: astropy-2.0
cid num_points_desg num_points_desr num_points_desi num_points_desz num_points_desy z t0 x0 x1 c z_err t0_err x0_err x1_err c_err chi dof message
1248677 0 13 17 16 0 0.1714943705730729 56550.72746300506 7.580806231453527e-17 1.7244464287710217 1.274669814144147e-10 0.0004824440407707048 0.03287301258023945 3.778549953306463e-19 0.010385420310783221 1.6051722785959122e-06 1303.4679410606034 41 "Covariance may not be accurate. Covariance not positive definite. Covariance forced positive definite."
1250017 0 16 15 15 0 nan nan nan nan nan nan nan nan nan nan nan nan "exception was raised in user function
User function arguments:
     z = +0.478400
    t0 = +56551.214678
    x0 = +0.000000
    x1 = -4.060770
     c = +0.993110
Original python exception in user function:
ValueError: Error code returned by bispev: 10
  File ""/anaconda3/envs/sdss_classification_3.7/lib/python3.7/site-packages/sncosmo/fitting.py"", line 46, in chisq
    zp=data.zp, zpsys=data.zpsys)
  File ""/anaconda3/envs/sdss_classification_3.7/lib/python3.7/site-packages/sncosmo/models.py"", line 1400, in bandflux
    raise e
  File ""/anaconda3/envs/sdss_classification_3.7/lib/python3.7/site-packages/sncosmo/models.py"", line 1397, in bandflux
    return _bandflux(self, band, time, zp, zpsys)
  File ""/anaconda3/envs/sdss_classification_3.7/lib/python3.7/site-packages/sncosmo/models.py"", line 154, in _bandflux
    fsum = _bandflux_single(model, b, time_or_phase[mask])
  File ""/anaconda3/envs/sdss_classification_3.7/lib/python3.7/site-packages/sncosmo/models.py"", line 116, in _bandflux_single
    f = model._flux(time_or_phase, wave)
  File ""/anaconda3/envs/sdss_classification_3.7/lib/python3.7/site-packages/sncosmo/models.py"", line 1272, in _flux
    f = a * self._source._flux(phase, restwave)
  File ""/Users/daniel/Github/SDSS-Classification/analysis_pipeline/_sn91bg_model/_model.py"", line 135, in _flux
    y = [self._model_flux[c1](phase / (st / 0.65), wave),
  File ""/anaconda3/envs/sdss_classification_3.7/lib/python3.7/site-packages/scipy/interpolate/fitpack2.py"", line 848, in __call__
    raise ValueError(""Error code returned by bispev: %s"" % ier)"
1253039 0 0 18 20 0 0.4007560770950687 56573.08938426692 3.344136122750189e-17 1.4662550542104904 8.023890611386086e-07 0.0019923084615827147 0.22933678629487986 6.465092721869982e-19 0.03146010010157075 3.420577410154224e-05 67.86758473327194 33 "Covariance may not be accurate. Covariance not positive definite. Covariance forced positive definite."
1253101 0 0 18 17 0 0.39881664367949005 56574.369574149416 3.247184470785172e-17 1.6665661539326053 4.5505154822045313e-07 0.0026204429351234515 0.07399738259482547 7.840044153000275e-19 0.047277904524898634 5.952726218103055e-05 62.14453879833821 30 "Covariance may not be accurate. Covariance not positive definite. Covariance forced positive definite."
1253920 0 15 14 15 0 0.17107236163113845 56581.15884230965 1.9436951032737048e-16 1.3471174449952081 1.1868090676880882e-08 0.0013575888758720345 0.07459896370346542 3.2530219658417843e-18 0.02070868254663879 1.283388471309821e-05 555.1853703449221 39 "Covariance may not be accurate. Covariance not positive definite. Covariance forced positive definite."
1255502 6 4 4 15 0 0.037896192870335195 56590.32966122932 4.343424505904515e-16 1.9102711074190906 3.6417147075695766e-11 0.0027500671773202923 0.13606038061334402 1.2278913666537785e-17 0.04639923530102631 3.0778762866001674e-05 322.99152655816084 24 "Covariance may not be accurate. Covariance not positive definite. Covariance forced positive definite."
1257366 0 8 10 15 0 0.1710249117531944 56608.41422993119 1.0220379286407186e-16 1.576621809763323 1.0973220665455585e-09 0.003073100028356479 0.04595444566075457 3.3179775065941594e-18 0.0700184071883829 0.0001237873657973232 74.71294775226119 28 "Covariance may not be accurate. Covariance not positive definite. Covariance forced positive definite."
1257695 0 11 13 12 0 0.03696066272399958 56609.88144787797 2.626064541180302e-16 1.5811042299829192 3.856425399628716e-05 0.0014029255226816958 0.03729123880111729 3.0312407697506302e-18 0.01269320603476074 0.7088410879420123 777.3371886007334 31 "Covariance may not be accurate. Covariance not positive definite. Covariance forced positive definite."
1258906 0 15 13 15 0 0.057460591399569085 56617.10235617966 8.414344382731566e-17 1.5209982689531751 0.5697729815376628 0.003767532233607509 0.01854285413355683 1.7642599004467473e-18 0.02129800097737691 0.027279522449477955 50.86907905922148 38 "Covariance may not be accurate. Covariance not positive definite. Covariance forced positive definite."
1258940 0 18 17 18 0 nan nan nan nan nan nan nan nan nan nan nan nan "exception was raised in user function
User function arguments:
     z = +0.589630
    t0 = +56610.315949
    x0 = +0.000000
    x1 = -1.171597
     c = +0.983348
Original python exception in user function:
ValueError: Error code returned by bispev: 10
  File ""/anaconda3/envs/sdss_classification_3.7/lib/python3.7/site-packages/sncosmo/fitting.py"", line 46, in chisq
    zp=data.zp, zpsys=data.zpsys)
  File ""/anaconda3/envs/sdss_classification_3.7/lib/python3.7/site-packages/sncosmo/models.py"", line 1400, in bandflux
    raise e
  File ""/anaconda3/envs/sdss_classification_3.7/lib/python3.7/site-packages/sncosmo/models.py"", line 1397, in bandflux
    return _bandflux(self, band, time, zp, zpsys)
  File ""/anaconda3/envs/sdss_classification_3.7/lib/python3.7/site-packages/sncosmo/models.py"", line 154, in _bandflux
    fsum = _bandflux_single(model, b, time_or_phase[mask])
  File ""/anaconda3/envs/sdss_classification_3.7/lib/python3.7/site-packages/sncosmo/models.py"", line 116, in _bandflux_single
    f = model._flux(time_or_phase, wave)
  File ""/anaconda3/envs/sdss_classification_3.7/lib/python3.7/site-packages/sncosmo/models.py"", line 1272, in _flux
    f = a * self._source._flux(phase, restwave)
  File ""/Users/daniel/Github/SDSS-Classification/analysis_pipeline/_sn91bg_model/_model.py"", line 135, in _flux
    y = [self._model_flux[c1](phase / (st / 0.65), wave),
  File ""/anaconda3/envs/sdss_classification_3.7/lib/python3.7/site-packages/scipy/interpolate/fitpack2.py"", line 848, in __call__
    raise ValueError(""Error code returned by bispev: %s"" % ier)"
1259412 0 11 12 12 0 0.09272151261829265 56620.59677521551 9.040358609910293e-17 1.681404557391938 0.00014160790568579218 0.0007907848932275918 0.09335839686173131 7.894158764227513e-19 0.012183279424051261 0.03260001973954649 270.1480474621033 30 "Covariance may not be accurate. Covariance not positive definite. Covariance forced positive definite."
1261579 0 10 10 10 0 0.17100657086833038 56636.08124505841 7.327616055645555e-17 1.6233526645139609 9.489772523352258e-09 0.000772158220202171 0.008898930755094625 5.124808734268401e-19 0.01594170264441029 5.537562918739303e-06 400.65357740808383 25 "Covariance may not be accurate. Covariance not positive definite. Covariance forced positive definite."
1262214 0 0 23 0 0 0.43334253944485035 56652.79204617957 2.5795277463908823e-17 1.3917345059333137 0.5705564631644716 0.003892447149655698 0.02905019579338841 3.053371713974955e-19 0.008916860506171178 0.00949071012133118 39.400796553090146 18 "Covariance may not be accurate. Covariance not positive definite. Covariance forced positive definite."
1262715 0 0 12 13 0 0.3993852189226967 56656.29689909142 1.7959625350992508e-17 1.6086345430430125 5.972182581803764e-09 0.0032536323747283658 0.11773772826927598 2.250900616803022e-19 0.024483501307638687 3.5307868888889704e-05 24.183832328976237 20 "Covariance may not be accurate. Covariance not positive definite. Covariance forced positive definite."
1263369 0 9 9 9 0 0.17101942644501275 56662.569716329825 7.962082833714127e-17 1.452213077384901 2.1766510427401187e-07 0.0020634131038499426 0.10449963848441257 2.0239592269449592e-18 0.040673532543198686 3.635444069352567e-05 70.88135494412197 22 "Covariance may not be accurate. Covariance not positive definite. Covariance forced positive definite."
1263715 0 9 9 9 0 0.06322029394361384 56662.92839094196 1.0528444650235392e-16 1.5203862679660503 0.03353922702358392 0.0025885098061648286 0.040020373544393806 1.5807236496368316e-18 0.013239675299486862 0.01842133092291326 77.04608091293777 22 "Covariance may not be accurate. Covariance not positive definite. Covariance forced positive definite."
1275946 0 18 19 19 0 nan nan nan nan nan nan nan nan nan nan nan nan "exception was raised in user function
User function arguments:
     z = +0.473160
    t0 = +57265.310088
    x0 = +0.000000
    x1 = -0.236505
     c = +0.550000
Original python exception in user function:
ValueError: Error code returned by bispev: 10
  File ""/anaconda3/envs/sdss_classification_3.7/lib/python3.7/site-packages/sncosmo/fitting.py"", line 46, in chisq
    zp=data.zp, zpsys=data.zpsys)
  File ""/anaconda3/envs/sdss_classification_3.7/lib/python3.7/site-packages/sncosmo/models.py"", line 1400, in bandflux
    raise e
  File ""/anaconda3/envs/sdss_classification_3.7/lib/python3.7/site-packages/sncosmo/models.py"", line 1397, in bandflux
    return _bandflux(self, band, time, zp, zpsys)
  File ""/anaconda3/envs/sdss_classification_3.7/lib/python3.7/site-packages/sncosmo/models.py"", line 154, in _bandflux
    fsum = _bandflux_single(model, b, time_or_phase[mask])
  File ""/anaconda3/envs/sdss_classification_3.7/lib/python3.7/site-packages/sncosmo/models.py"", line 116, in _bandflux_single
    f = model._flux(time_or_phase, wave)
  File ""/anaconda3/envs/sdss_classification_3.7/lib/python3.7/site-packages/sncosmo/models.py"", line 1272, in _flux
    f = a * self._source._flux(phase, restwave)
  File ""/Users/daniel/Github/SDSS-Classification/analysis_pipeline/_sn91bg_model/_model.py"", line 135, in _flux
    y = [self._model_flux[c1](phase / (st / 0.65), wave),
  File ""/anaconda3/envs/sdss_classification_3.7/lib/python3.7/site-packages/scipy/interpolate/fitpack2.py"", line 848, in __call__
    raise ValueError(""Error code returned by bispev: %s"" % ier)"
1279500 0 12 12 11 0 nan nan nan nan nan nan nan nan nan nan nan nan "exception was raised in user function
User function arguments:
     z = +0.477208
    t0 = +57257.563773
    x0 = +0.000000
    x1 = -0.070976
     c = +0.915336
Original python exception in user function:
ValueError: Error code returned by bispev: 10
  File ""/anaconda3/envs/sdss_classification_3.7/lib/python3.7/site-packages/sncosmo/fitting.py"", line 46, in chisq
    zp=data.zp, zpsys=data.zpsys)
  File ""/anaconda3/envs/sdss_classification_3.7/lib/python3.7/site-packages/sncosmo/models.py"", line 1400, in bandflux
    raise e
  File ""/anaconda3/envs/sdss_classification_3.7/lib/python3.7/site-packages/sncosmo/models.py"", line 1397, in bandflux
    return _bandflux(self, band, time, zp, zpsys)
  File ""/anaconda3/envs/sdss_classification_3.7/lib/python3.7/site-packages/sncosmo/models.py"", line 154, in _bandflux
    fsum = _bandflux_single(model, b, time_or_phase[mask])
  File ""/anaconda3/envs/sdss_classification_3.7/lib/python3.7/site-packages/sncosmo/models.py"", line 116, in _bandflux_single
    f = model._flux(time_or_phase, wave)
  File ""/anaconda3/envs/sdss_classification_3.7/lib/python3.7/site-packages/sncosmo/models.py"", line 1272, in _flux
    f = a * self._source._flux(phase, restwave)
  File ""/Users/daniel/Github/SDSS-Classification/analysis_pipeline/_sn91bg_model/_model.py"", line 135, in _flux
    y = [self._model_flux[c1](phase / (st / 0.65), wave),
  File ""/anaconda3/envs/sdss_classification_3.7/lib/python3.7/site-packages/scipy/interpolate/fitpack2.py"", line 848, in __call__
    raise ValueError(""Error code returned by bispev: %s"" % ier)"
1280217 0 16 16 17 0 nan nan nan nan nan nan nan nan nan nan nan nan "exception was raised in user function
User function arguments:
     z = +0.537937
    t0 = +57255.765906
    x0 = +0.000000
    x1 = -1.152673
     c = +0.904096
Original python exception in user function:
ValueError: Error code returned by bispev: 10
  File ""/anaconda3/envs/sdss_classification_3.7/lib/python3.7/site-packages/sncosmo/fitting.py"", line 46, in chisq
    zp=data.zp, zpsys=data.zpsys)
  File ""/anaconda3/envs/sdss_classification_3.7/lib/python3.7/site-packages/sncosmo/models.py"", line 1400, in bandflux
    raise e
  File ""/anaconda3/envs/sdss_classification_3.7/lib/python3.7/site-packages/sncosmo/models.py"", line 1397, in bandflux
    return _bandflux(self, band, time, zp, zpsys)
  File ""/anaconda3/envs/sdss_classification_3.7/lib/python3.7/site-packages/sncosmo/models.py"", line 154, in _bandflux
    fsum = _bandflux_single(model, b, time_or_phase[mask])
  File ""/anaconda3/envs/sdss_classification_3.7/lib/python3.7/site-packages/sncosmo/models.py"", line 116, in _bandflux_single
    f = model._flux(time_or_phase, wave)
  File ""/anaconda3/envs/sdss_classification_3.7/lib/python3.7/site-packages/sncosmo/models.py"", line 1272, in _flux
    f = a * self._source._flux(phase, restwave)
  File ""/Users/daniel/Github/SDSS-Classification/analysis_pipeline/_sn91bg_model/_model.py"", line 135, in _flux
    y = [self._model_flux[c1](phase / (st / 0.65), wave),
  File ""/anaconda3/envs/sdss_classification_3.7/lib/python3.7/site-packages/scipy/interpolate/fitpack2.py"", line 848, in __call__
    raise ValueError(""Error code returned by bispev: %s"" % ier)"
1281668 0 20 21 22 0 0.060230243748151495 57267.00530791084 1.1015055223314544e-16 1.541302349636166 0.2103684670934335 0.003050104458628154 0.042851000540395034 1.779899861694071e-18 0.015472261148685449 0.019097827686715058 72.222464027518 58 "Covariance may not be accurate. Covariance not positive definite. Covariance forced positive definite."
1281886 0 18 18 19 0 0.13390142368769511 57264.39199303261 5.738777347883525e-17 1.6747375557287116 0.0045472900413689454 0.003640626156135973 0.05307333955352078 1.1812694066692867e-18 0.021502997517778503 0.0352819040115083 55.59794883609004 50 "Covariance may not be accurate. Covariance not positive definite. Covariance forced positive definite."
1282736 0 19 16 20 0 0.17338663867739953 57263.50827762763 5.2513016291136114e-17 1.5137615061858047 0.3363392400602986 0.004412710862853289 0.0502582716580946 1.1581884773341952e-18 0.024739096854486897 0.025229433168981685 44.825711062873836 50 "Covariance may not be accurate. Covariance not positive definite. Covariance forced positive definite."
1283373 0 13 15 18 0 nan nan nan nan nan nan nan nan nan nan nan nan "exception was raised in user function
User function arguments:
     z = +0.509772
    t0 = +57263.082155
    x0 = +0.000000
    x1 = -0.191104
     c = +0.985364
Original python exception in user function:
ValueError: Error code returned by bispev: 10
  File ""/anaconda3/envs/sdss_classification_3.7/lib/python3.7/site-packages/sncosmo/fitting.py"", line 46, in chisq
    zp=data.zp, zpsys=data.zpsys)
  File ""/anaconda3/envs/sdss_classification_3.7/lib/python3.7/site-packages/sncosmo/models.py"", line 1400, in bandflux
    raise e
  File ""/anaconda3/envs/sdss_classification_3.7/lib/python3.7/site-packages/sncosmo/models.py"", line 1397, in bandflux
    return _bandflux(self, band, time, zp, zpsys)
  File ""/anaconda3/envs/sdss_classification_3.7/lib/python3.7/site-packages/sncosmo/models.py"", line 154, in _bandflux
    fsum = _bandflux_single(model, b, time_or_phase[mask])
  File ""/anaconda3/envs/sdss_classification_3.7/lib/python3.7/site-packages/sncosmo/models.py"", line 116, in _bandflux_single
    f = model._flux(time_or_phase, wave)
  File ""/anaconda3/envs/sdss_classification_3.7/lib/python3.7/site-packages/sncosmo/models.py"", line 1272, in _flux
    f = a * self._source._flux(phase, restwave)
  File ""/Users/daniel/Github/SDSS-Classification/analysis_pipeline/_sn91bg_model/_model.py"", line 135, in _flux
    y = [self._model_flux[c1](phase / (st / 0.65), wave),
  File ""/anaconda3/envs/sdss_classification_3.7/lib/python3.7/site-packages/scipy/interpolate/fitpack2.py"", line 848, in __call__
    raise ValueError(""Error code returned by bispev: %s"" % ier)"
1283878 0 15 14 14 0 nan nan nan nan nan nan nan nan nan nan nan nan "exception was raised in user function
User function arguments:
     z = +0.475308
    t0 = +57272.190877
    x0 = +0.000000
    x1 = -1.498149
     c = +0.878396
Original python exception in user function:
ValueError: Error code returned by bispev: 10
  File ""/anaconda3/envs/sdss_classification_3.7/lib/python3.7/site-packages/sncosmo/fitting.py"", line 46, in chisq
    zp=data.zp, zpsys=data.zpsys)
  File ""/anaconda3/envs/sdss_classification_3.7/lib/python3.7/site-packages/sncosmo/models.py"", line 1400, in bandflux
    raise e
  File ""/anaconda3/envs/sdss_classification_3.7/lib/python3.7/site-packages/sncosmo/models.py"", line 1397, in bandflux
    return _bandflux(self, band, time, zp, zpsys)
  File ""/anaconda3/envs/sdss_classification_3.7/lib/python3.7/site-packages/sncosmo/models.py"", line 154, in _bandflux
    fsum = _bandflux_single(model, b, time_or_phase[mask])
  File ""/anaconda3/envs/sdss_classification_3.7/lib/python3.7/site-packages/sncosmo/models.py"", line 116, in _bandflux_single
    f = model._flux(time_or_phase, wave)
  File ""/anaconda3/envs/sdss_classification_3.7/lib/python3.7/site-packages/sncosmo/models.py"", line 1272, in _flux
    f = a * self._source._flux(phase, restwave)
  File ""/Users/daniel/Github/SDSS-Classification/analysis_pipeline/_sn91bg_model/_model.py"", line 135, in _flux
    y = [self._model_flux[c1](phase / (st / 0.65), wave),
  File ""/anaconda3/envs/sdss_classification_3.7/lib/python3.7/site-packages/scipy/interpolate/fitpack2.py"", line 848, in __call__
    raise ValueError(""Error code returned by bispev: %s"" % ier)"
1283936 0 21 21 23 0 nan nan nan nan nan nan nan nan nan nan nan nan "exception was raised in user function
User function arguments:
     z = +0.472212
    t0 = +57259.382496
    x0 = +0.000000
    x1 = -3.451421
     c = +0.975448
Original python exception in user function:
ValueError: Error code returned by bispev: 10
  File ""/anaconda3/envs/sdss_classification_3.7/lib/python3.7/site-packages/sncosmo/fitting.py"", line 46, in chisq
    zp=data.zp, zpsys=data.zpsys)
  File ""/anaconda3/envs/sdss_classification_3.7/lib/python3.7/site-packages/sncosmo/models.py"", line 1400, in bandflux
    raise e
  File ""/anaconda3/envs/sdss_classification_3.7/lib/python3.7/site-packages/sncosmo/models.py"", line 1397, in bandflux
    return _bandflux(self, band, time, zp, zpsys)
  File ""/anaconda3/envs/sdss_classification_3.7/lib/python3.7/site-packages/sncosmo/models.py"", line 154, in _bandflux
    fsum = _bandflux_single(model, b, time_or_phase[mask])
  File ""/anaconda3/envs/sdss_classification_3.7/lib/python3.7/site-packages/sncosmo/models.py"", line 116, in _bandflux_single
    f = model._flux(time_or_phase, wave)
  File ""/anaconda3/envs/sdss_classification_3.7/lib/python3.7/site-packages/sncosmo/models.py"", line 1272, in _flux
    f = a * self._source._flux(phase, restwave)
  File ""/Users/daniel/Github/SDSS-Classification/analysis_pipeline/_sn91bg_model/_model.py"", line 135, in _flux
    y = [self._model_flux[c1](phase / (st / 0.65), wave),
  File ""/anaconda3/envs/sdss_classification_3.7/lib/python3.7/site-packages/scipy/interpolate/fitpack2.py"", line 848, in __call__
    raise ValueError(""Error code returned by bispev: %s"" % ier)"
1285160 0 0 0 17 0 0.4741957334907159 57268.461507568114 1.5386055194454913e-17 1.4647331137980621 0.5127719897122854 0.0007352266990814926 0.019354549440322444 2.5132315842617327e-19 0.017779686578789287 0.022309939365060816 11.278807209557034 12 "Covariance may not be accurate. Covariance not positive definite. Covariance forced positive definite."
1285317 0 0 23 24 0 0.39907597726306604 57265.793771647164 2.106195889604681e-17 1.5157595811710387 3.21626155763699e-07 0.0033139486862997225 0.11490479764324846 5.044191176036793e-19 0.05541643795287802 0.00010829611812920859 29.70136518496173 42 "Covariance may not be accurate. Covariance not positive definite. Covariance forced positive definite."
1286398 12 14 13 13 0 nan nan nan nan nan nan nan nan nan nan nan nan "exception was raised in user function
User function arguments:
     z = +0.487956
    t0 = +57266.818215
    x0 = +0.000000
    x1 = -0.622412
     c = +0.962872
Original python exception in user function:
ValueError: Error code returned by bispev: 10
  File ""/anaconda3/envs/sdss_classification_3.7/lib/python3.7/site-packages/sncosmo/fitting.py"", line 46, in chisq
    zp=data.zp, zpsys=data.zpsys)
  File ""/anaconda3/envs/sdss_classification_3.7/lib/python3.7/site-packages/sncosmo/models.py"", line 1400, in bandflux
    raise e
  File ""/anaconda3/envs/sdss_classification_3.7/lib/python3.7/site-packages/sncosmo/models.py"", line 1397, in bandflux
    return _bandflux(self, band, time, zp, zpsys)
  File ""/anaconda3/envs/sdss_classification_3.7/lib/python3.7/site-packages/sncosmo/models.py"", line 154, in _bandflux
    fsum = _bandflux_single(model, b, time_or_phase[mask])
  File ""/anaconda3/envs/sdss_classification_3.7/lib/python3.7/site-packages/sncosmo/models.py"", line 116, in _bandflux_single
    f = model._flux(time_or_phase, wave)
  File ""/anaconda3/envs/sdss_classification_3.7/lib/python3.7/site-packages/sncosmo/models.py"", line 1272, in _flux
    f = a * self._source._flux(phase, restwave)
  File ""/Users/daniel/Github/SDSS-Classification/analysis_pipeline/_sn91bg_model/_model.py"", line 135, in _flux
    y = [self._model_flux[c1](phase / (st / 0.65), wave),
  File ""/anaconda3/envs/sdss_classification_3.7/lib/python3.7/site-packages/scipy/interpolate/fitpack2.py"", line 848, in __call__
    raise ValueError(""Error code returned by bispev: %s"" % ier)"
1287626 0 5 7 6 0 nan nan nan nan nan nan nan nan nan nan nan nan "exception was raised in user function
User function arguments:
     z = +0.474629
    t0 = +56673.375546
    x0 = +0.000000
    x1 = -3.453637
     c = +0.940144
Original python exception in user function:
ValueError: Error code returned by bispev: 10
  File ""/anaconda3/envs/sdss_classification_3.7/lib/python3.7/site-packages/sncosmo/fitting.py"", line 46, in chisq
    zp=data.zp, zpsys=data.zpsys)
  File ""/anaconda3/envs/sdss_classification_3.7/lib/python3.7/site-packages/sncosmo/models.py"", line 1400, in bandflux
    raise e
  File ""/anaconda3/envs/sdss_classification_3.7/lib/python3.7/site-packages/sncosmo/models.py"", line 1397, in bandflux
    return _bandflux(self, band, time, zp, zpsys)
  File ""/anaconda3/envs/sdss_classification_3.7/lib/python3.7/site-packages/sncosmo/models.py"", line 154, in _bandflux
    fsum = _bandflux_single(model, b, time_or_phase[mask])
  File ""/anaconda3/envs/sdss_classification_3.7/lib/python3.7/site-packages/sncosmo/models.py"", line 116, in _bandflux_single
    f = model._flux(time_or_phase, wave)
  File ""/anaconda3/envs/sdss_classification_3.7/lib/python3.7/site-packages/sncosmo/models.py"", line 1272, in _flux
    f = a * self._source._flux(phase, restwave)
  File ""/Users/daniel/Github/SDSS-Classification/analysis_pipeline/_sn91bg_model/_model.py"", line 135, in _flux
    y = [self._model_flux[c1](phase / (st / 0.65), wave),
  File ""/anaconda3/envs/sdss_classification_3.7/lib/python3.7/site-packages/scipy/interpolate/fitpack2.py"", line 848, in __call__
    raise ValueError(""Error code returned by bispev: %s"" % ier)"
1289288 0 19 21 23 0 nan nan nan nan nan nan nan nan nan nan nan nan "exception was raised in user function
User function arguments:
     z = +0.477503
    t0 = +57282.722190
    x0 = +0.000000
    x1 = -1.673541
     c = +0.952369
Original python exception in user function:
ValueError: Error code returned by bispev: 10
  File ""/anaconda3/envs/sdss_classification_3.7/lib/python3.7/site-packages/sncosmo/fitting.py"", line 46, in chisq
    zp=data.zp, zpsys=data.zpsys)
  File ""/anaconda3/envs/sdss_classification_3.7/lib/python3.7/site-packages/sncosmo/models.py"", line 1400, in bandflux
    raise e
  File ""/anaconda3/envs/sdss_classification_3.7/lib/python3.7/site-packages/sncosmo/models.py"", line 1397, in bandflux
    return _bandflux(self, band, time, zp, zpsys)
  File ""/anaconda3/envs/sdss_classification_3.7/lib/python3.7/site-packages/sncosmo/models.py"", line 154, in _bandflux
    fsum = _bandflux_single(model, b, time_or_phase[mask])
  File ""/anaconda3/envs/sdss_classification_3.7/lib/python3.7/site-packages/sncosmo/models.py"", line 116, in _bandflux_single
    f = model._flux(time_or_phase, wave)
  File ""/anaconda3/envs/sdss_classification_3.7/lib/python3.7/site-packages/sncosmo/models.py"", line 1272, in _flux
    f = a * self._source._flux(phase, restwave)
  File ""/Users/daniel/Github/SDSS-Classification/analysis_pipeline/_sn91bg_model/_model.py"", line 135, in _flux
    y = [self._model_flux[c1](phase / (st / 0.65), wave),
  File ""/anaconda3/envs/sdss_classification_3.7/lib/python3.7/site-packages/scipy/interpolate/fitpack2.py"", line 848, in __call__
    raise ValueError(""Error code returned by bispev: %s"" % ier)"
1289555 0 0 20 21 0 0.39967554212613066 57272.904385074515 2.4388574351675165e-17 1.4816956508776262 2.605057292659474e-07 0.004244832892244199 0.30118017685890663 7.987919389980915e-19 0.06268588556262214 0.00015999021791934798 28.292630375564475 36 "Covariance may not be accurate. Covariance not positive definite. Covariance forced positive definite."
1289600 0 17 17 16 0 nan nan nan nan nan nan nan nan nan nan nan nan "exception was raised in user function
User function arguments:
     z = +0.483032
    t0 = +57290.382629
    x0 = +0.000000
    x1 = -0.038583
     c = +0.822804
Original python exception in user function:
ValueError: Error code returned by bispev: 10
  File ""/anaconda3/envs/sdss_classification_3.7/lib/python3.7/site-packages/sncosmo/fitting.py"", line 46, in chisq
    zp=data.zp, zpsys=data.zpsys)
  File ""/anaconda3/envs/sdss_classification_3.7/lib/python3.7/site-packages/sncosmo/models.py"", line 1400, in bandflux
    raise e
  File ""/anaconda3/envs/sdss_classification_3.7/lib/python3.7/site-packages/sncosmo/models.py"", line 1397, in bandflux
    return _bandflux(self, band, time, zp, zpsys)
  File ""/anaconda3/envs/sdss_classification_3.7/lib/python3.7/site-packages/sncosmo/models.py"", line 154, in _bandflux
    fsum = _bandflux_single(model, b, time_or_phase[mask])
  File ""/anaconda3/envs/sdss_classification_3.7/lib/python3.7/site-packages/sncosmo/models.py"", line 116, in _bandflux_single
    f = model._flux(time_or_phase, wave)
  File ""/anaconda3/envs/sdss_classification_3.7/lib/python3.7/site-packages/sncosmo/models.py"", line 1272, in _flux
    f = a * self._source._flux(phase, restwave)
  File ""/Users/daniel/Github/SDSS-Classification/analysis_pipeline/_sn91bg_model/_model.py"", line 135, in _flux
    y = [self._model_flux[c1](phase / (st / 0.65), wave),
  File ""/anaconda3/envs/sdss_classification_3.7/lib/python3.7/site-packages/scipy/interpolate/fitpack2.py"", line 848, in __call__
    raise ValueError(""Error code returned by bispev: %s"" % ier)"
1289656 0 0 19 21 0 0.4014376218086902 57267.91930275729 2.0971385679918165e-17 1.4206325667805222 1.8878289392842973e-07 0.005860699580406581 0.21000278432256891 5.56498981343971e-19 0.04850436336952247 0.0005259406614175344 29.141778815729477 35 "Covariance may not be accurate. Covariance not positive definite. Covariance forced positive definite."
1289664 0 17 17 18 0 0.07007602509219366 57275.997053819934 1.5398432937114607e-16 1.4561717791639852 0.39111211601203855 0.002841165117371744 0.01523927012385684 1.8932770561045066e-18 0.010375531919618921 0.016085332375656985 136.35493046270068 47 "Covariance may not be accurate. Covariance not positive definite. Covariance forced positive definite."
1290779 0 11 11 12 0 0.17097981209083976 56888.49895211197 4.644589561135366e-17 1.3535663868373078 2.5228788585907047e-05 0.00342249522450265 0.046675454344949685 9.003108291334364e-19 0.031372434213444725 0.038830972856324086 57.91797709684674 29 "Covariance may not be accurate. Covariance not positive definite. Covariance forced positive definite."
1290816 0 10 10 10 0 0.05701986159000066 56884.91608917684 1.4670682870503384e-16 1.9822627089781713 6.45498948737e-09 0.0022887993414156746 0.22729296900797635 1.7279715890708944e-18 0.020918278942746935 2.7799826490648716e-05 195.07438137194538 25 "Covariance may not be accurate. Covariance not positive definite. Covariance forced positive definite."
1291080 0 0 13 14 0 nan nan nan nan nan nan nan nan nan nan nan nan "exception was raised in user function
User function arguments:
     z = +0.880250
    t0 = +56909.246816
    x0 = -762392281391349120.000000
    x1 = -40.915451
     c = +0.052416
Original python exception in user function:
ValueError: Error code returned by bispev: 10
  File ""/anaconda3/envs/sdss_classification_3.7/lib/python3.7/site-packages/sncosmo/fitting.py"", line 46, in chisq
    zp=data.zp, zpsys=data.zpsys)
  File ""/anaconda3/envs/sdss_classification_3.7/lib/python3.7/site-packages/sncosmo/models.py"", line 1400, in bandflux
    raise e
  File ""/anaconda3/envs/sdss_classification_3.7/lib/python3.7/site-packages/sncosmo/models.py"", line 1397, in bandflux
    return _bandflux(self, band, time, zp, zpsys)
  File ""/anaconda3/envs/sdss_classification_3.7/lib/python3.7/site-packages/sncosmo/models.py"", line 154, in _bandflux
    fsum = _bandflux_single(model, b, time_or_phase[mask])
  File ""/anaconda3/envs/sdss_classification_3.7/lib/python3.7/site-packages/sncosmo/models.py"", line 116, in _bandflux_single
    f = model._flux(time_or_phase, wave)
  File ""/anaconda3/envs/sdss_classification_3.7/lib/python3.7/site-packages/sncosmo/models.py"", line 1272, in _flux
    f = a * self._source._flux(phase, restwave)
  File ""/Users/daniel/Github/SDSS-Classification/analysis_pipeline/_sn91bg_model/_model.py"", line 135, in _flux
    y = [self._model_flux[c1](phase / (st / 0.65), wave),
  File ""/anaconda3/envs/sdss_classification_3.7/lib/python3.7/site-packages/scipy/interpolate/fitpack2.py"", line 848, in __call__
    raise ValueError(""Error code returned by bispev: %s"" % ier)"
1291090 0 13 11 14 0 0.05833459019310101 56901.17376548131 1.173129812901115e-16 1.7203571425285389 1.2873890892217688e-07 0.0026731306253271886 0.013575691802543588 2.502978467694967e-18 0.02624754985339638 6.467233272713924e-05 110.44772978276055 33 "Covariance may not be accurate. Covariance not positive definite. Covariance forced positive definite."
1291794 0 18 19 18 0 nan nan nan nan nan nan nan nan nan nan nan nan "exception was raised in user function
User function arguments:
     z = +0.483350
    t0 = +57283.876565
    x0 = +0.000000
    x1 = -0.179014
     c = +0.896900
Original python exception in user function:
ValueError: Error code returned by bispev: 10
  File ""/anaconda3/envs/sdss_classification_3.7/lib/python3.7/site-packages/sncosmo/fitting.py"", line 46, in chisq
    zp=data.zp, zpsys=data.zpsys)
  File ""/anaconda3/envs/sdss_classification_3.7/lib/python3.7/site-packages/sncosmo/models.py"", line 1400, in bandflux
    raise e
  File ""/anaconda3/envs/sdss_classification_3.7/lib/python3.7/site-packages/sncosmo/models.py"", line 1397, in bandflux
    return _bandflux(self, band, time, zp, zpsys)
  File ""/anaconda3/envs/sdss_classification_3.7/lib/python3.7/site-packages/sncosmo/models.py"", line 154, in _bandflux
    fsum = _bandflux_single(model, b, time_or_phase[mask])
  File ""/anaconda3/envs/sdss_classification_3.7/lib/python3.7/site-packages/sncosmo/models.py"", line 116, in _bandflux_single
    f = model._flux(time_or_phase, wave)
  File ""/anaconda3/envs/sdss_classification_3.7/lib/python3.7/site-packages/sncosmo/models.py"", line 1272, in _flux
    f = a * self._source._flux(phase, restwave)
  File ""/Users/daniel/Github/SDSS-Classification/analysis_pipeline/_sn91bg_model/_model.py"", line 135, in _flux
    y = [self._model_flux[c1](phase / (st / 0.65), wave),
  File ""/anaconda3/envs/sdss_classification_3.7/lib/python3.7/site-packages/scipy/interpolate/fitpack2.py"", line 848, in __call__
    raise ValueError(""Error code returned by bispev: %s"" % ier)"
1291957 0 15 14 15 0 0.09748424435633518 56901.31736333923 7.571609012021002e-17 1.5850167618455964 0.20428935031020373 0.0009381536624326753 0.02257625788115547 1.292841640002539e-18 0.01681746644476993 0.019958392652909718 81.23817740732082 39 "Covariance may not be accurate. Covariance not positive definite. Covariance forced positive definite."
1292145 0 0 19 19 0 0.379081764720092 57271.24420001629 1.8854232410712618e-17 1.7310198394085872 0.20222794893942542 0.0016771131290658214 0.0507233640528284 5.355711122170213e-19 0.031850888931437504 0.03139639232354707 24.477795565016287 33 "Covariance may not be accurate. Covariance not positive definite. Covariance forced positive definite."
1292195 0 0 0 19 0 0.6382547643379888 57279.19506545777 1.2844271000902949e-17 1.4005185383525374 0.6821639499182557 0.0021925407280403153 0.12069346108182799 3.0721408139246074e-19 0.020817106696962736 0.02306749255630025 18.652201742554098 14 "Covariance may not be accurate. Covariance not positive definite. Covariance forced positive definite."
1292332 0 12 13 12 0 0.07331941406650583 56897.45115474831 1.1968288119847338e-16 1.7105546491386765 3.774823842339625e-06 0.006348549333556726 0.029264710865390953 3.4006963675650487e-18 0.04502995886718485 0.0020642007588216604 43.3106487795858 32 "Covariance may not be accurate. Covariance not positive definite. Covariance forced positive definite."
1292336 0 12 13 12 0 0.3937338693821779 56900.67312249328 7.302078715852109e-17 1.5943376068920683 1.4793300306958912e-08 0.0009440653819541012 0.07151194212565315 1.596159296241048e-18 0.04020588283034366 5.59462228608143e-06 586.7172279127892 32 "Covariance may not be accurate. Covariance not positive definite. Covariance forced positive definite."
1292560 0 11 14 13 0 0.05491387372430278 56900.77670279328 1.674548662339117e-16 1.6506505851298117 8.691380642966706e-08 0.0022369435131987456 0.11356224467090215 2.6742165565300063e-18 0.02213130201504338 2.0281312057474077e-05 241.93869365691455 33 "Covariance may not be accurate. Covariance not positive definite. Covariance forced positive definite."
1293319 0 14 14 15 0 nan nan nan nan nan nan nan nan nan nan nan nan "exception was raised in user function
User function arguments:
     z = +0.460258
    t0 = +56898.121456
    x0 = +0.000000
    x1 = -1.231251
     c = +0.948776
Original python exception in user function:
ValueError: Error code returned by bispev: 10
  File ""/anaconda3/envs/sdss_classification_3.7/lib/python3.7/site-packages/sncosmo/fitting.py"", line 46, in chisq
    zp=data.zp, zpsys=data.zpsys)
  File ""/anaconda3/envs/sdss_classification_3.7/lib/python3.7/site-packages/sncosmo/models.py"", line 1400, in bandflux
    raise e
  File ""/anaconda3/envs/sdss_classification_3.7/lib/python3.7/site-packages/sncosmo/models.py"", line 1397, in bandflux
    return _bandflux(self, band, time, zp, zpsys)
  File ""/anaconda3/envs/sdss_classification_3.7/lib/python3.7/site-packages/sncosmo/models.py"", line 154, in _bandflux
    fsum = _bandflux_single(model, b, time_or_phase[mask])
  File ""/anaconda3/envs/sdss_classification_3.7/lib/python3.7/site-packages/sncosmo/models.py"", line 116, in _bandflux_single
    f = model._flux(time_or_phase, wave)
  File ""/anaconda3/envs/sdss_classification_3.7/lib/python3.7/site-packages/sncosmo/models.py"", line 1272, in _flux
    f = a * self._source._flux(phase, restwave)
  File ""/Users/daniel/Github/SDSS-Classification/analysis_pipeline/_sn91bg_model/_model.py"", line 135, in _flux
    y = [self._model_flux[c1](phase / (st / 0.65), wave),
  File ""/anaconda3/envs/sdss_classification_3.7/lib/python3.7/site-packages/scipy/interpolate/fitpack2.py"", line 848, in __call__
    raise ValueError(""Error code returned by bispev: %s"" % ier)"
1293758 10 7 1 17 0 nan nan nan nan nan nan nan nan nan nan nan nan "exception was raised in user function
User function arguments:
     z = +0.389083
    t0 = +56897.686643
    x0 = +0.000000
    x1 = -1.378882
     c = +0.901762
Original python exception in user function:
ValueError: Error code returned by bispev: 10
  File ""/anaconda3/envs/sdss_classification_3.7/lib/python3.7/site-packages/sncosmo/fitting.py"", line 46, in chisq
    zp=data.zp, zpsys=data.zpsys)
  File ""/anaconda3/envs/sdss_classification_3.7/lib/python3.7/site-packages/sncosmo/models.py"", line 1400, in bandflux
    raise e
  File ""/anaconda3/envs/sdss_classification_3.7/lib/python3.7/site-packages/sncosmo/models.py"", line 1397, in bandflux
    return _bandflux(self, band, time, zp, zpsys)
  File ""/anaconda3/envs/sdss_classification_3.7/lib/python3.7/site-packages/sncosmo/models.py"", line 154, in _bandflux
    fsum = _bandflux_single(model, b, time_or_phase[mask])
  File ""/anaconda3/envs/sdss_classification_3.7/lib/python3.7/site-packages/sncosmo/models.py"", line 116, in _bandflux_single
    f = model._flux(time_or_phase, wave)
  File ""/anaconda3/envs/sdss_classification_3.7/lib/python3.7/site-packages/sncosmo/models.py"", line 1272, in _flux
    f = a * self._source._flux(phase, restwave)
  File ""/Users/daniel/Github/SDSS-Classification/analysis_pipeline/_sn91bg_model/_model.py"", line 135, in _flux
    y = [self._model_flux[c1](phase / (st / 0.65), wave),
  File ""/anaconda3/envs/sdss_classification_3.7/lib/python3.7/site-packages/scipy/interpolate/fitpack2.py"", line 848, in __call__
    raise ValueError(""Error code returned by bispev: %s"" % ier)"
1294014 0 13 9 6 0 0.4584832863009695 56921.888415060486 5.968864580167705e-17 1.5205109557806935 8.011853902534227e-09 0.0010624205039872492 0.4281037347209349 1.6476355251131695e-18 0.037575830966827144 1.286107156400762e-05 131.84971677737994 23 "Covariance may not be accurate. Covariance not positive definite. Covariance forced positive definite."
1294743 0 11 11 14 0 0.19143069494775192 56909.03024962718 4.602440328798817e-17 1.6005464098213622 0.004708695463710166 0.0012934670002385518 0.15312714920582948 6.4881824146279515e-19 0.014471556982843095 0.014744128985558658 47.77591730395745 31 "Covariance may not be accurate. Covariance not positive definite. Covariance forced positive definite."
1295027 0 18 17 19 0 nan nan nan nan nan nan nan nan nan nan nan nan "exception was raised in user function
User function arguments:
     z = +0.462230
    t0 = +56893.172584
    x0 = +0.000000
    x1 = -1.162117
     c = +0.949323
Original python exception in user function:
ValueError: Error code returned by bispev: 10
  File ""/anaconda3/envs/sdss_classification_3.7/lib/python3.7/site-packages/sncosmo/fitting.py"", line 46, in chisq
    zp=data.zp, zpsys=data.zpsys)
  File ""/anaconda3/envs/sdss_classification_3.7/lib/python3.7/site-packages/sncosmo/models.py"", line 1400, in bandflux
    raise e
  File ""/anaconda3/envs/sdss_classification_3.7/lib/python3.7/site-packages/sncosmo/models.py"", line 1397, in bandflux
    return _bandflux(self, band, time, zp, zpsys)
  File ""/anaconda3/envs/sdss_classification_3.7/lib/python3.7/site-packages/sncosmo/models.py"", line 154, in _bandflux
    fsum = _bandflux_single(model, b, time_or_phase[mask])
  File ""/anaconda3/envs/sdss_classification_3.7/lib/python3.7/site-packages/sncosmo/models.py"", line 116, in _bandflux_single
    f = model._flux(time_or_phase, wave)
  File ""/anaconda3/envs/sdss_classification_3.7/lib/python3.7/site-packages/sncosmo/models.py"", line 1272, in _flux
    f = a * self._source._flux(phase, restwave)
  File ""/Users/daniel/Github/SDSS-Classification/analysis_pipeline/_sn91bg_model/_model.py"", line 135, in _flux
    y = [self._model_flux[c1](phase / (st / 0.65), wave),
  File ""/anaconda3/envs/sdss_classification_3.7/lib/python3.7/site-packages/scipy/interpolate/fitpack2.py"", line 848, in __call__
    raise ValueError(""Error code returned by bispev: %s"" % ier)"
1295256 0 0 16 17 0 0.40014632921622595 56924.83297103267 2.9913399299720575e-17 1.40781987799942 6.707127109262245e-08 0.001293670507625716 0.10233667910506483 5.852188638179596e-19 0.03666491701443411 2.187708554679535e-05 98.30077904126219 28 "Covariance may not be accurate. Covariance not positive definite. Covariance forced positive definite."
1295305 0 0 15 18 0 0.3983153528157129 56913.75466085665 1.606308548644995e-17 1.4948085945603902 2.7439911454152366e-10 0.0007333228632643296 0.1519945183681557 1.599016188431174e-19 0.016978812570069914 1.2349801575439745e-05 66.21338013384114 28 "Covariance may not be accurate. Covariance not positive definite. Covariance forced positive definite."
1295921 0 0 14 13 0 0.4060685966691547 56907.765213880986 1.970908650889974e-17 1.7735917534841976 1.1308105413887493e-05 0.005488670743035828 0.4492431951366598 5.156286146064607e-19 0.0418211282322587 0.0005153787681655697 19.61982736787207 22 "Covariance may not be accurate. Covariance not positive definite. Covariance forced positive definite."
1296273 0 16 15 16 0 nan nan nan nan nan nan nan nan nan nan nan nan "exception was raised in user function
User function arguments:
     z = +0.464335
    t0 = +56893.502925
    x0 = +0.000000
    x1 = -0.550523
     c = +0.944356
Original python exception in user function:
ValueError: Error code returned by bispev: 10
  File ""/anaconda3/envs/sdss_classification_3.7/lib/python3.7/site-packages/sncosmo/fitting.py"", line 46, in chisq
    zp=data.zp, zpsys=data.zpsys)
  File ""/anaconda3/envs/sdss_classification_3.7/lib/python3.7/site-packages/sncosmo/models.py"", line 1400, in bandflux
    raise e
  File ""/anaconda3/envs/sdss_classification_3.7/lib/python3.7/site-packages/sncosmo/models.py"", line 1397, in bandflux
    return _bandflux(self, band, time, zp, zpsys)
  File ""/anaconda3/envs/sdss_classification_3.7/lib/python3.7/site-packages/sncosmo/models.py"", line 154, in _bandflux
    fsum = _bandflux_single(model, b, time_or_phase[mask])
  File ""/anaconda3/envs/sdss_classification_3.7/lib/python3.7/site-packages/sncosmo/models.py"", line 116, in _bandflux_single
    f = model._flux(time_or_phase, wave)
  File ""/anaconda3/envs/sdss_classification_3.7/lib/python3.7/site-packages/sncosmo/models.py"", line 1272, in _flux
    f = a * self._source._flux(phase, restwave)
  File ""/Users/daniel/Github/SDSS-Classification/analysis_pipeline/_sn91bg_model/_model.py"", line 135, in _flux
    y = [self._model_flux[c1](phase / (st / 0.65), wave),
  File ""/anaconda3/envs/sdss_classification_3.7/lib/python3.7/site-packages/scipy/interpolate/fitpack2.py"", line 848, in __call__
    raise ValueError(""Error code returned by bispev: %s"" % ier)"
1296321 0 13 12 13 0 nan nan nan nan nan nan nan nan nan nan nan nan "exception was raised in user function
User function arguments:
     z = +0.472669
    t0 = +56932.754433
    x0 = +0.000000
    x1 = -0.708345
     c = +0.968110
Original python exception in user function:
ValueError: Error code returned by bispev: 10
  File ""/anaconda3/envs/sdss_classification_3.7/lib/python3.7/site-packages/sncosmo/fitting.py"", line 46, in chisq
    zp=data.zp, zpsys=data.zpsys)
  File ""/anaconda3/envs/sdss_classification_3.7/lib/python3.7/site-packages/sncosmo/models.py"", line 1400, in bandflux
    raise e
  File ""/anaconda3/envs/sdss_classification_3.7/lib/python3.7/site-packages/sncosmo/models.py"", line 1397, in bandflux
    return _bandflux(self, band, time, zp, zpsys)
  File ""/anaconda3/envs/sdss_classification_3.7/lib/python3.7/site-packages/sncosmo/models.py"", line 154, in _bandflux
    fsum = _bandflux_single(model, b, time_or_phase[mask])
  File ""/anaconda3/envs/sdss_classification_3.7/lib/python3.7/site-packages/sncosmo/models.py"", line 116, in _bandflux_single
    f = model._flux(time_or_phase, wave)
  File ""/anaconda3/envs/sdss_classification_3.7/lib/python3.7/site-packages/sncosmo/models.py"", line 1272, in _flux
    f = a * self._source._flux(phase, restwave)
  File ""/Users/daniel/Github/SDSS-Classification/analysis_pipeline/_sn91bg_model/_model.py"", line 135, in _flux
    y = [self._model_flux[c1](phase / (st / 0.65), wave),
  File ""/anaconda3/envs/sdss_classification_3.7/lib/python3.7/site-packages/scipy/interpolate/fitpack2.py"", line 848, in __call__
    raise ValueError(""Error code returned by bispev: %s"" % ier)"
1296657 4 4 10 14 0 nan nan nan nan nan nan nan nan nan nan nan nan "exception was raised in user function
User function arguments:
     z = +0.389795
    t0 = +56872.528311
    x0 = +0.000000
    x1 = -0.340701
     c = +0.901495
Original python exception in user function:
ValueError: Error code returned by bispev: 10
  File ""/anaconda3/envs/sdss_classification_3.7/lib/python3.7/site-packages/sncosmo/fitting.py"", line 46, in chisq
    zp=data.zp, zpsys=data.zpsys)
  File ""/anaconda3/envs/sdss_classification_3.7/lib/python3.7/site-packages/sncosmo/models.py"", line 1400, in bandflux
    raise e
  File ""/anaconda3/envs/sdss_classification_3.7/lib/python3.7/site-packages/sncosmo/models.py"", line 1397, in bandflux
    return _bandflux(self, band, time, zp, zpsys)
  File ""/anaconda3/envs/sdss_classification_3.7/lib/python3.7/site-packages/sncosmo/models.py"", line 154, in _bandflux
    fsum = _bandflux_single(model, b, time_or_phase[mask])
  File ""/anaconda3/envs/sdss_classification_3.7/lib/python3.7/site-packages/sncosmo/models.py"", line 116, in _bandflux_single
    f = model._flux(time_or_phase, wave)
  File ""/anaconda3/envs/sdss_classification_3.7/lib/python3.7/site-packages/sncosmo/models.py"", line 1272, in _flux
    f = a * self._source._flux(phase, restwave)
  File ""/Users/daniel/Github/SDSS-Classification/analysis_pipeline/_sn91bg_model/_model.py"", line 135, in _flux
    y = [self._model_flux[c1](phase / (st / 0.65), wave),
  File ""/anaconda3/envs/sdss_classification_3.7/lib/python3.7/site-packages/scipy/interpolate/fitpack2.py"", line 848, in __call__
    raise ValueError(""Error code returned by bispev: %s"" % ier)"
1297026 0 13 13 16 0 nan nan nan nan nan nan nan nan nan nan nan nan "exception was raised in user function
User function arguments:
     z = +0.628934
    t0 = +56932.978332
    x0 = +0.000000
    x1 = -1.008314
     c = +0.934028
Original python exception in user function:
ValueError: Error code returned by bispev: 10
  File ""/anaconda3/envs/sdss_classification_3.7/lib/python3.7/site-packages/sncosmo/fitting.py"", line 46, in chisq
    zp=data.zp, zpsys=data.zpsys)
  File ""/anaconda3/envs/sdss_classification_3.7/lib/python3.7/site-packages/sncosmo/models.py"", line 1400, in bandflux
    raise e
  File ""/anaconda3/envs/sdss_classification_3.7/lib/python3.7/site-packages/sncosmo/models.py"", line 1397, in bandflux
    return _bandflux(self, band, time, zp, zpsys)
  File ""/anaconda3/envs/sdss_classification_3.7/lib/python3.7/site-packages/sncosmo/models.py"", line 154, in _bandflux
    fsum = _bandflux_single(model, b, time_or_phase[mask])
  File ""/anaconda3/envs/sdss_classification_3.7/lib/python3.7/site-packages/sncosmo/models.py"", line 116, in _bandflux_single
    f = model._flux(time_or_phase, wave)
  File ""/anaconda3/envs/sdss_classification_3.7/lib/python3.7/site-packages/sncosmo/models.py"", line 1272, in _flux
    f = a * self._source._flux(phase, restwave)
  File ""/Users/daniel/Github/SDSS-Classification/analysis_pipeline/_sn91bg_model/_model.py"", line 135, in _flux
    y = [self._model_flux[c1](phase / (st / 0.65), wave),
  File ""/anaconda3/envs/sdss_classification_3.7/lib/python3.7/site-packages/scipy/interpolate/fitpack2.py"", line 848, in __call__
    raise ValueError(""Error code returned by bispev: %s"" % ier)"
1297465 0 14 16 16 0 0.17103221452592784 56936.28376386026 7.694334954946089e-17 1.7150592030777456 1.092459456231154e-11 0.0009068310651451084 0.014984184996137628 6.669176039364244e-19 0.014204036470561267 5.2509521425436745e-06 553.6627724683055 41 "Covariance may not be accurate. Covariance not positive definite. Covariance forced positive definite."
1298281 0 15 14 15 0 nan nan nan nan nan nan nan nan nan nan nan nan "exception was raised in user function
User function arguments:
     z = +0.472507
    t0 = +56933.641492
    x0 = +0.000000
    x1 = -0.238541
     c = +0.957351
Original python exception in user function:
ValueError: Error code returned by bispev: 10
  File ""/anaconda3/envs/sdss_classification_3.7/lib/python3.7/site-packages/sncosmo/fitting.py"", line 46, in chisq
    zp=data.zp, zpsys=data.zpsys)
  File ""/anaconda3/envs/sdss_classification_3.7/lib/python3.7/site-packages/sncosmo/models.py"", line 1400, in bandflux
    raise e
  File ""/anaconda3/envs/sdss_classification_3.7/lib/python3.7/site-packages/sncosmo/models.py"", line 1397, in bandflux
    return _bandflux(self, band, time, zp, zpsys)
  File ""/anaconda3/envs/sdss_classification_3.7/lib/python3.7/site-packages/sncosmo/models.py"", line 154, in _bandflux
    fsum = _bandflux_single(model, b, time_or_phase[mask])
  File ""/anaconda3/envs/sdss_classification_3.7/lib/python3.7/site-packages/sncosmo/models.py"", line 116, in _bandflux_single
    f = model._flux(time_or_phase, wave)
  File ""/anaconda3/envs/sdss_classification_3.7/lib/python3.7/site-packages/sncosmo/models.py"", line 1272, in _flux
    f = a * self._source._flux(phase, restwave)
  File ""/Users/daniel/Github/SDSS-Classification/analysis_pipeline/_sn91bg_model/_model.py"", line 135, in _flux
    y = [self._model_flux[c1](phase / (st / 0.65), wave),
  File ""/anaconda3/envs/sdss_classification_3.7/lib/python3.7/site-packages/scipy/interpolate/fitpack2.py"", line 848, in __call__
    raise ValueError(""Error code returned by bispev: %s"" % ier)"
1298893 0 4 5 10 0 0.4817158311808538 56960.79027368966 1.3353718212478609e-16 0.4802421265742376 3.938512366241653e-07 0.007366629562531063 0.10398260780493729 9.402716051316516e-18 0.010951716471304789 0.00012070819737572402 1135.6315254738613 14 "Covariance may not be accurate. Covariance not positive definite. Covariance forced positive definite."
1299643 0 17 16 17 0 0.10922785904663636 56937.11229549284 6.634600249444508e-17 1.604600512557942 6.47619087706941e-06 0.0023332668257220954 0.08684818454275955 1.2278530355387427e-18 0.02922230739246017 0.05348742463660869 96.07711741363241 45 "Covariance may not be accurate. Covariance not positive definite. Covariance forced positive definite."
1299775 0 6 9 14 0 0.04896063553474654 56938.72277607286 2.578714932737953e-16 1.6574743725283259 5.888827808164798e-07 0.008061086046881168 0.040811877632222604 1.1264929285732437e-17 0.050682294184606784 0.0007571420849386556 47.387593066007454 24 "Covariance may not be accurate. Covariance not positive definite. Covariance forced positive definite."
1299785 0 16 17 15 0 nan nan nan nan nan nan nan nan nan nan nan nan "exception was raised in user function
User function arguments:
     z = +0.461192
    t0 = +56935.861648
    x0 = +0.000000
    x1 = -0.186117
     c = +0.930008
Original python exception in user function:
ValueError: Error code returned by bispev: 10
  File ""/anaconda3/envs/sdss_classification_3.7/lib/python3.7/site-packages/sncosmo/fitting.py"", line 46, in chisq
    zp=data.zp, zpsys=data.zpsys)
  File ""/anaconda3/envs/sdss_classification_3.7/lib/python3.7/site-packages/sncosmo/models.py"", line 1400, in bandflux
    raise e
  File ""/anaconda3/envs/sdss_classification_3.7/lib/python3.7/site-packages/sncosmo/models.py"", line 1397, in bandflux
    return _bandflux(self, band, time, zp, zpsys)
  File ""/anaconda3/envs/sdss_classification_3.7/lib/python3.7/site-packages/sncosmo/models.py"", line 154, in _bandflux
    fsum = _bandflux_single(model, b, time_or_phase[mask])
  File ""/anaconda3/envs/sdss_classification_3.7/lib/python3.7/site-packages/sncosmo/models.py"", line 116, in _bandflux_single
    f = model._flux(time_or_phase, wave)
  File ""/anaconda3/envs/sdss_classification_3.7/lib/python3.7/site-packages/sncosmo/models.py"", line 1272, in _flux
    f = a * self._source._flux(phase, restwave)
  File ""/Users/daniel/Github/SDSS-Classification/analysis_pipeline/_sn91bg_model/_model.py"", line 135, in _flux
    y = [self._model_flux[c1](phase / (st / 0.65), wave),
  File ""/anaconda3/envs/sdss_classification_3.7/lib/python3.7/site-packages/scipy/interpolate/fitpack2.py"", line 848, in __call__
    raise ValueError(""Error code returned by bispev: %s"" % ier)"
1300516 0 17 18 18 0 nan nan nan nan nan nan nan nan nan nan nan nan "exception was raised in user function
User function arguments:
     z = +0.461645
    t0 = +56942.413657
    x0 = +0.000000
    x1 = -7.482895
     c = +0.823507
Original python exception in user function:
ValueError: Error code returned by bispev: 10
  File ""/anaconda3/envs/sdss_classification_3.7/lib/python3.7/site-packages/sncosmo/fitting.py"", line 46, in chisq
    zp=data.zp, zpsys=data.zpsys)
  File ""/anaconda3/envs/sdss_classification_3.7/lib/python3.7/site-packages/sncosmo/models.py"", line 1400, in bandflux
    raise e
  File ""/anaconda3/envs/sdss_classification_3.7/lib/python3.7/site-packages/sncosmo/models.py"", line 1397, in bandflux
    return _bandflux(self, band, time, zp, zpsys)
  File ""/anaconda3/envs/sdss_classification_3.7/lib/python3.7/site-packages/sncosmo/models.py"", line 154, in _bandflux
    fsum = _bandflux_single(model, b, time_or_phase[mask])
  File ""/anaconda3/envs/sdss_classification_3.7/lib/python3.7/site-packages/sncosmo/models.py"", line 116, in _bandflux_single
    f = model._flux(time_or_phase, wave)
  File ""/anaconda3/envs/sdss_classification_3.7/lib/python3.7/site-packages/sncosmo/models.py"", line 1272, in _flux
    f = a * self._source._flux(phase, restwave)
  File ""/Users/daniel/Github/SDSS-Classification/analysis_pipeline/_sn91bg_model/_model.py"", line 135, in _flux
    y = [self._model_flux[c1](phase / (st / 0.65), wave),
  File ""/anaconda3/envs/sdss_classification_3.7/lib/python3.7/site-packages/scipy/interpolate/fitpack2.py"", line 848, in __call__
    raise ValueError(""Error code returned by bispev: %s"" % ier)"
1300912 0 15 17 17 0 0.1749211028220705 56944.00563643578 5.0095775245510794e-17 1.5113811525335177 1.2926994169548678e-07 0.0033884551607541585 0.01961262110125972 4.365414514730161e-19 0.010805563875438066 0.00015167408362359858 179.1764750171703 44 "Covariance may not be accurate. Covariance not positive definite. Covariance forced positive definite."
1301933 0 16 15 16 0 0.1049426131847952 56949.20170866365 7.635549409366981e-17 1.4931151832056442 0.008529454937853453 0.0005274893787548182 0.007077719070366584 3.9743344848259784e-19 0.005210878060104836 0.00720121751415248 579.6048212270023 42 "Covariance may not be accurate. Covariance not positive definite. Covariance forced positive definite."
1302058 0 14 16 15 0 0.1716943976300742 56957.457336168285 2.2244301663633316e-16 1.5900903698629203 3.187402453086463e-09 0.0011015728102019423 0.05774618919167551 3.831554381519675e-18 0.03234329242461174 8.699644676896101e-06 996.3871626184346 40 "Covariance may not be accurate. Covariance not positive definite. Covariance forced positive definite."
1302141 0 0 22 24 0 0.3981658026929497 57277.12094172755 2.214476142452515e-17 1.4482305447113228 0.15525724805598712 0.005403856794575251 0.07736401767397183 6.527122520375934e-19 0.022115052993784485 0.03174638371436164 51.1385128053649 41 "Covariance may not be accurate. Covariance not positive definite. Covariance forced positive definite."
1302187 0 9 15 16 0 nan nan nan nan nan nan nan nan nan nan nan nan "exception was raised in user function
User function arguments:
     z = +0.470236
    t0 = +56947.173857
    x0 = +0.000000
    x1 = -5.256761
     c = +0.985056
Original python exception in user function:
ValueError: Error code returned by bispev: 10
  File ""/anaconda3/envs/sdss_classification_3.7/lib/python3.7/site-packages/sncosmo/fitting.py"", line 46, in chisq
    zp=data.zp, zpsys=data.zpsys)
  File ""/anaconda3/envs/sdss_classification_3.7/lib/python3.7/site-packages/sncosmo/models.py"", line 1400, in bandflux
    raise e
  File ""/anaconda3/envs/sdss_classification_3.7/lib/python3.7/site-packages/sncosmo/models.py"", line 1397, in bandflux
    return _bandflux(self, band, time, zp, zpsys)
  File ""/anaconda3/envs/sdss_classification_3.7/lib/python3.7/site-packages/sncosmo/models.py"", line 154, in _bandflux
    fsum = _bandflux_single(model, b, time_or_phase[mask])
  File ""/anaconda3/envs/sdss_classification_3.7/lib/python3.7/site-packages/sncosmo/models.py"", line 116, in _bandflux_single
    f = model._flux(time_or_phase, wave)
  File ""/anaconda3/envs/sdss_classification_3.7/lib/python3.7/site-packages/sncosmo/models.py"", line 1272, in _flux
    f = a * self._source._flux(phase, restwave)
  File ""/Users/daniel/Github/SDSS-Classification/analysis_pipeline/_sn91bg_model/_model.py"", line 135, in _flux
    y = [self._model_flux[c1](phase / (st / 0.65), wave),
  File ""/anaconda3/envs/sdss_classification_3.7/lib/python3.7/site-packages/scipy/interpolate/fitpack2.py"", line 848, in __call__
    raise ValueError(""Error code returned by bispev: %s"" % ier)"
1302523 0 15 13 15 0 0.17522601748600225 57284.600444202195 4.5154773737801044e-17 1.5034219134470426 1.856568154767757e-06 0.007994473994317547 0.035578103095758706 4.77093290567605e-19 0.010952226752965939 0.00016915845260248585 68.22651922770298 38 "Covariance may not be accurate. Covariance not positive definite. Covariance forced positive definite."
1302648 0 13 15 15 0 0.17023183090584937 56946.721426838514 1.086649710474721e-16 1.506756849862452 2.7616986475464955e-10 0.001949996350457353 0.1425576586589159 2.9177796173475817e-18 0.044995943523241946 3.774043779444791e-05 120.34638276088131 38 "Covariance may not be accurate. Covariance not positive definite. Covariance forced positive definite."
1303004 0 18 18 19 0 nan nan nan nan nan nan nan nan nan nan nan nan "exception was raised in user function
User function arguments:
     z = +0.469626
    t0 = +56961.797559
    x0 = +0.000000
    x1 = -2.986140
     c = +0.917182
Original python exception in user function:
ValueError: Error code returned by bispev: 10
  File ""/anaconda3/envs/sdss_classification_3.7/lib/python3.7/site-packages/sncosmo/fitting.py"", line 46, in chisq
    zp=data.zp, zpsys=data.zpsys)
  File ""/anaconda3/envs/sdss_classification_3.7/lib/python3.7/site-packages/sncosmo/models.py"", line 1400, in bandflux
    raise e
  File ""/anaconda3/envs/sdss_classification_3.7/lib/python3.7/site-packages/sncosmo/models.py"", line 1397, in bandflux
    return _bandflux(self, band, time, zp, zpsys)
  File ""/anaconda3/envs/sdss_classification_3.7/lib/python3.7/site-packages/sncosmo/models.py"", line 154, in _bandflux
    fsum = _bandflux_single(model, b, time_or_phase[mask])
  File ""/anaconda3/envs/sdss_classification_3.7/lib/python3.7/site-packages/sncosmo/models.py"", line 116, in _bandflux_single
    f = model._flux(time_or_phase, wave)
  File ""/anaconda3/envs/sdss_classification_3.7/lib/python3.7/site-packages/sncosmo/models.py"", line 1272, in _flux
    f = a * self._source._flux(phase, restwave)
  File ""/Users/daniel/Github/SDSS-Classification/analysis_pipeline/_sn91bg_model/_model.py"", line 135, in _flux
    y = [self._model_flux[c1](phase / (st / 0.65), wave),
  File ""/anaconda3/envs/sdss_classification_3.7/lib/python3.7/site-packages/scipy/interpolate/fitpack2.py"", line 848, in __call__
    raise ValueError(""Error code returned by bispev: %s"" % ier)"
1303279 0 8 9 17 0 0.0441172969701168 56962.10075051028 3.7605241157629824e-16 1.6312623688057475 5.761015109406742e-09 0.003707818830740589 0.1410964057140518 1.4012511995174235e-17 0.07793464893231662 5.310632220245637e-05 140.3663519296681 29 "Covariance may not be accurate. Covariance not positive definite. Covariance forced positive definite."
1303496 0 10 9 13 0 nan nan nan nan nan nan nan nan nan nan nan nan "exception was raised in user function
User function arguments:
     z = +0.473592
    t0 = +56962.824024
    x0 = +0.000000
    x1 = -1.908398
     c = +0.894493
Original python exception in user function:
ValueError: Error code returned by bispev: 10
  File ""/anaconda3/envs/sdss_classification_3.7/lib/python3.7/site-packages/sncosmo/fitting.py"", line 46, in chisq
    zp=data.zp, zpsys=data.zpsys)
  File ""/anaconda3/envs/sdss_classification_3.7/lib/python3.7/site-packages/sncosmo/models.py"", line 1400, in bandflux
    raise e
  File ""/anaconda3/envs/sdss_classification_3.7/lib/python3.7/site-packages/sncosmo/models.py"", line 1397, in bandflux
    return _bandflux(self, band, time, zp, zpsys)
  File ""/anaconda3/envs/sdss_classification_3.7/lib/python3.7/site-packages/sncosmo/models.py"", line 154, in _bandflux
    fsum = _bandflux_single(model, b, time_or_phase[mask])
  File ""/anaconda3/envs/sdss_classification_3.7/lib/python3.7/site-packages/sncosmo/models.py"", line 116, in _bandflux_single
    f = model._flux(time_or_phase, wave)
  File ""/anaconda3/envs/sdss_classification_3.7/lib/python3.7/site-packages/sncosmo/models.py"", line 1272, in _flux
    f = a * self._source._flux(phase, restwave)
  File ""/Users/daniel/Github/SDSS-Classification/analysis_pipeline/_sn91bg_model/_model.py"", line 135, in _flux
    y = [self._model_flux[c1](phase / (st / 0.65), wave),
  File ""/anaconda3/envs/sdss_classification_3.7/lib/python3.7/site-packages/scipy/interpolate/fitpack2.py"", line 848, in __call__
    raise ValueError(""Error code returned by bispev: %s"" % ier)"
1303883 0 17 18 20 0 0.17093318524480883 57283.0961866068 1.1551134623142098e-16 1.6917844032077987 1.084396961115175e-09 0.0016545087674765951 0.1469465397967724 2.3673524988297047e-18 0.04355594302659148 2.199486889589708e-05 148.93668025161577 50 "Covariance may not be accurate. Covariance not positive definite. Covariance forced positive definite."
1303952 0 0 21 21 0 0.400987474959538 57284.45179558282 2.5554224366636775e-17 1.202660784577631 1.2381139701811428e-06 0.002893450766530914 0.12771751216132543 9.181910893678843e-19 0.04138183302686911 0.00011148972694360881 40.674656736367524 37 "Covariance may not be accurate. Covariance not positive definite. Covariance forced positive definite."
1304127 0 0 0 21 0 0.3653815055523536 57279.414279517216 1.422212533796221e-17 2.0077568201022964 0.31591261656258823 0.005632653463942705 0.11811810322615202 5.6726326097972275e-19 0.052303663616186866 0.05628628524839621 20.209514967206495 16 "Covariance may not be accurate. Covariance not positive definite. Covariance forced positive definite."
1304442 0 2 2 7 0 0.5941104033812642 57036.450093209285 5.966316067639277e-17 9731.07220222649 0.09798301985138336 0.0004998107153188491 43.132897495208454 1.06760301953829e-18 1824.5769227056492 0.017126861357358386 788.1468382829569 6 "Covariance may not be accurate. Covariance not positive definite. Covariance forced positive definite."
1304678 0 10 13 16 0 nan nan nan nan nan nan nan nan nan nan nan nan "exception was raised in user function
User function arguments:
     z = +0.468193
    t0 = +56960.961421
    x0 = +0.000000
    x1 = -1.087934
     c = +0.979639
Original python exception in user function:
ValueError: Error code returned by bispev: 10
  File ""/anaconda3/envs/sdss_classification_3.7/lib/python3.7/site-packages/sncosmo/fitting.py"", line 46, in chisq
    zp=data.zp, zpsys=data.zpsys)
  File ""/anaconda3/envs/sdss_classification_3.7/lib/python3.7/site-packages/sncosmo/models.py"", line 1400, in bandflux
    raise e
  File ""/anaconda3/envs/sdss_classification_3.7/lib/python3.7/site-packages/sncosmo/models.py"", line 1397, in bandflux
    return _bandflux(self, band, time, zp, zpsys)
  File ""/anaconda3/envs/sdss_classification_3.7/lib/python3.7/site-packages/sncosmo/models.py"", line 154, in _bandflux
    fsum = _bandflux_single(model, b, time_or_phase[mask])
  File ""/anaconda3/envs/sdss_classification_3.7/lib/python3.7/site-packages/sncosmo/models.py"", line 116, in _bandflux_single
    f = model._flux(time_or_phase, wave)
  File ""/anaconda3/envs/sdss_classification_3.7/lib/python3.7/site-packages/sncosmo/models.py"", line 1272, in _flux
    f = a * self._source._flux(phase, restwave)
  File ""/Users/daniel/Github/SDSS-Classification/analysis_pipeline/_sn91bg_model/_model.py"", line 135, in _flux
    y = [self._model_flux[c1](phase / (st / 0.65), wave),
  File ""/anaconda3/envs/sdss_classification_3.7/lib/python3.7/site-packages/scipy/interpolate/fitpack2.py"", line 848, in __call__
    raise ValueError(""Error code returned by bispev: %s"" % ier)"
1305504 0 0 14 16 0 0.3984512083591867 56971.59038920127 2.2079740746673025e-17 1.513075884874258 8.367424531030565e-09 0.001016956272489461 0.11196939538422157 2.2378767068596575e-19 0.019889524005943123 1.137773171716594e-05 67.51612377860599 25 "Covariance may not be accurate. Covariance not positive definite. Covariance forced positive definite."
1305626 0 15 13 13 0 0.17159610555283372 56972.48322244787 7.075418655612154e-17 1.5104324209833326 3.7881129899552946e-09 0.0013727106881673556 0.1500472050793178 5.470839429948575e-19 0.01626171836780384 0.0011128480293902676 574.320168919212 36 "Minimization exited successfully."
1306029 0 19 19 20 0 0.12602307217168507 57275.403471095044 4.4300263747505654e-17 1.7088141108705344 0.17143938963258626 0.001785386471567979 0.05538820916626719 8.548575428495861e-19 0.0238197601131512 0.02490429777373032 69.17569477905748 53 "Covariance may not be accurate. Covariance not positive definite. Covariance forced positive definite."
1306073 0 15 13 14 0 nan nan nan nan nan nan nan nan nan nan nan nan "exception was raised in user function
User function arguments:
     z = +0.450361
    t0 = +56965.833200
    x0 = +0.000000
    x1 = -21.142535
     c = +0.938066
Original python exception in user function:
ValueError: Error code returned by bispev: 10
  File ""/anaconda3/envs/sdss_classification_3.7/lib/python3.7/site-packages/sncosmo/fitting.py"", line 46, in chisq
    zp=data.zp, zpsys=data.zpsys)
  File ""/anaconda3/envs/sdss_classification_3.7/lib/python3.7/site-packages/sncosmo/models.py"", line 1400, in bandflux
    raise e
  File ""/anaconda3/envs/sdss_classification_3.7/lib/python3.7/site-packages/sncosmo/models.py"", line 1397, in bandflux
    return _bandflux(self, band, time, zp, zpsys)
  File ""/anaconda3/envs/sdss_classification_3.7/lib/python3.7/site-packages/sncosmo/models.py"", line 154, in _bandflux
    fsum = _bandflux_single(model, b, time_or_phase[mask])
  File ""/anaconda3/envs/sdss_classification_3.7/lib/python3.7/site-packages/sncosmo/models.py"", line 116, in _bandflux_single
    f = model._flux(time_or_phase, wave)
  File ""/anaconda3/envs/sdss_classification_3.7/lib/python3.7/site-packages/sncosmo/models.py"", line 1272, in _flux
    f = a * self._source._flux(phase, restwave)
  File ""/Users/daniel/Github/SDSS-Classification/analysis_pipeline/_sn91bg_model/_model.py"", line 135, in _flux
    y = [self._model_flux[c1](phase / (st / 0.65), wave),
  File ""/anaconda3/envs/sdss_classification_3.7/lib/python3.7/site-packages/scipy/interpolate/fitpack2.py"", line 848, in __call__
    raise ValueError(""Error code returned by bispev: %s"" % ier)"
1306141 0 15 17 16 0 nan nan nan nan nan nan nan nan nan nan nan nan "exception was raised in user function
User function arguments:
     z = +0.475650
    t0 = +56999.977386
    x0 = +0.000000
    x1 = -4.920428
     c = +0.943010
Original python exception in user function:
ValueError: Error code returned by bispev: 10
  File ""/anaconda3/envs/sdss_classification_3.7/lib/python3.7/site-packages/sncosmo/fitting.py"", line 46, in chisq
    zp=data.zp, zpsys=data.zpsys)
  File ""/anaconda3/envs/sdss_classification_3.7/lib/python3.7/site-packages/sncosmo/models.py"", line 1400, in bandflux
    raise e
  File ""/anaconda3/envs/sdss_classification_3.7/lib/python3.7/site-packages/sncosmo/models.py"", line 1397, in bandflux
    return _bandflux(self, band, time, zp, zpsys)
  File ""/anaconda3/envs/sdss_classification_3.7/lib/python3.7/site-packages/sncosmo/models.py"", line 154, in _bandflux
    fsum = _bandflux_single(model, b, time_or_phase[mask])
  File ""/anaconda3/envs/sdss_classification_3.7/lib/python3.7/site-packages/sncosmo/models.py"", line 116, in _bandflux_single
    f = model._flux(time_or_phase, wave)
  File ""/anaconda3/envs/sdss_classification_3.7/lib/python3.7/site-packages/sncosmo/models.py"", line 1272, in _flux
    f = a * self._source._flux(phase, restwave)
  File ""/Users/daniel/Github/SDSS-Classification/analysis_pipeline/_sn91bg_model/_model.py"", line 135, in _flux
    y = [self._model_flux[c1](phase / (st / 0.65), wave),
  File ""/anaconda3/envs/sdss_classification_3.7/lib/python3.7/site-packages/scipy/interpolate/fitpack2.py"", line 848, in __call__
    raise ValueError(""Error code returned by bispev: %s"" % ier)"
1306360 0 0 19 21 0 0.3981663813784805 57277.01969032572 2.5365747670439757e-17 1.4372658915176422 5.7225858385301365e-08 0.005263117607481577 0.4302701548294863 1.3045833170918607e-18 0.09179990116089552 0.00024495162232349155 18.27200380162087 35 "Covariance may not be accurate. Covariance not positive definite. Covariance forced positive definite."
1306390 0 17 17 17 0 0.17012667617665492 57276.61055466467 4.257952285571546e-17 1.409761369885013 0.4958704214577133 0.006685329045729188 0.3990542814935907 1.5931546316232751e-18 0.0397191362110691 0.03633008830522785 15.99233091565106 46 "Covariance may not be accurate. Covariance not positive definite. Covariance forced positive definite."
1306537 0 0 19 20 0 0.4011591464317131 57284.981336612625 3.0556623761800455e-17 1.656626402867332 6.642944055945676e-08 0.0021491434837274948 0.04705882037887932 7.453079425876752e-19 0.047604124966134004 5.052862207960418e-05 51.612901757371134 34 "Covariance may not be accurate. Covariance not positive definite. Covariance forced positive definite."
1306626 0 18 18 20 0 0.12113525007517897 57280.00946391944 5.589907898405216e-17 1.5440967018982557 0.007220517409375626 0.0014643284691359254 0.07542122497034143 9.502092945818501e-19 0.020088241286009716 0.02167106293980639 68.9380321511195 51 "Covariance may not be accurate. Covariance not positive definite. Covariance forced positive definite."
1306785 0 0 11 12 0 0.3945620518889181 57278.57068128204 2.024917590079286e-17 1.630028166444543 3.779358083044748e-06 0.024112572697542772 0.6643972067213326 9.928692282128125e-19 0.09591204537647803 0.0051035631620006405 10.116677428843827 18 "Covariance may not be accurate. Covariance not positive definite. Covariance forced positive definite."
1306980 0 0 22 24 0 0.3801256065233737 57278.374273931106 2.5071428639776834e-17 1.2397646798493276 0.2588345615006663 0.003185465732004289 0.09679639220848912 1.128255845953131e-18 0.03726815165488002 0.056863702723745 25.264256775220634 41 "Covariance may not be accurate. Covariance not positive definite. Covariance forced positive definite."
1306991 0 18 17 20 0 nan nan nan nan nan nan nan nan nan nan nan nan "exception was raised in user function
User function arguments:
     z = +0.474418
    t0 = +57281.592728
    x0 = +0.000000
    x1 = -0.514249
     c = +0.948320
Original python exception in user function:
ValueError: Error code returned by bispev: 10
  File ""/anaconda3/envs/sdss_classification_3.7/lib/python3.7/site-packages/sncosmo/fitting.py"", line 46, in chisq
    zp=data.zp, zpsys=data.zpsys)
  File ""/anaconda3/envs/sdss_classification_3.7/lib/python3.7/site-packages/sncosmo/models.py"", line 1400, in bandflux
    raise e
  File ""/anaconda3/envs/sdss_classification_3.7/lib/python3.7/site-packages/sncosmo/models.py"", line 1397, in bandflux
    return _bandflux(self, band, time, zp, zpsys)
  File ""/anaconda3/envs/sdss_classification_3.7/lib/python3.7/site-packages/sncosmo/models.py"", line 154, in _bandflux
    fsum = _bandflux_single(model, b, time_or_phase[mask])
  File ""/anaconda3/envs/sdss_classification_3.7/lib/python3.7/site-packages/sncosmo/models.py"", line 116, in _bandflux_single
    f = model._flux(time_or_phase, wave)
  File ""/anaconda3/envs/sdss_classification_3.7/lib/python3.7/site-packages/sncosmo/models.py"", line 1272, in _flux
    f = a * self._source._flux(phase, restwave)
  File ""/Users/daniel/Github/SDSS-Classification/analysis_pipeline/_sn91bg_model/_model.py"", line 135, in _flux
    y = [self._model_flux[c1](phase / (st / 0.65), wave),
  File ""/anaconda3/envs/sdss_classification_3.7/lib/python3.7/site-packages/scipy/interpolate/fitpack2.py"", line 848, in __call__
    raise ValueError(""Error code returned by bispev: %s"" % ier)"
1307277 0 18 18 19 0 0.30044446578714834 57281.052656498716 3.2461456505564603e-17 1.495510329845599 8.040624266791863e-06 0.006412721708723118 0.22209981656124 1.2121526867289542e-18 0.07899792478337467 0.0017069518464803979 24.86597937968669 50 "Covariance may not be accurate. Covariance not positive definite. Covariance forced positive definite."
1307830 0 15 16 15 0 0.16966763661397685 57283.49664820885 4.7350697777313906e-17 1.2486862223641704 2.1766025747327333e-06 0.003994920358184842 0.04240886104889796 6.219645432645957e-19 0.016805705366767627 0.0007797262000335814 100.23447801121468 41 "Covariance may not be accurate. Covariance not positive definite. Covariance forced positive definite."
1308314 0 18 19 19 0 0.16799167483537708 56974.08493555122 4.528972977093129e-17 1.5106412476330464 5.723081625275128e-08 0.0034482815236693276 0.022956656419410137 7.245241222913105e-19 0.026813241863927136 6.824925317694408e-05 101.96181414192623 51 "Covariance may not be accurate. Covariance not positive definite. Covariance forced positive definite."
1308326 0 16 16 15 0 nan nan nan nan nan nan nan nan nan nan nan nan "exception was raised in user function
User function arguments:
     z = +0.476291
    t0 = +56982.347683
    x0 = +0.000000
    x1 = -0.878699
     c = +0.876831
Original python exception in user function:
ValueError: Error code returned by bispev: 10
  File ""/anaconda3/envs/sdss_classification_3.7/lib/python3.7/site-packages/sncosmo/fitting.py"", line 46, in chisq
    zp=data.zp, zpsys=data.zpsys)
  File ""/anaconda3/envs/sdss_classification_3.7/lib/python3.7/site-packages/sncosmo/models.py"", line 1400, in bandflux
    raise e
  File ""/anaconda3/envs/sdss_classification_3.7/lib/python3.7/site-packages/sncosmo/models.py"", line 1397, in bandflux
    return _bandflux(self, band, time, zp, zpsys)
  File ""/anaconda3/envs/sdss_classification_3.7/lib/python3.7/site-packages/sncosmo/models.py"", line 154, in _bandflux
    fsum = _bandflux_single(model, b, time_or_phase[mask])
  File ""/anaconda3/envs/sdss_classification_3.7/lib/python3.7/site-packages/sncosmo/models.py"", line 116, in _bandflux_single
    f = model._flux(time_or_phase, wave)
  File ""/anaconda3/envs/sdss_classification_3.7/lib/python3.7/site-packages/sncosmo/models.py"", line 1272, in _flux
    f = a * self._source._flux(phase, restwave)
  File ""/Users/daniel/Github/SDSS-Classification/analysis_pipeline/_sn91bg_model/_model.py"", line 135, in _flux
    y = [self._model_flux[c1](phase / (st / 0.65), wave),
  File ""/anaconda3/envs/sdss_classification_3.7/lib/python3.7/site-packages/scipy/interpolate/fitpack2.py"", line 848, in __call__
    raise ValueError(""Error code returned by bispev: %s"" % ier)"
1308568 0 0 19 21 0 0.4308633291894672 57286.492169709425 1.8697819512088315e-17 1.9110042840889834 0.1371245975136336 0.0016086603224343687 0.03986140639608493 5.737597529198355e-19 0.04289414647636617 0.031739220874200946 37.14837439376569 35 "Covariance may not be accurate. Covariance not positive definite. Covariance forced positive definite."
1308582 0 14 15 15 0 nan nan nan nan nan nan nan nan nan nan nan nan "exception was raised in user function
User function arguments:
     z = +0.476380
    t0 = +57292.306442
    x0 = +0.000000
    x1 = -4.530907
     c = +0.955791
Original python exception in user function:
ValueError: Error code returned by bispev: 10
  File ""/anaconda3/envs/sdss_classification_3.7/lib/python3.7/site-packages/sncosmo/fitting.py"", line 46, in chisq
    zp=data.zp, zpsys=data.zpsys)
  File ""/anaconda3/envs/sdss_classification_3.7/lib/python3.7/site-packages/sncosmo/models.py"", line 1400, in bandflux
    raise e
  File ""/anaconda3/envs/sdss_classification_3.7/lib/python3.7/site-packages/sncosmo/models.py"", line 1397, in bandflux
    return _bandflux(self, band, time, zp, zpsys)
  File ""/anaconda3/envs/sdss_classification_3.7/lib/python3.7/site-packages/sncosmo/models.py"", line 154, in _bandflux
    fsum = _bandflux_single(model, b, time_or_phase[mask])
  File ""/anaconda3/envs/sdss_classification_3.7/lib/python3.7/site-packages/sncosmo/models.py"", line 116, in _bandflux_single
    f = model._flux(time_or_phase, wave)
  File ""/anaconda3/envs/sdss_classification_3.7/lib/python3.7/site-packages/sncosmo/models.py"", line 1272, in _flux
    f = a * self._source._flux(phase, restwave)
  File ""/Users/daniel/Github/SDSS-Classification/analysis_pipeline/_sn91bg_model/_model.py"", line 135, in _flux
    y = [self._model_flux[c1](phase / (st / 0.65), wave),
  File ""/anaconda3/envs/sdss_classification_3.7/lib/python3.7/site-packages/scipy/interpolate/fitpack2.py"", line 848, in __call__
    raise ValueError(""Error code returned by bispev: %s"" % ier)"
1308884 10 13 13 12 0 nan nan nan nan nan nan nan nan nan nan nan nan "exception was raised in user function
User function arguments:
     z = +0.492539
    t0 = +57291.036323
    x0 = +0.000000
    x1 = -1.441798
     c = +0.949159
Original python exception in user function:
ValueError: Error code returned by bispev: 10
  File ""/anaconda3/envs/sdss_classification_3.7/lib/python3.7/site-packages/sncosmo/fitting.py"", line 46, in chisq
    zp=data.zp, zpsys=data.zpsys)
  File ""/anaconda3/envs/sdss_classification_3.7/lib/python3.7/site-packages/sncosmo/models.py"", line 1400, in bandflux
    raise e
  File ""/anaconda3/envs/sdss_classification_3.7/lib/python3.7/site-packages/sncosmo/models.py"", line 1397, in bandflux
    return _bandflux(self, band, time, zp, zpsys)
  File ""/anaconda3/envs/sdss_classification_3.7/lib/python3.7/site-packages/sncosmo/models.py"", line 154, in _bandflux
    fsum = _bandflux_single(model, b, time_or_phase[mask])
  File ""/anaconda3/envs/sdss_classification_3.7/lib/python3.7/site-packages/sncosmo/models.py"", line 116, in _bandflux_single
    f = model._flux(time_or_phase, wave)
  File ""/anaconda3/envs/sdss_classification_3.7/lib/python3.7/site-packages/sncosmo/models.py"", line 1272, in _flux
    f = a * self._source._flux(phase, restwave)
  File ""/Users/daniel/Github/SDSS-Classification/analysis_pipeline/_sn91bg_model/_model.py"", line 135, in _flux
    y = [self._model_flux[c1](phase / (st / 0.65), wave),
  File ""/anaconda3/envs/sdss_classification_3.7/lib/python3.7/site-packages/scipy/interpolate/fitpack2.py"", line 848, in __call__
    raise ValueError(""Error code returned by bispev: %s"" % ier)"
1308957 0 0 19 18 0 nan nan nan nan nan nan nan nan nan nan nan nan "exception was raised in user function
User function arguments:
     z = +0.598577
    t0 = +57259.594575
    x0 = +0.000000
    x1 = -0.052838
     c = +0.900348
Original python exception in user function:
ValueError: Error code returned by bispev: 10
  File ""/anaconda3/envs/sdss_classification_3.7/lib/python3.7/site-packages/sncosmo/fitting.py"", line 46, in chisq
    zp=data.zp, zpsys=data.zpsys)
  File ""/anaconda3/envs/sdss_classification_3.7/lib/python3.7/site-packages/sncosmo/models.py"", line 1400, in bandflux
    raise e
  File ""/anaconda3/envs/sdss_classification_3.7/lib/python3.7/site-packages/sncosmo/models.py"", line 1397, in bandflux
    return _bandflux(self, band, time, zp, zpsys)
  File ""/anaconda3/envs/sdss_classification_3.7/lib/python3.7/site-packages/sncosmo/models.py"", line 154, in _bandflux
    fsum = _bandflux_single(model, b, time_or_phase[mask])
  File ""/anaconda3/envs/sdss_classification_3.7/lib/python3.7/site-packages/sncosmo/models.py"", line 116, in _bandflux_single
    f = model._flux(time_or_phase, wave)
  File ""/anaconda3/envs/sdss_classification_3.7/lib/python3.7/site-packages/sncosmo/models.py"", line 1272, in _flux
    f = a * self._source._flux(phase, restwave)
  File ""/Users/daniel/Github/SDSS-Classification/analysis_pipeline/_sn91bg_model/_model.py"", line 135, in _flux
    y = [self._model_flux[c1](phase / (st / 0.65), wave),
  File ""/anaconda3/envs/sdss_classification_3.7/lib/python3.7/site-packages/scipy/interpolate/fitpack2.py"", line 848, in __call__
    raise ValueError(""Error code returned by bispev: %s"" % ier)"
1309288 0 6 13 17 0 0.8119093371187246 56993.22036761882 8.17271935994275e-17 1.4506547653548216 1.740229738089738e-08 0.0014031880361112248 0.09024785486326437 4.9688260601406875e-18 0.10399715211948182 3.270305864680467e-05 135.15834806882617 31 "Covariance may not be accurate. Covariance not positive definite. Covariance forced positive definite."
1309492 0 15 15 17 0 0.17110322142335657 56990.34705425195 8.019485100295309e-17 1.54381255596816 2.944868793264277e-10 0.0008949637435278768 0.02229215433180798 5.395889666571043e-19 0.010172629471020607 4.757920149089934e-06 682.461493196488 42 "Covariance may not be accurate. Covariance not positive definite. Covariance forced positive definite."
1309749 0 0 0 19 0 0.5537319670712733 56982.35647872352 1.6669143263828535e-17 1.5567439643611052 0.5230455985921493 0.005083310906079552 0.06496245260132127 2.4017027794670375e-19 0.012716640881798259 0.014457305345136229 9.005008543368154 14 "Covariance may not be accurate. Covariance not positive definite. Covariance forced positive definite."
1310338 0 17 9 19 0 0.12016255856608508 56973.26872137085 5.501020950504697e-17 1.5250373951009815 0.1634103293708266 0.0003844073216694374 0.10669611265620915 8.23386702194376e-19 0.018594979928486247 0.018342448520789728 44.09338475461608 40 "Covariance may not be accurate. Covariance not positive definite. Covariance forced positive definite."
1310395 0 18 17 18 0 0.39311130391789934 56980.5362453715 5.1225163741507645e-17 1.5594104821755876 3.363487266483389e-10 0.0011280057936204901 0.05029932526304037 8.400340011390602e-19 0.038927072643348944 3.519965064369135e-06 676.8899231159198 48 "Covariance may not be accurate. Covariance not positive definite. Covariance forced positive definite."
1312274 0 16 16 14 0 nan nan nan nan nan nan nan nan nan nan nan nan "exception was raised in user function
User function arguments:
     z = +0.479734
    t0 = +56983.717151
    x0 = +0.000000
    x1 = -0.884961
     c = +0.855305
Original python exception in user function:
ValueError: Error code returned by bispev: 10
  File ""/anaconda3/envs/sdss_classification_3.7/lib/python3.7/site-packages/sncosmo/fitting.py"", line 46, in chisq
    zp=data.zp, zpsys=data.zpsys)
  File ""/anaconda3/envs/sdss_classification_3.7/lib/python3.7/site-packages/sncosmo/models.py"", line 1400, in bandflux
    raise e
  File ""/anaconda3/envs/sdss_classification_3.7/lib/python3.7/site-packages/sncosmo/models.py"", line 1397, in bandflux
    return _bandflux(self, band, time, zp, zpsys)
  File ""/anaconda3/envs/sdss_classification_3.7/lib/python3.7/site-packages/sncosmo/models.py"", line 154, in _bandflux
    fsum = _bandflux_single(model, b, time_or_phase[mask])
  File ""/anaconda3/envs/sdss_classification_3.7/lib/python3.7/site-packages/sncosmo/models.py"", line 116, in _bandflux_single
    f = model._flux(time_or_phase, wave)
  File ""/anaconda3/envs/sdss_classification_3.7/lib/python3.7/site-packages/sncosmo/models.py"", line 1272, in _flux
    f = a * self._source._flux(phase, restwave)
  File ""/Users/daniel/Github/SDSS-Classification/analysis_pipeline/_sn91bg_model/_model.py"", line 135, in _flux
    y = [self._model_flux[c1](phase / (st / 0.65), wave),
  File ""/anaconda3/envs/sdss_classification_3.7/lib/python3.7/site-packages/scipy/interpolate/fitpack2.py"", line 848, in __call__
    raise ValueError(""Error code returned by bispev: %s"" % ier)"
1313594 0 12 14 14 0 nan nan nan nan nan nan nan nan nan nan nan nan "exception was raised in user function
User function arguments:
     z = +0.466800
    t0 = +56994.315471
    x0 = +0.000000
    x1 = -5.157038
     c = +0.953044
Original python exception in user function:
ValueError: Error code returned by bispev: 10
  File ""/anaconda3/envs/sdss_classification_3.7/lib/python3.7/site-packages/sncosmo/fitting.py"", line 46, in chisq
    zp=data.zp, zpsys=data.zpsys)
  File ""/anaconda3/envs/sdss_classification_3.7/lib/python3.7/site-packages/sncosmo/models.py"", line 1400, in bandflux
    raise e
  File ""/anaconda3/envs/sdss_classification_3.7/lib/python3.7/site-packages/sncosmo/models.py"", line 1397, in bandflux
    return _bandflux(self, band, time, zp, zpsys)
  File ""/anaconda3/envs/sdss_classification_3.7/lib/python3.7/site-packages/sncosmo/models.py"", line 154, in _bandflux
    fsum = _bandflux_single(model, b, time_or_phase[mask])
  File ""/anaconda3/envs/sdss_classification_3.7/lib/python3.7/site-packages/sncosmo/models.py"", line 116, in _bandflux_single
    f = model._flux(time_or_phase, wave)
  File ""/anaconda3/envs/sdss_classification_3.7/lib/python3.7/site-packages/sncosmo/models.py"", line 1272, in _flux
    f = a * self._source._flux(phase, restwave)
  File ""/Users/daniel/Github/SDSS-Classification/analysis_pipeline/_sn91bg_model/_model.py"", line 135, in _flux
    y = [self._model_flux[c1](phase / (st / 0.65), wave),
  File ""/anaconda3/envs/sdss_classification_3.7/lib/python3.7/site-packages/scipy/interpolate/fitpack2.py"", line 848, in __call__
    raise ValueError(""Error code returned by bispev: %s"" % ier)"
1314897 0 11 14 15 0 0.11803074917317626 57297.65144686938 7.846814211656863e-17 1.7829398422255955 0.06410713174422 0.002446910201245378 0.03290676584219909 1.6260565117836678e-18 0.02574834842637273 0.028064451112126687 45.77967813306614 35 "Covariance may not be accurate. Covariance not positive definite. Covariance forced positive definite."
1315192 0 7 12 10 0 0.06566165060284378 57005.713657890665 1.6542125802451256e-16 1.6017757577899845 0.09702554368679028 0.0028895760864876274 0.016057806522439932 2.9473548549946547e-18 0.014363311756801986 0.024202922833885115 144.63877623044084 24 "Covariance may not be accurate. Covariance not positive definite. Covariance forced positive definite."
1315259 0 10 11 13 0 0.17078206430966716 57002.32551810941 1.0795199574690176e-16 1.4653367601432619 1.7973464327969424e-08 0.0028531269786955527 0.06857646332719014 1.871367606104111e-18 0.030401533299849227 1.9549788959905e-05 197.9609792584531 29 "Covariance may not be accurate. Covariance not positive definite. Covariance forced positive definite."
1315296 0 14 13 14 0 0.2521963465996189 57001.31303220454 2.885485816512801e-17 1.7308687032984278 1.1910405954829173e-06 0.00914776541444981 0.08708651912093046 7.578434580263236e-19 0.0534541314849792 0.00011809032527082541 28.307551328542424 36 "Covariance may not be accurate. Covariance not positive definite. Covariance forced positive definite."
1316385 8 3 8 13 0 nan nan nan nan nan nan nan nan nan nan nan nan "exception was raised in user function
User function arguments:
     z = +0.477052
    t0 = +57028.259158
    x0 = +0.000000
    x1 = -0.787654
     c = +0.550000
Original python exception in user function:
ValueError: Error code returned by bispev: 10
  File ""/anaconda3/envs/sdss_classification_3.7/lib/python3.7/site-packages/sncosmo/fitting.py"", line 46, in chisq
    zp=data.zp, zpsys=data.zpsys)
  File ""/anaconda3/envs/sdss_classification_3.7/lib/python3.7/site-packages/sncosmo/models.py"", line 1400, in bandflux
    raise e
  File ""/anaconda3/envs/sdss_classification_3.7/lib/python3.7/site-packages/sncosmo/models.py"", line 1397, in bandflux
    return _bandflux(self, band, time, zp, zpsys)
  File ""/anaconda3/envs/sdss_classification_3.7/lib/python3.7/site-packages/sncosmo/models.py"", line 154, in _bandflux
    fsum = _bandflux_single(model, b, time_or_phase[mask])
  File ""/anaconda3/envs/sdss_classification_3.7/lib/python3.7/site-packages/sncosmo/models.py"", line 116, in _bandflux_single
    f = model._flux(time_or_phase, wave)
  File ""/anaconda3/envs/sdss_classification_3.7/lib/python3.7/site-packages/sncosmo/models.py"", line 1272, in _flux
    f = a * self._source._flux(phase, restwave)
  File ""/Users/daniel/Github/SDSS-Classification/analysis_pipeline/_sn91bg_model/_model.py"", line 135, in _flux
    y = [self._model_flux[c1](phase / (st / 0.65), wave),
  File ""/anaconda3/envs/sdss_classification_3.7/lib/python3.7/site-packages/scipy/interpolate/fitpack2.py"", line 848, in __call__
    raise ValueError(""Error code returned by bispev: %s"" % ier)"
1316431 0 10 10 9 0 nan nan nan nan nan nan nan nan nan nan nan nan "exception was raised in user function
User function arguments:
     z = +0.475221
    t0 = +57020.149585
    x0 = +0.000000
    x1 = -17.749724
     c = +0.986697
Original python exception in user function:
ValueError: Error code returned by bispev: 10
  File ""/anaconda3/envs/sdss_classification_3.7/lib/python3.7/site-packages/sncosmo/fitting.py"", line 46, in chisq
    zp=data.zp, zpsys=data.zpsys)
  File ""/anaconda3/envs/sdss_classification_3.7/lib/python3.7/site-packages/sncosmo/models.py"", line 1400, in bandflux
    raise e
  File ""/anaconda3/envs/sdss_classification_3.7/lib/python3.7/site-packages/sncosmo/models.py"", line 1397, in bandflux
    return _bandflux(self, band, time, zp, zpsys)
  File ""/anaconda3/envs/sdss_classification_3.7/lib/python3.7/site-packages/sncosmo/models.py"", line 154, in _bandflux
    fsum = _bandflux_single(model, b, time_or_phase[mask])
  File ""/anaconda3/envs/sdss_classification_3.7/lib/python3.7/site-packages/sncosmo/models.py"", line 116, in _bandflux_single
    f = model._flux(time_or_phase, wave)
  File ""/anaconda3/envs/sdss_classification_3.7/lib/python3.7/site-packages/sncosmo/models.py"", line 1272, in _flux
    f = a * self._source._flux(phase, restwave)
  File ""/Users/daniel/Github/SDSS-Classification/analysis_pipeline/_sn91bg_model/_model.py"", line 135, in _flux
    y = [self._model_flux[c1](phase / (st / 0.65), wave),
  File ""/anaconda3/envs/sdss_classification_3.7/lib/python3.7/site-packages/scipy/interpolate/fitpack2.py"", line 848, in __call__
    raise ValueError(""Error code returned by bispev: %s"" % ier)"
1316437 0 0 13 11 0 0.40114987313986844 57007.78303994623 2.115256832206649e-17 1.4281260788582004 1.2819869293911879e-07 0.0023903321636965513 0.03701448091305792 6.90418368453353e-19 0.06813094246803353 6.250534768814653e-05 50.43318580923125 19 "Covariance may not be accurate. Covariance not positive definite. Covariance forced positive definite."
1316465 0 11 10 11 0 nan nan nan nan nan nan nan nan nan nan nan nan "exception was raised in user function
User function arguments:
     z = +0.472608
    t0 = +56945.363116
    x0 = +0.000000
    x1 = -12.155043
     c = +0.956698
Original python exception in user function:
ValueError: Error code returned by bispev: 10
  File ""/anaconda3/envs/sdss_classification_3.7/lib/python3.7/site-packages/sncosmo/fitting.py"", line 46, in chisq
    zp=data.zp, zpsys=data.zpsys)
  File ""/anaconda3/envs/sdss_classification_3.7/lib/python3.7/site-packages/sncosmo/models.py"", line 1400, in bandflux
    raise e
  File ""/anaconda3/envs/sdss_classification_3.7/lib/python3.7/site-packages/sncosmo/models.py"", line 1397, in bandflux
    return _bandflux(self, band, time, zp, zpsys)
  File ""/anaconda3/envs/sdss_classification_3.7/lib/python3.7/site-packages/sncosmo/models.py"", line 154, in _bandflux
    fsum = _bandflux_single(model, b, time_or_phase[mask])
  File ""/anaconda3/envs/sdss_classification_3.7/lib/python3.7/site-packages/sncosmo/models.py"", line 116, in _bandflux_single
    f = model._flux(time_or_phase, wave)
  File ""/anaconda3/envs/sdss_classification_3.7/lib/python3.7/site-packages/sncosmo/models.py"", line 1272, in _flux
    f = a * self._source._flux(phase, restwave)
  File ""/Users/daniel/Github/SDSS-Classification/analysis_pipeline/_sn91bg_model/_model.py"", line 135, in _flux
    y = [self._model_flux[c1](phase / (st / 0.65), wave),
  File ""/anaconda3/envs/sdss_classification_3.7/lib/python3.7/site-packages/scipy/interpolate/fitpack2.py"", line 848, in __call__
    raise ValueError(""Error code returned by bispev: %s"" % ier)"
1317164 0 5 6 15 0 0.16967580372270058 57296.28616038994 1.4815355893596528e-16 1.3788375533283135 2.41503918696484e-07 0.0009328190667575315 0.6694377675557917 6.359834878131084e-18 0.04506922237526039 8.610428749350474e-05 58.25303362536097 21 "Covariance may not be accurate. Covariance not positive definite. Covariance forced positive definite."
1317277 0 12 13 14 0 nan nan nan nan nan nan nan nan nan nan nan nan "exception was raised in user function
User function arguments:
     z = +0.463105
    t0 = +57002.841352
    x0 = +0.000000
    x1 = -0.003736
     c = +0.939688
Original python exception in user function:
ValueError: Error code returned by bispev: 10
  File ""/anaconda3/envs/sdss_classification_3.7/lib/python3.7/site-packages/sncosmo/fitting.py"", line 46, in chisq
    zp=data.zp, zpsys=data.zpsys)
  File ""/anaconda3/envs/sdss_classification_3.7/lib/python3.7/site-packages/sncosmo/models.py"", line 1400, in bandflux
    raise e
  File ""/anaconda3/envs/sdss_classification_3.7/lib/python3.7/site-packages/sncosmo/models.py"", line 1397, in bandflux
    return _bandflux(self, band, time, zp, zpsys)
  File ""/anaconda3/envs/sdss_classification_3.7/lib/python3.7/site-packages/sncosmo/models.py"", line 154, in _bandflux
    fsum = _bandflux_single(model, b, time_or_phase[mask])
  File ""/anaconda3/envs/sdss_classification_3.7/lib/python3.7/site-packages/sncosmo/models.py"", line 116, in _bandflux_single
    f = model._flux(time_or_phase, wave)
  File ""/anaconda3/envs/sdss_classification_3.7/lib/python3.7/site-packages/sncosmo/models.py"", line 1272, in _flux
    f = a * self._source._flux(phase, restwave)
  File ""/Users/daniel/Github/SDSS-Classification/analysis_pipeline/_sn91bg_model/_model.py"", line 135, in _flux
    y = [self._model_flux[c1](phase / (st / 0.65), wave),
  File ""/anaconda3/envs/sdss_classification_3.7/lib/python3.7/site-packages/scipy/interpolate/fitpack2.py"", line 848, in __call__
    raise ValueError(""Error code returned by bispev: %s"" % ier)"
1317286 0 14 13 14 0 0.06765694007804894 57011.49022355561 1.2639486968798663e-16 1.656424275285704 0.009365107759968128 0.0018389914175176644 0.02219438794782036 1.224006443503953e-18 0.010845718537562747 0.012600241909831 155.36955943315138 36 "Covariance may not be accurate. Covariance not positive definite. Covariance forced positive definite."
1317454 0 0 10 10 0 0.5714362857045591 57013.462192035615 2.000338954786324e-17 1.5200736147000506 2.2418695566628344e-08 0.0034279771444383766 0.3089634672469401 4.960179342681488e-19 0.05470217553264735 6.519401512608547e-05 23.86963216003393 15 "Covariance may not be accurate. Covariance not positive definite. Covariance forced positive definite."
1317666 10 12 12 13 0 nan nan nan nan nan nan nan nan nan nan nan nan "exception was raised in user function
User function arguments:
     z = +0.486686
    t0 = +57334.676666
    x0 = +0.000000
    x1 = -1.195504
     c = +0.942458
Original python exception in user function:
ValueError: Error code returned by bispev: 10
  File ""/anaconda3/envs/sdss_classification_3.7/lib/python3.7/site-packages/sncosmo/fitting.py"", line 46, in chisq
    zp=data.zp, zpsys=data.zpsys)
  File ""/anaconda3/envs/sdss_classification_3.7/lib/python3.7/site-packages/sncosmo/models.py"", line 1400, in bandflux
    raise e
  File ""/anaconda3/envs/sdss_classification_3.7/lib/python3.7/site-packages/sncosmo/models.py"", line 1397, in bandflux
    return _bandflux(self, band, time, zp, zpsys)
  File ""/anaconda3/envs/sdss_classification_3.7/lib/python3.7/site-packages/sncosmo/models.py"", line 154, in _bandflux
    fsum = _bandflux_single(model, b, time_or_phase[mask])
  File ""/anaconda3/envs/sdss_classification_3.7/lib/python3.7/site-packages/sncosmo/models.py"", line 116, in _bandflux_single
    f = model._flux(time_or_phase, wave)
  File ""/anaconda3/envs/sdss_classification_3.7/lib/python3.7/site-packages/sncosmo/models.py"", line 1272, in _flux
    f = a * self._source._flux(phase, restwave)
  File ""/Users/daniel/Github/SDSS-Classification/analysis_pipeline/_sn91bg_model/_model.py"", line 135, in _flux
    y = [self._model_flux[c1](phase / (st / 0.65), wave),
  File ""/anaconda3/envs/sdss_classification_3.7/lib/python3.7/site-packages/scipy/interpolate/fitpack2.py"", line 848, in __call__
    raise ValueError(""Error code returned by bispev: %s"" % ier)"
1319366 0 17 17 18 0 nan nan nan nan nan nan nan nan nan nan nan nan "exception was raised in user function
User function arguments:
     z = +0.449898
    t0 = +57296.274004
    x0 = +0.000000
    x1 = -0.500235
     c = +0.955054
Original python exception in user function:
ValueError: Error code returned by bispev: 10
  File ""/anaconda3/envs/sdss_classification_3.7/lib/python3.7/site-packages/sncosmo/fitting.py"", line 46, in chisq
    zp=data.zp, zpsys=data.zpsys)
  File ""/anaconda3/envs/sdss_classification_3.7/lib/python3.7/site-packages/sncosmo/models.py"", line 1400, in bandflux
    raise e
  File ""/anaconda3/envs/sdss_classification_3.7/lib/python3.7/site-packages/sncosmo/models.py"", line 1397, in bandflux
    return _bandflux(self, band, time, zp, zpsys)
  File ""/anaconda3/envs/sdss_classification_3.7/lib/python3.7/site-packages/sncosmo/models.py"", line 154, in _bandflux
    fsum = _bandflux_single(model, b, time_or_phase[mask])
  File ""/anaconda3/envs/sdss_classification_3.7/lib/python3.7/site-packages/sncosmo/models.py"", line 116, in _bandflux_single
    f = model._flux(time_or_phase, wave)
  File ""/anaconda3/envs/sdss_classification_3.7/lib/python3.7/site-packages/sncosmo/models.py"", line 1272, in _flux
    f = a * self._source._flux(phase, restwave)
  File ""/Users/daniel/Github/SDSS-Classification/analysis_pipeline/_sn91bg_model/_model.py"", line 135, in _flux
    y = [self._model_flux[c1](phase / (st / 0.65), wave),
  File ""/anaconda3/envs/sdss_classification_3.7/lib/python3.7/site-packages/scipy/interpolate/fitpack2.py"", line 848, in __call__
    raise ValueError(""Error code returned by bispev: %s"" % ier)"
1319821 0 10 13 13 0 nan nan nan nan nan nan nan nan nan nan nan nan "exception was raised in user function
User function arguments:
     z = +0.468265
    t0 = +57020.190967
    x0 = +0.000000
    x1 = -0.082649
     c = +0.973774
Original python exception in user function:
ValueError: Error code returned by bispev: 10
  File ""/anaconda3/envs/sdss_classification_3.7/lib/python3.7/site-packages/sncosmo/fitting.py"", line 46, in chisq
    zp=data.zp, zpsys=data.zpsys)
  File ""/anaconda3/envs/sdss_classification_3.7/lib/python3.7/site-packages/sncosmo/models.py"", line 1400, in bandflux
    raise e
  File ""/anaconda3/envs/sdss_classification_3.7/lib/python3.7/site-packages/sncosmo/models.py"", line 1397, in bandflux
    return _bandflux(self, band, time, zp, zpsys)
  File ""/anaconda3/envs/sdss_classification_3.7/lib/python3.7/site-packages/sncosmo/models.py"", line 154, in _bandflux
    fsum = _bandflux_single(model, b, time_or_phase[mask])
  File ""/anaconda3/envs/sdss_classification_3.7/lib/python3.7/site-packages/sncosmo/models.py"", line 116, in _bandflux_single
    f = model._flux(time_or_phase, wave)
  File ""/anaconda3/envs/sdss_classification_3.7/lib/python3.7/site-packages/sncosmo/models.py"", line 1272, in _flux
    f = a * self._source._flux(phase, restwave)
  File ""/Users/daniel/Github/SDSS-Classification/analysis_pipeline/_sn91bg_model/_model.py"", line 135, in _flux
    y = [self._model_flux[c1](phase / (st / 0.65), wave),
  File ""/anaconda3/envs/sdss_classification_3.7/lib/python3.7/site-packages/scipy/interpolate/fitpack2.py"", line 848, in __call__
    raise ValueError(""Error code returned by bispev: %s"" % ier)"
1320166 0 0 10 9 0 0.3895321689897642 57018.45346919702 2.7140667141638233e-17 1.4371930226856882 9.473636097823146e-09 0.003539597045197157 0.14171158639510395 6.850530099664829e-19 0.0481261086858662 0.00023183740026166966 23.668494498004996 14 "Covariance may not be accurate. Covariance not positive definite. Covariance forced positive definite."
1322229 0 0 7 7 0 0.3134869819005882 57028.94706488667 3.882400774508018e-17 1.4744249274908448 0.619923802660826 0.002311329121323147 0.026963692802382866 7.627931094032219e-19 0.017861552091667204 0.023654501391687233 5.427463550230538 9 "Covariance may not be accurate. Covariance not positive definite. Covariance forced positive definite."
1322979 0 0 9 10 0 0.3990608995335657 57035.340591729895 2.2640558116356634e-17 1.4229619538084297 1.285874996093117e-06 0.001649589194211959 0.022095752698078286 2.0951132660029917e-19 0.02193509615832119 1.8549088804137304e-05 73.46921564148926 14 "Covariance may not be accurate. Covariance not positive definite. Covariance forced positive definite."
1324542 0 0 9 10 0 0.39775756425916164 57040.22490275183 1.9337105506167652e-17 1.48215171806676 1.733339360932007e-09 0.004731965869574778 0.315261767780612 5.569060096825975e-19 0.06366270573188494 0.00011936342584836779 16.06806599686341 14 "Covariance may not be accurate. Covariance not positive definite. Covariance forced positive definite."
1325358 0 0 0 7 0 0.3809119245521392 57039.85500860484 1.8609773500236033e-17 1.5786921754378853 0.5481134230305521 0.015828719958327936 0.19891994248246192 7.500837926393436e-19 0.01671519876074724 0.04933041847597766 6.936309703106582 2 "Covariance may not be accurate. Covariance not positive definite. Covariance forced positive definite."
1327978 0 10 13 19 0 nan nan nan nan nan nan nan nan nan nan nan nan "exception was raised in user function
User function arguments:
     z = +0.469486
    t0 = +57302.147621
    x0 = +0.000000
    x1 = -0.056879
     c = +0.959436
Original python exception in user function:
ValueError: Error code returned by bispev: 10
  File ""/anaconda3/envs/sdss_classification_3.7/lib/python3.7/site-packages/sncosmo/fitting.py"", line 46, in chisq
    zp=data.zp, zpsys=data.zpsys)
  File ""/anaconda3/envs/sdss_classification_3.7/lib/python3.7/site-packages/sncosmo/models.py"", line 1400, in bandflux
    raise e
  File ""/anaconda3/envs/sdss_classification_3.7/lib/python3.7/site-packages/sncosmo/models.py"", line 1397, in bandflux
    return _bandflux(self, band, time, zp, zpsys)
  File ""/anaconda3/envs/sdss_classification_3.7/lib/python3.7/site-packages/sncosmo/models.py"", line 154, in _bandflux
    fsum = _bandflux_single(model, b, time_or_phase[mask])
  File ""/anaconda3/envs/sdss_classification_3.7/lib/python3.7/site-packages/sncosmo/models.py"", line 116, in _bandflux_single
    f = model._flux(time_or_phase, wave)
  File ""/anaconda3/envs/sdss_classification_3.7/lib/python3.7/site-packages/sncosmo/models.py"", line 1272, in _flux
    f = a * self._source._flux(phase, restwave)
  File ""/Users/daniel/Github/SDSS-Classification/analysis_pipeline/_sn91bg_model/_model.py"", line 135, in _flux
    y = [self._model_flux[c1](phase / (st / 0.65), wave),
  File ""/anaconda3/envs/sdss_classification_3.7/lib/python3.7/site-packages/scipy/interpolate/fitpack2.py"", line 848, in __call__
    raise ValueError(""Error code returned by bispev: %s"" % ier)"
1328066 0 0 20 22 0 0.39809887096694146 57296.98054069591 2.948931353514287e-17 1.8389885893554336 1.4203421627723145e-06 0.0017619222248307642 0.36429181899802643 9.602416881086679e-19 0.0612492596189621 6.943133517975375e-05 40.59891257276057 37 "Covariance may not be accurate. Covariance not positive definite. Covariance forced positive definite."
1328105 0 21 21 23 0 0.054896263371007635 57296.48180412869 8.082160754808098e-17 1.5789280942971198 0.6289210515129355 0.003761525381531655 0.21336253622575896 2.1039215851172804e-18 0.02435592707234001 0.03100792684987247 62.922876076495406 60 "Covariance may not be accurate. Covariance not positive definite. Covariance forced positive definite."
1329166 0 0 0 17 0 0.6744288953855677 57306.3113858898 1.6225586883441333e-17 1.7038863425108755 0.5557946447615455 0.005266220221033346 0.10588705195550574 2.9825346036558106e-19 0.018949527083948564 0.014333340077521683 13.593307433605464 12 "Covariance may not be accurate. Covariance not positive definite. Covariance forced positive definite."
1329196 0 0 0 20 0 0.540369801950024 57305.8825184296 1.5183901743486842e-17 1.701353699756762 0.6057292099235847 0.006491947408122922 0.09134709685895359 2.1774776219381523e-19 0.012537053333088445 0.012963498993276978 11.50459098282866 15 "Covariance may not be accurate. Covariance not positive definite. Covariance forced positive definite."
1329312 0 15 16 15 0 0.16810759281807308 57307.54488177909 5.5049203604728815e-17 1.3368099476457729 0.1121216332613319 0.002371622087214559 0.035573739296523854 1.315252687457361e-18 0.021123822680062413 0.02938658947833589 27.360967697710464 41 "Covariance may not be accurate. Covariance not positive definite. Covariance forced positive definite."
1329615 0 17 17 16 0 0.18510073600295976 57301.04360075251 4.1868888551384447e-17 1.4992473149506287 0.016560544868017668 0.003597113691614459 0.16232206976565067 9.593662233868739e-19 0.022576523487408233 0.026338096891851098 31.934550110376314 45 "Covariance may not be accurate. Covariance not positive definite. Covariance forced positive definite."
1330031 13 13 13 0 0 nan nan nan nan nan nan nan nan nan nan nan nan "exception was raised in user function
User function arguments:
     z = +0.528329
    t0 = +57310.637120
    x0 = +0.000000
    x1 = -2.569360
     c = +0.315672
Original python exception in user function:
ValueError: Error code returned by bispev: 10
  File ""/anaconda3/envs/sdss_classification_3.7/lib/python3.7/site-packages/sncosmo/fitting.py"", line 46, in chisq
    zp=data.zp, zpsys=data.zpsys)
  File ""/anaconda3/envs/sdss_classification_3.7/lib/python3.7/site-packages/sncosmo/models.py"", line 1400, in bandflux
    raise e
  File ""/anaconda3/envs/sdss_classification_3.7/lib/python3.7/site-packages/sncosmo/models.py"", line 1397, in bandflux
    return _bandflux(self, band, time, zp, zpsys)
  File ""/anaconda3/envs/sdss_classification_3.7/lib/python3.7/site-packages/sncosmo/models.py"", line 154, in _bandflux
    fsum = _bandflux_single(model, b, time_or_phase[mask])
  File ""/anaconda3/envs/sdss_classification_3.7/lib/python3.7/site-packages/sncosmo/models.py"", line 116, in _bandflux_single
    f = model._flux(time_or_phase, wave)
  File ""/anaconda3/envs/sdss_classification_3.7/lib/python3.7/site-packages/sncosmo/models.py"", line 1272, in _flux
    f = a * self._source._flux(phase, restwave)
  File ""/Users/daniel/Github/SDSS-Classification/analysis_pipeline/_sn91bg_model/_model.py"", line 135, in _flux
    y = [self._model_flux[c1](phase / (st / 0.65), wave),
  File ""/anaconda3/envs/sdss_classification_3.7/lib/python3.7/site-packages/scipy/interpolate/fitpack2.py"", line 848, in __call__
    raise ValueError(""Error code returned by bispev: %s"" % ier)"
1330426 0 16 17 17 0 0.17129736687258493 57313.01560380902 1.2832441186242854e-16 1.8752701014536706 7.737893104042826e-10 0.001480220661157966 0.01887500353404903 1.1679476633815542e-18 0.019896781552681014 3.365796527654563e-06 1236.6594706001133 45 "Covariance may not be accurate. Covariance not positive definite. Covariance forced positive definite."
1330642 0 0 17 17 0 0.4009475018581888 57313.299749444646 2.1086494514176034e-17 1.6126824789249363 7.492834969147211e-07 0.0017117061901873454 0.06741954276731121 2.5798744554325137e-19 0.02344143210721213 2.575801607465622e-05 57.50885533814629 29 "Covariance may not be accurate. Covariance not positive definite. Covariance forced positive definite."
1330903 0 0 20 21 0 0.3996977116757763 57303.02716969563 1.8574977207158407e-17 1.5055541931427503 1.4633295883914599e-06 0.0022276707702229004 0.23962852818294778 5.861412771727233e-19 0.06888337767297331 9.453555915023282e-05 46.85204588754324 36 "Covariance may not be accurate. Covariance not positive definite. Covariance forced positive definite."
1331123 0 17 17 17 0 nan nan nan nan nan nan nan nan nan nan nan nan "exception was raised in user function
User function arguments:
     z = +0.483297
    t0 = +57311.183807
    x0 = +0.000000
    x1 = -1.830640
     c = +0.965726
Original python exception in user function:
ValueError: Error code returned by bispev: 10
  File ""/anaconda3/envs/sdss_classification_3.7/lib/python3.7/site-packages/sncosmo/fitting.py"", line 46, in chisq
    zp=data.zp, zpsys=data.zpsys)
  File ""/anaconda3/envs/sdss_classification_3.7/lib/python3.7/site-packages/sncosmo/models.py"", line 1400, in bandflux
    raise e
  File ""/anaconda3/envs/sdss_classification_3.7/lib/python3.7/site-packages/sncosmo/models.py"", line 1397, in bandflux
    return _bandflux(self, band, time, zp, zpsys)
  File ""/anaconda3/envs/sdss_classification_3.7/lib/python3.7/site-packages/sncosmo/models.py"", line 154, in _bandflux
    fsum = _bandflux_single(model, b, time_or_phase[mask])
  File ""/anaconda3/envs/sdss_classification_3.7/lib/python3.7/site-packages/sncosmo/models.py"", line 116, in _bandflux_single
    f = model._flux(time_or_phase, wave)
  File ""/anaconda3/envs/sdss_classification_3.7/lib/python3.7/site-packages/sncosmo/models.py"", line 1272, in _flux
    f = a * self._source._flux(phase, restwave)
  File ""/Users/daniel/Github/SDSS-Classification/analysis_pipeline/_sn91bg_model/_model.py"", line 135, in _flux
    y = [self._model_flux[c1](phase / (st / 0.65), wave),
  File ""/anaconda3/envs/sdss_classification_3.7/lib/python3.7/site-packages/scipy/interpolate/fitpack2.py"", line 848, in __call__
    raise ValueError(""Error code returned by bispev: %s"" % ier)"
1331993 0 0 16 14 0 0.39812496532337005 57322.51919667623 1.2587025229603428e-17 1.5235313274108002 1.881661632952003e-06 0.00438496032225652 0.015691953823989024 1.927653325502069e-19 0.021299538129161032 0.00024394082119572058 31.0102576944444 25 "Covariance may not be accurate. Covariance not positive definite. Covariance forced positive definite."
1332059 0 0 18 19 0 0.3978064676860963 57321.01605334084 2.0380736256026143e-17 1.5073956581609473 6.993672658661687e-06 0.00575663304770363 0.12480678079009522 5.554129649520659e-19 0.038968223682666295 0.0006178787277166253 37.817127673254504 32 "Covariance may not be accurate. Covariance not positive definite. Covariance forced positive definite."
1332413 0 0 17 17 0 0.4022164713985216 57321.983977209056 2.0384591398312546e-17 1.686126511774411 2.694943419534468e-07 0.006071930794852104 0.07356031091330806 4.592755525331223e-19 0.04100814227660278 0.00020791432918951247 47.713091280578794 29 "Covariance may not be accurate. Covariance not positive definite. Covariance forced positive definite."
1333246 0 16 14 16 0 0.24188446609155748 57322.29244676611 3.121519927873416e-17 1.7563910066124324 2.3232000138817543e-05 0.02033511042162156 0.053484368123463355 9.265524600120901e-19 0.02953805314882504 0.0010227933401585343 16.059350813148434 41 "Covariance may not be accurate. Covariance not positive definite. Covariance forced positive definite."
1333438 0 15 16 9 0 0.45551864080359594 57327.239611151075 3.5758598058574134e-17 1.5902168999596675 1.594035375918068e-08 0.003686545327771268 0.028438395620469237 1.1146598593153622e-18 0.050929586472061555 2.5166382425056977e-05 38.42818171411513 35 "Covariance may not be accurate. Covariance not positive definite. Covariance forced positive definite."
1334084 6 8 11 0 0 nan nan nan nan nan nan nan nan nan nan nan nan "exception was raised in user function
User function arguments:
     z = +0.455000
    t0 = +57347.320158
    x0 = +0.000000
    x1 = -0.284076
     c = +0.550000
Original python exception in user function:
ValueError: Error code returned by bispev: 10
  File ""/anaconda3/envs/sdss_classification_3.7/lib/python3.7/site-packages/sncosmo/fitting.py"", line 46, in chisq
    zp=data.zp, zpsys=data.zpsys)
  File ""/anaconda3/envs/sdss_classification_3.7/lib/python3.7/site-packages/sncosmo/models.py"", line 1400, in bandflux
    raise e
  File ""/anaconda3/envs/sdss_classification_3.7/lib/python3.7/site-packages/sncosmo/models.py"", line 1397, in bandflux
    return _bandflux(self, band, time, zp, zpsys)
  File ""/anaconda3/envs/sdss_classification_3.7/lib/python3.7/site-packages/sncosmo/models.py"", line 154, in _bandflux
    fsum = _bandflux_single(model, b, time_or_phase[mask])
  File ""/anaconda3/envs/sdss_classification_3.7/lib/python3.7/site-packages/sncosmo/models.py"", line 116, in _bandflux_single
    f = model._flux(time_or_phase, wave)
  File ""/anaconda3/envs/sdss_classification_3.7/lib/python3.7/site-packages/sncosmo/models.py"", line 1272, in _flux
    f = a * self._source._flux(phase, restwave)
  File ""/Users/daniel/Github/SDSS-Classification/analysis_pipeline/_sn91bg_model/_model.py"", line 135, in _flux
    y = [self._model_flux[c1](phase / (st / 0.65), wave),
  File ""/anaconda3/envs/sdss_classification_3.7/lib/python3.7/site-packages/scipy/interpolate/fitpack2.py"", line 848, in __call__
    raise ValueError(""Error code returned by bispev: %s"" % ier)"
1334087 0 4 3 12 0 nan nan nan nan nan nan nan nan nan nan nan nan "exception was raised in user function
User function arguments:
     z = +0.428656
    t0 = +57359.937426
    x0 = +0.000000
    x1 = -2.907829
     c = +0.893733
Original python exception in user function:
ValueError: Error code returned by bispev: 10
  File ""/anaconda3/envs/sdss_classification_3.7/lib/python3.7/site-packages/sncosmo/fitting.py"", line 46, in chisq
    zp=data.zp, zpsys=data.zpsys)
  File ""/anaconda3/envs/sdss_classification_3.7/lib/python3.7/site-packages/sncosmo/models.py"", line 1400, in bandflux
    raise e
  File ""/anaconda3/envs/sdss_classification_3.7/lib/python3.7/site-packages/sncosmo/models.py"", line 1397, in bandflux
    return _bandflux(self, band, time, zp, zpsys)
  File ""/anaconda3/envs/sdss_classification_3.7/lib/python3.7/site-packages/sncosmo/models.py"", line 154, in _bandflux
    fsum = _bandflux_single(model, b, time_or_phase[mask])
  File ""/anaconda3/envs/sdss_classification_3.7/lib/python3.7/site-packages/sncosmo/models.py"", line 116, in _bandflux_single
    f = model._flux(time_or_phase, wave)
  File ""/anaconda3/envs/sdss_classification_3.7/lib/python3.7/site-packages/sncosmo/models.py"", line 1272, in _flux
    f = a * self._source._flux(phase, restwave)
  File ""/Users/daniel/Github/SDSS-Classification/analysis_pipeline/_sn91bg_model/_model.py"", line 135, in _flux
    y = [self._model_flux[c1](phase / (st / 0.65), wave),
  File ""/anaconda3/envs/sdss_classification_3.7/lib/python3.7/site-packages/scipy/interpolate/fitpack2.py"", line 848, in __call__
    raise ValueError(""Error code returned by bispev: %s"" % ier)"
1334302 0 0 17 19 0 0.39889218305522167 57329.624125717644 2.6860774556447363e-17 1.3807653558649244 3.932248432425567e-07 0.00487233624365821 0.20612901959975716 9.985799776631274e-19 0.06756218211019781 0.00016193259853594655 17.41729542665209 31 "Covariance may not be accurate. Covariance not positive definite. Covariance forced positive definite."
1334423 0 14 14 14 0 0.06074909432954727 57331.15487643684 8.175906595341291e-17 1.7092774036325333 0.6022824314616834 0.004946689091587773 0.06369786376308184 1.8443884230344906e-18 0.02933676468138416 0.03084183616792957 31.087842224488817 37 "Covariance may not be accurate. Covariance not positive definite. Covariance forced positive definite."
1334448 0 0 16 16 0 nan nan nan nan nan nan nan nan nan nan nan nan "No data points with S/N > 5.0. Initial guessing failed."
1334470 0 0 15 15 0 0.4005182288238317 57330.75516137073 2.3744649230605658e-17 1.5724106864237153 8.378917987772461e-07 0.0036412201009082823 0.11552958200263674 6.348661496217084e-19 0.04918924112572591 0.00016032476598396017 21.011397458343474 25 "Covariance may not be accurate. Covariance not positive definite. Covariance forced positive definite."
1334597 0 12 12 11 0 0.0841789020774501 57340.06126929681 1.0570016673384496e-16 1.644646950337188 2.616562954638191e-07 0.0014857665318386143 0.01357279579679016 7.433882007060598e-19 0.010332816333870285 3.847475876445072e-05 437.1090355731476 30 "Covariance may not be accurate. Covariance not positive definite. Covariance forced positive definite."
1334620 0 15 14 15 0 0.16972856527955688 57333.16236347058 1.0655543499132703e-16 1.569110218163451 4.31495117414471e-09 0.0029725266699608954 0.0719381889430224 3.3251777761293137e-18 0.056826633577869226 5.2241676941816584e-05 84.33058432816203 39 "Covariance may not be accurate. Covariance not positive definite. Covariance forced positive definite."
1334644 0 15 13 14 0 0.17276323507313832 57329.639845904174 7.673707417053692e-17 1.2248356174918276 1.648629954775771e-09 0.007164137590893335 0.034679831343964906 1.9747592063243173e-18 0.031208562198540617 3.4227989489710176e-05 93.23779154405119 37 "Covariance may not be accurate. Covariance not positive definite. Covariance forced positive definite."
1334645 0 12 14 14 0 0.1704392147640836 57332.97194407052 1.2246777191630727e-16 1.4925908012308962 9.260009314893125e-09 0.0020537736269507917 0.02498962569006835 2.1792673950445434e-18 0.032940153428661516 1.727299973047769e-05 225.4203170524836 35 "Covariance may not be accurate. Covariance not positive definite. Covariance forced positive definite."
1334707 0 0 15 16 0 0.39975171940048776 57335.983390627785 1.8919206685659694e-17 1.4263096843758714 1.0383421406023885e-07 0.002002749270043541 0.022978106051596114 2.2854066088474354e-19 0.0213811199555099 2.2535990772121206e-05 58.60016555198837 26 "Covariance may not be accurate. Covariance not positive definite. Covariance forced positive definite."
1334879 0 0 16 17 0 0.4036715139880716 57332.50642045067 1.3256249839377238e-17 1.548266920879133 4.796215409497151e-05 0.0016051163873880836 0.014365959832502995 1.278829699881761e-19 0.014792634107475987 0.04886088929786864 71.41551929676422 28 "Covariance may not be accurate. Covariance not positive definite. Covariance forced positive definite."
1335472 0 0 14 15 0 0.4027381787865367 57341.527708130496 2.4425496484548636e-17 1.6028338220907683 6.547528253131318e-06 0.005205647294548116 0.09130862642996362 5.912755844188643e-19 0.05146446991537864 0.0004143553886278295 17.589541166144386 24 "Covariance may not be accurate. Covariance not positive definite. Covariance forced positive definite."
1335564 0 0 15 14 0 0.39641722218364867 57340.75389038506 1.8248995776192415e-17 1.4584137067855085 7.462015480519391e-07 0.005386794154104063 0.1158112108023488 5.897011774199456e-19 0.0527012208146132 0.00023017989571871844 27.149473530673184 24 "Covariance may not be accurate. Covariance not positive definite. Covariance forced positive definite."
1335694 0 11 8 12 0 nan nan nan nan nan nan nan nan nan nan nan nan "exception was raised in user function
User function arguments:
     z = +0.462831
    t0 = +57341.645491
    x0 = +0.000000
    x1 = -2.596793
     c = +0.939032
Original python exception in user function:
ValueError: Error code returned by bispev: 10
  File ""/anaconda3/envs/sdss_classification_3.7/lib/python3.7/site-packages/sncosmo/fitting.py"", line 46, in chisq
    zp=data.zp, zpsys=data.zpsys)
  File ""/anaconda3/envs/sdss_classification_3.7/lib/python3.7/site-packages/sncosmo/models.py"", line 1400, in bandflux
    raise e
  File ""/anaconda3/envs/sdss_classification_3.7/lib/python3.7/site-packages/sncosmo/models.py"", line 1397, in bandflux
    return _bandflux(self, band, time, zp, zpsys)
  File ""/anaconda3/envs/sdss_classification_3.7/lib/python3.7/site-packages/sncosmo/models.py"", line 154, in _bandflux
    fsum = _bandflux_single(model, b, time_or_phase[mask])
  File ""/anaconda3/envs/sdss_classification_3.7/lib/python3.7/site-packages/sncosmo/models.py"", line 116, in _bandflux_single
    f = model._flux(time_or_phase, wave)
  File ""/anaconda3/envs/sdss_classification_3.7/lib/python3.7/site-packages/sncosmo/models.py"", line 1272, in _flux
    f = a * self._source._flux(phase, restwave)
  File ""/Users/daniel/Github/SDSS-Classification/analysis_pipeline/_sn91bg_model/_model.py"", line 135, in _flux
    y = [self._model_flux[c1](phase / (st / 0.65), wave),
  File ""/anaconda3/envs/sdss_classification_3.7/lib/python3.7/site-packages/scipy/interpolate/fitpack2.py"", line 848, in __call__
    raise ValueError(""Error code returned by bispev: %s"" % ier)"
1335717 0 13 12 13 0 nan nan nan nan nan nan nan nan nan nan nan nan "exception was raised in user function
User function arguments:
     z = +0.534382
    t0 = +57334.597763
    x0 = +0.000000
    x1 = -0.507784
     c = +0.883398
Original python exception in user function:
ValueError: Error code returned by bispev: 10
  File ""/anaconda3/envs/sdss_classification_3.7/lib/python3.7/site-packages/sncosmo/fitting.py"", line 46, in chisq
    zp=data.zp, zpsys=data.zpsys)
  File ""/anaconda3/envs/sdss_classification_3.7/lib/python3.7/site-packages/sncosmo/models.py"", line 1400, in bandflux
    raise e
  File ""/anaconda3/envs/sdss_classification_3.7/lib/python3.7/site-packages/sncosmo/models.py"", line 1397, in bandflux
    return _bandflux(self, band, time, zp, zpsys)
  File ""/anaconda3/envs/sdss_classification_3.7/lib/python3.7/site-packages/sncosmo/models.py"", line 154, in _bandflux
    fsum = _bandflux_single(model, b, time_or_phase[mask])
  File ""/anaconda3/envs/sdss_classification_3.7/lib/python3.7/site-packages/sncosmo/models.py"", line 116, in _bandflux_single
    f = model._flux(time_or_phase, wave)
  File ""/anaconda3/envs/sdss_classification_3.7/lib/python3.7/site-packages/sncosmo/models.py"", line 1272, in _flux
    f = a * self._source._flux(phase, restwave)
  File ""/Users/daniel/Github/SDSS-Classification/analysis_pipeline/_sn91bg_model/_model.py"", line 135, in _flux
    y = [self._model_flux[c1](phase / (st / 0.65), wave),
  File ""/anaconda3/envs/sdss_classification_3.7/lib/python3.7/site-packages/scipy/interpolate/fitpack2.py"", line 848, in __call__
    raise ValueError(""Error code returned by bispev: %s"" % ier)"
1335718 0 0 14 15 0 0.400246201558809 57346.60282916198 1.4276664055232003e-17 1.5788084734317829 9.231822604705009e-07 0.0015674893404741541 0.032137449612491764 1.4437244106632973e-19 0.017520308052466325 1.7548104306847057e-05 62.794016358048935 24 "Covariance may not be accurate. Covariance not positive definite. Covariance forced positive definite."
1335868 0 0 17 16 0 0.4060760546847127 57344.182703024555 2.020385533942606e-17 1.7258366833274412 0.1719898129906295 0.0020233364758676653 0.051459090780554106 4.363412331044404e-19 0.026716889099804075 0.02196537211763258 30.865499661905606 28 "Covariance may not be accurate. Covariance not positive definite. Covariance forced positive definite."
1336008 0 13 11 13 0 0.17093887351601852 57343.76109062315 5.692362836017759e-17 1.575955978430568 1.2576661478913564e-06 0.003300911109948443 0.11706654502268066 1.1067241678135188e-18 0.0326780982026367 0.0001296857148030961 56.49175263977933 32 "Covariance may not be accurate. Covariance not positive definite. Covariance forced positive definite."
1336009 0 13 12 13 0 0.19862199647384504 57341.69227079933 4.035764275577572e-17 1.4878522102026104 0.02426328900214131 0.0028827959724687796 0.05071296171445283 6.4827632638859685e-19 0.016796412894123692 0.01747725251421356 34.20200341706027 33 "Covariance may not be accurate. Covariance not positive definite. Covariance forced positive definite."
1336453 0 9 10 10 0 nan nan nan nan nan nan nan nan nan nan nan nan "exception was raised in user function
User function arguments:
     z = +0.468931
    t0 = +57343.246898
    x0 = +0.000000
    x1 = -0.090401
     c = +0.995076
Original python exception in user function:
ValueError: Error code returned by bispev: 10
  File ""/anaconda3/envs/sdss_classification_3.7/lib/python3.7/site-packages/sncosmo/fitting.py"", line 46, in chisq
    zp=data.zp, zpsys=data.zpsys)
  File ""/anaconda3/envs/sdss_classification_3.7/lib/python3.7/site-packages/sncosmo/models.py"", line 1400, in bandflux
    raise e
  File ""/anaconda3/envs/sdss_classification_3.7/lib/python3.7/site-packages/sncosmo/models.py"", line 1397, in bandflux
    return _bandflux(self, band, time, zp, zpsys)
  File ""/anaconda3/envs/sdss_classification_3.7/lib/python3.7/site-packages/sncosmo/models.py"", line 154, in _bandflux
    fsum = _bandflux_single(model, b, time_or_phase[mask])
  File ""/anaconda3/envs/sdss_classification_3.7/lib/python3.7/site-packages/sncosmo/models.py"", line 116, in _bandflux_single
    f = model._flux(time_or_phase, wave)
  File ""/anaconda3/envs/sdss_classification_3.7/lib/python3.7/site-packages/sncosmo/models.py"", line 1272, in _flux
    f = a * self._source._flux(phase, restwave)
  File ""/Users/daniel/Github/SDSS-Classification/analysis_pipeline/_sn91bg_model/_model.py"", line 135, in _flux
    y = [self._model_flux[c1](phase / (st / 0.65), wave),
  File ""/anaconda3/envs/sdss_classification_3.7/lib/python3.7/site-packages/scipy/interpolate/fitpack2.py"", line 848, in __call__
    raise ValueError(""Error code returned by bispev: %s"" % ier)"
1336480 0 7 10 11 0 0.07508634433867706 57346.939658394 9.010894161955004e-17 1.6327154875232723 0.02824020914298697 0.0033242483507270396 0.0545343784688157 1.931483429871196e-18 0.02668121402045084 0.025805195485992805 39.97978175281264 23 "Covariance may not be accurate. Covariance not positive definite. Covariance forced positive definite."
1336687 0 12 11 11 0 0.2713450888119744 57347.87644148118 1.1239257260218315e-15 0.1452760614375417 3.3141031585692815e-09 0.0022667951288389276 0.016947069361776812 5.518842062027522e-17 0.0016954990328569286 5.464433927640511e-05 2727.4921203969866 29 "Covariance may not be accurate. Covariance not positive definite. Covariance forced positive definite."
1337117 0 0 11 12 0 0.39835261515208487 57358.750551520796 3.0026800474021274e-17 1.60148592603023 1.6729350205135773e-07 0.0037289589989857597 0.18196949463163037 6.85110093269784e-19 0.04041178960866674 8.490440824679424e-05 29.019742594624446 18 "Covariance may not be accurate. Covariance not positive definite. Covariance forced positive definite."
1337221 0 0 14 14 0 0.3980655505674216 57354.93441191359 1.8765513880112932e-17 1.3238424084758529 4.4305311178161055e-06 0.009357649621540204 0.057923475476854946 5.291145771919972e-19 0.04083369047419754 0.0009276561397126848 17.367943951191002 23 "Covariance may not be accurate. Covariance not positive definite. Covariance forced positive definite."
1337228 0 0 14 14 0 0.291306354916631 57354.10366574489 3.0444462829917555e-17 1.4694838428523636 0.9506653523982277 0.002648883997741963 0.03577611876971787 1.2285986955253138e-18 0.04094005720530606 0.04907133281112652 12.408660713210468 23 "Covariance may not be accurate. Covariance not positive definite. Covariance forced positive definite."
1337272 0 0 12 12 0 0.39760343714320356 57354.14029964041 2.213867036265751e-17 1.3330974120819639 7.328664938799356e-07 0.0022555550043596717 0.09512095781610697 6.7989881644263e-19 0.058336690251227306 7.27268169090356e-05 28.127223876948133 19 "Covariance may not be accurate. Covariance not positive definite. Covariance forced positive definite."
1337325 0 0 12 12 0 0.39994217607454896 57354.10553376153 1.7978569308580984e-17 1.311129786342097 1.5946499343222342e-08 0.0022805579144806742 0.11190252280721324 5.122710584204349e-19 0.052271266730514895 9.278862065154048e-05 27.43922934909644 19 "Covariance may not be accurate. Covariance not positive definite. Covariance forced positive definite."
1337649 0 9 9 9 0 nan nan nan nan nan nan nan nan nan nan nan nan "exception was raised in user function
User function arguments:
     z = +0.476669
    t0 = +57372.425542
    x0 = +0.000000
    x1 = -1.443105
     c = +0.925249
Original python exception in user function:
ValueError: Error code returned by bispev: 10
  File ""/anaconda3/envs/sdss_classification_3.7/lib/python3.7/site-packages/sncosmo/fitting.py"", line 46, in chisq
    zp=data.zp, zpsys=data.zpsys)
  File ""/anaconda3/envs/sdss_classification_3.7/lib/python3.7/site-packages/sncosmo/models.py"", line 1400, in bandflux
    raise e
  File ""/anaconda3/envs/sdss_classification_3.7/lib/python3.7/site-packages/sncosmo/models.py"", line 1397, in bandflux
    return _bandflux(self, band, time, zp, zpsys)
  File ""/anaconda3/envs/sdss_classification_3.7/lib/python3.7/site-packages/sncosmo/models.py"", line 154, in _bandflux
    fsum = _bandflux_single(model, b, time_or_phase[mask])
  File ""/anaconda3/envs/sdss_classification_3.7/lib/python3.7/site-packages/sncosmo/models.py"", line 116, in _bandflux_single
    f = model._flux(time_or_phase, wave)
  File ""/anaconda3/envs/sdss_classification_3.7/lib/python3.7/site-packages/sncosmo/models.py"", line 1272, in _flux
    f = a * self._source._flux(phase, restwave)
  File ""/Users/daniel/Github/SDSS-Classification/analysis_pipeline/_sn91bg_model/_model.py"", line 135, in _flux
    y = [self._model_flux[c1](phase / (st / 0.65), wave),
  File ""/anaconda3/envs/sdss_classification_3.7/lib/python3.7/site-packages/scipy/interpolate/fitpack2.py"", line 848, in __call__
    raise ValueError(""Error code returned by bispev: %s"" % ier)"
1337655 0 0 0 10 0 0.4760946251021534 57358.248755814675 1.5183658680271495e-17 1.4984045019212964 0.5023174902954044 0.0010280613958353335 0.03404787477120408 2.685022765832277e-19 0.01926677923186128 0.02426024816965458 7.135774060459648 5 "Covariance may not be accurate. Covariance not positive definite. Covariance forced positive definite."
1337687 0 12 12 11 0 nan nan nan nan nan nan nan nan nan nan nan nan "exception was raised in user function
User function arguments:
     z = +0.493591
    t0 = +57370.593267
    x0 = +0.000000
    x1 = -0.979774
     c = +0.945204
Original python exception in user function:
ValueError: Error code returned by bispev: 10
  File ""/anaconda3/envs/sdss_classification_3.7/lib/python3.7/site-packages/sncosmo/fitting.py"", line 46, in chisq
    zp=data.zp, zpsys=data.zpsys)
  File ""/anaconda3/envs/sdss_classification_3.7/lib/python3.7/site-packages/sncosmo/models.py"", line 1400, in bandflux
    raise e
  File ""/anaconda3/envs/sdss_classification_3.7/lib/python3.7/site-packages/sncosmo/models.py"", line 1397, in bandflux
    return _bandflux(self, band, time, zp, zpsys)
  File ""/anaconda3/envs/sdss_classification_3.7/lib/python3.7/site-packages/sncosmo/models.py"", line 154, in _bandflux
    fsum = _bandflux_single(model, b, time_or_phase[mask])
  File ""/anaconda3/envs/sdss_classification_3.7/lib/python3.7/site-packages/sncosmo/models.py"", line 116, in _bandflux_single
    f = model._flux(time_or_phase, wave)
  File ""/anaconda3/envs/sdss_classification_3.7/lib/python3.7/site-packages/sncosmo/models.py"", line 1272, in _flux
    f = a * self._source._flux(phase, restwave)
  File ""/Users/daniel/Github/SDSS-Classification/analysis_pipeline/_sn91bg_model/_model.py"", line 135, in _flux
    y = [self._model_flux[c1](phase / (st / 0.65), wave),
  File ""/anaconda3/envs/sdss_classification_3.7/lib/python3.7/site-packages/scipy/interpolate/fitpack2.py"", line 848, in __call__
    raise ValueError(""Error code returned by bispev: %s"" % ier)"
1337703 0 0 15 14 0 0.3924485062113471 57356.90282395541 2.5868952355461484e-17 1.5196369830836218 2.36722244806864e-05 0.0156363813142448 0.2998896582357702 9.459737514708322e-19 0.06403145324528617 0.009167030003396859 16.940799851292752 24 "Covariance may not be accurate. Covariance not positive definite. Covariance forced positive definite."
1337838 0 11 10 11 0 0.06484911656006548 57359.77475039388 1.112979466297849e-16 1.6363649516957248 0.3266662952567452 0.002386209093623283 0.01639779660399654 1.2124221976805998e-18 0.012651456696912177 0.013968254431661165 149.9970249536097 27 "Covariance may not be accurate. Covariance not positive definite. Covariance forced positive definite."
1338128 0 11 11 11 0 nan nan nan nan nan nan nan nan nan nan nan nan "exception was raised in user function
User function arguments:
     z = +0.501068
    t0 = +57375.837814
    x0 = +0.000000
    x1 = -0.945124
     c = +0.999631
Original python exception in user function:
ValueError: Error code returned by bispev: 10
  File ""/anaconda3/envs/sdss_classification_3.7/lib/python3.7/site-packages/sncosmo/fitting.py"", line 46, in chisq
    zp=data.zp, zpsys=data.zpsys)
  File ""/anaconda3/envs/sdss_classification_3.7/lib/python3.7/site-packages/sncosmo/models.py"", line 1400, in bandflux
    raise e
  File ""/anaconda3/envs/sdss_classification_3.7/lib/python3.7/site-packages/sncosmo/models.py"", line 1397, in bandflux
    return _bandflux(self, band, time, zp, zpsys)
  File ""/anaconda3/envs/sdss_classification_3.7/lib/python3.7/site-packages/sncosmo/models.py"", line 154, in _bandflux
    fsum = _bandflux_single(model, b, time_or_phase[mask])
  File ""/anaconda3/envs/sdss_classification_3.7/lib/python3.7/site-packages/sncosmo/models.py"", line 116, in _bandflux_single
    f = model._flux(time_or_phase, wave)
  File ""/anaconda3/envs/sdss_classification_3.7/lib/python3.7/site-packages/sncosmo/models.py"", line 1272, in _flux
    f = a * self._source._flux(phase, restwave)
  File ""/Users/daniel/Github/SDSS-Classification/analysis_pipeline/_sn91bg_model/_model.py"", line 135, in _flux
    y = [self._model_flux[c1](phase / (st / 0.65), wave),
  File ""/anaconda3/envs/sdss_classification_3.7/lib/python3.7/site-packages/scipy/interpolate/fitpack2.py"", line 848, in __call__
    raise ValueError(""Error code returned by bispev: %s"" % ier)"
1338170 0 11 11 11 0 nan nan nan nan nan nan nan nan nan nan nan nan "exception was raised in user function
User function arguments:
     z = +0.463557
    t0 = +57355.379112
    x0 = +0.000000
    x1 = -0.021484
     c = +0.955911
Original python exception in user function:
ValueError: Error code returned by bispev: 10
  File ""/anaconda3/envs/sdss_classification_3.7/lib/python3.7/site-packages/sncosmo/fitting.py"", line 46, in chisq
    zp=data.zp, zpsys=data.zpsys)
  File ""/anaconda3/envs/sdss_classification_3.7/lib/python3.7/site-packages/sncosmo/models.py"", line 1400, in bandflux
    raise e
  File ""/anaconda3/envs/sdss_classification_3.7/lib/python3.7/site-packages/sncosmo/models.py"", line 1397, in bandflux
    return _bandflux(self, band, time, zp, zpsys)
  File ""/anaconda3/envs/sdss_classification_3.7/lib/python3.7/site-packages/sncosmo/models.py"", line 154, in _bandflux
    fsum = _bandflux_single(model, b, time_or_phase[mask])
  File ""/anaconda3/envs/sdss_classification_3.7/lib/python3.7/site-packages/sncosmo/models.py"", line 116, in _bandflux_single
    f = model._flux(time_or_phase, wave)
  File ""/anaconda3/envs/sdss_classification_3.7/lib/python3.7/site-packages/sncosmo/models.py"", line 1272, in _flux
    f = a * self._source._flux(phase, restwave)
  File ""/Users/daniel/Github/SDSS-Classification/analysis_pipeline/_sn91bg_model/_model.py"", line 135, in _flux
    y = [self._model_flux[c1](phase / (st / 0.65), wave),
  File ""/anaconda3/envs/sdss_classification_3.7/lib/python3.7/site-packages/scipy/interpolate/fitpack2.py"", line 848, in __call__
    raise ValueError(""Error code returned by bispev: %s"" % ier)"
1338233 0 0 13 13 0 0.3956599032756273 57354.00188129587 1.3905528782393518e-17 1.2577319652855128 5.958999425403899e-06 0.005551073796255468 0.19334506347149727 6.714560773604742e-19 0.08426535289861228 0.0005004817401845496 7.785483417487596 21 "Covariance may not be accurate. Covariance not positive definite. Covariance forced positive definite."
1338266 0 0 19 21 0 0.48876745397396637 57364.11271989681 1.2744264739762233e-17 1.4076390436904793 1.6023673679588235e-06 0.004013105563879432 0.20524392023435212 3.8450031139521614e-19 0.061817813125206525 9.09163463566065e-05 37.545590719987985 35 "Covariance may not be accurate. Covariance not positive definite. Covariance forced positive definite."
1338278 0 0 10 10 0 0.40037416531642894 57363.9699501183 2.2006625665798333e-17 1.5340384771598838 3.079497218339e-08 0.006071483914799725 0.28356139939205605 7.784827167122569e-19 0.0793579132307358 0.0001817801260700913 12.872545640841198 15 "Covariance may not be accurate. Covariance not positive definite. Covariance forced positive definite."
1338387 0 0 10 10 0 0.2534847246999336 57359.94946602054 4.1326850206959364e-17 1.6946774804813882 0.7759252674661788 0.002534826573338256 0.07758583747636294 1.0149371252205418e-18 0.03335116620498915 0.037388593203455944 24.94494988345344 15 "Covariance may not be accurate. Covariance not positive definite. Covariance forced positive definite."
1338430 0 0 9 9 0 0.3988796353594516 57359.80625298788 2.794112796394559e-17 1.5078136450059372 2.566646449153609e-06 0.006473258556111139 0.20737462938996032 8.363916357619792e-19 0.06625293926486898 0.00034810071877505733 9.429937924323617 13 "Covariance may not be accurate. Covariance not positive definite. Covariance forced positive definite."
1338471 0 0 11 12 0 0.3952559538632341 57348.87300699986 1.3743063167993168e-17 1.5383970668046794 1.978882561115558e-05 0.004090148757218359 0.43810544878579094 5.35490249044579e-19 0.06715423445582697 0.0005014300228954605 8.512169974975105 18 "Covariance may not be accurate. Covariance not positive definite. Covariance forced positive definite."
1338675 0 8 9 8 0 0.06940675181797172 57367.42202980258 7.671606892309998e-17 1.5559361726167762 0.44356935646338225 0.0018304518848257928 0.032648277356202016 7.411556710238362e-19 0.011039396718636836 0.011657487651988568 85.65741240706734 20 "Covariance may not be accurate. Covariance not positive definite. Covariance forced positive definite."
1339002 0 9 9 10 0 0.1908648997823561 57367.95258977337 6.0908040810507e-17 1.42048225484591 0.06894023760690488 0.0022340341196749602 0.07699179526025546 1.7033935987117975e-18 0.02506750223841174 0.03127569869868321 29.89923227688654 23 "Covariance may not be accurate. Covariance not positive definite. Covariance forced positive definite."
1339149 0 0 9 9 0 0.39765402689666424 57371.01502569989 2.803931747976463e-17 1.4574263427213527 3.091675687683093e-07 0.0032148767431352254 0.10234424133523135 8.512544885727619e-19 0.05236382448248808 8.603668076073712e-05 25.02125553212772 13 "Covariance may not be accurate. Covariance not positive definite. Covariance forced positive definite."
1339392 0 6 7 12 0 nan nan nan nan nan nan nan nan nan nan nan nan "exception was raised in user function
User function arguments:
     z = +0.480668
    t0 = +57373.821738
    x0 = +0.000000
    x1 = -0.234674
     c = +0.998349
Original python exception in user function:
ValueError: Error code returned by bispev: 10
  File ""/anaconda3/envs/sdss_classification_3.7/lib/python3.7/site-packages/sncosmo/fitting.py"", line 46, in chisq
    zp=data.zp, zpsys=data.zpsys)
  File ""/anaconda3/envs/sdss_classification_3.7/lib/python3.7/site-packages/sncosmo/models.py"", line 1400, in bandflux
    raise e
  File ""/anaconda3/envs/sdss_classification_3.7/lib/python3.7/site-packages/sncosmo/models.py"", line 1397, in bandflux
    return _bandflux(self, band, time, zp, zpsys)
  File ""/anaconda3/envs/sdss_classification_3.7/lib/python3.7/site-packages/sncosmo/models.py"", line 154, in _bandflux
    fsum = _bandflux_single(model, b, time_or_phase[mask])
  File ""/anaconda3/envs/sdss_classification_3.7/lib/python3.7/site-packages/sncosmo/models.py"", line 116, in _bandflux_single
    f = model._flux(time_or_phase, wave)
  File ""/anaconda3/envs/sdss_classification_3.7/lib/python3.7/site-packages/sncosmo/models.py"", line 1272, in _flux
    f = a * self._source._flux(phase, restwave)
  File ""/Users/daniel/Github/SDSS-Classification/analysis_pipeline/_sn91bg_model/_model.py"", line 135, in _flux
    y = [self._model_flux[c1](phase / (st / 0.65), wave),
  File ""/anaconda3/envs/sdss_classification_3.7/lib/python3.7/site-packages/scipy/interpolate/fitpack2.py"", line 848, in __call__
    raise ValueError(""Error code returned by bispev: %s"" % ier)"
1339450 0 0 13 13 0 0.399156460529208 57366.36057177089 1.617996476505606e-17 1.3370837371685458 1.4692527150472756e-06 0.005272016562733073 0.3446458578837337 7.280899768547967e-19 0.07666657630795624 0.00032483777482472664 23.560809710583698 21 "Covariance may not be accurate. Covariance not positive definite. Covariance forced positive definite."
1340454 0 11 11 10 0 0.2650226308891433 57371.96768151387 3.99455946973746e-17 1.8307529276789716 1.5417688975505328e-06 0.004977897884447108 0.040899509185692295 6.502340648933546e-19 0.044470380170913766 0.0015847017958958987 23.82745663562565 27 "Covariance may not be accurate. Covariance not positive definite. Covariance forced positive definite."
1341370 0 8 8 8 0 0.17048459857939613 57372.17611680952 4.529727759850342e-17 1.6435014767520366 3.867444411054244e-06 0.004429997377867395 0.0167406866348756 8.182356239465789e-19 0.02909683725582761 0.00014464917984316483 41.745638923662966 19 "Covariance may not be accurate. Covariance not positive definite. Covariance forced positive definite."
1341894 0 7 7 7 0 0.06306856640680428 57386.3522014969 8.779621468429779e-17 1.5923185979947532 0.2759094681300406 0.005075119321139264 0.04280692011161591 2.393496004764797e-18 0.030987147437482862 0.03800357605223767 21.0918810366027 16 "Covariance may not be accurate. Covariance not positive definite. Covariance forced positive definite."
1342255 0 6 6 6 0 nan nan nan nan nan nan nan nan nan nan nan nan "exception was raised in user function
User function arguments:
     z = +0.483852
    t0 = +57389.196088
    x0 = +0.000000
    x1 = -0.094764
     c = +0.550000
Original python exception in user function:
ValueError: Error code returned by bispev: 10
  File ""/anaconda3/envs/sdss_classification_3.7/lib/python3.7/site-packages/sncosmo/fitting.py"", line 46, in chisq
    zp=data.zp, zpsys=data.zpsys)
  File ""/anaconda3/envs/sdss_classification_3.7/lib/python3.7/site-packages/sncosmo/models.py"", line 1400, in bandflux
    raise e
  File ""/anaconda3/envs/sdss_classification_3.7/lib/python3.7/site-packages/sncosmo/models.py"", line 1397, in bandflux
    return _bandflux(self, band, time, zp, zpsys)
  File ""/anaconda3/envs/sdss_classification_3.7/lib/python3.7/site-packages/sncosmo/models.py"", line 154, in _bandflux
    fsum = _bandflux_single(model, b, time_or_phase[mask])
  File ""/anaconda3/envs/sdss_classification_3.7/lib/python3.7/site-packages/sncosmo/models.py"", line 116, in _bandflux_single
    f = model._flux(time_or_phase, wave)
  File ""/anaconda3/envs/sdss_classification_3.7/lib/python3.7/site-packages/sncosmo/models.py"", line 1272, in _flux
    f = a * self._source._flux(phase, restwave)
  File ""/Users/daniel/Github/SDSS-Classification/analysis_pipeline/_sn91bg_model/_model.py"", line 135, in _flux
    y = [self._model_flux[c1](phase / (st / 0.65), wave),
  File ""/anaconda3/envs/sdss_classification_3.7/lib/python3.7/site-packages/scipy/interpolate/fitpack2.py"", line 848, in __call__
    raise ValueError(""Error code returned by bispev: %s"" % ier)"
1343208 0 0 6 10 0 0.3960220802564671 57386.967129075405 2.4262255292881562e-17 1.2692836904950116 8.146325354840833e-07 0.009626830551749344 0.05576925177956582 4.744512173558234e-19 0.03228601715558221 0.0006405123540945412 5.680650872860037 11 "Covariance may not be accurate. Covariance not positive definite. Covariance forced positive definite."
1343337 0 8 8 8 0 nan nan nan nan nan nan nan nan nan nan nan nan "exception was raised in user function
User function arguments:
     z = +0.472154
    t0 = +57392.434498
    x0 = +0.000000
    x1 = -3.859332
     c = +0.815128
Original python exception in user function:
ValueError: Error code returned by bispev: 10
  File ""/anaconda3/envs/sdss_classification_3.7/lib/python3.7/site-packages/sncosmo/fitting.py"", line 46, in chisq
    zp=data.zp, zpsys=data.zpsys)
  File ""/anaconda3/envs/sdss_classification_3.7/lib/python3.7/site-packages/sncosmo/models.py"", line 1400, in bandflux
    raise e
  File ""/anaconda3/envs/sdss_classification_3.7/lib/python3.7/site-packages/sncosmo/models.py"", line 1397, in bandflux
    return _bandflux(self, band, time, zp, zpsys)
  File ""/anaconda3/envs/sdss_classification_3.7/lib/python3.7/site-packages/sncosmo/models.py"", line 154, in _bandflux
    fsum = _bandflux_single(model, b, time_or_phase[mask])
  File ""/anaconda3/envs/sdss_classification_3.7/lib/python3.7/site-packages/sncosmo/models.py"", line 116, in _bandflux_single
    f = model._flux(time_or_phase, wave)
  File ""/anaconda3/envs/sdss_classification_3.7/lib/python3.7/site-packages/sncosmo/models.py"", line 1272, in _flux
    f = a * self._source._flux(phase, restwave)
  File ""/Users/daniel/Github/SDSS-Classification/analysis_pipeline/_sn91bg_model/_model.py"", line 135, in _flux
    y = [self._model_flux[c1](phase / (st / 0.65), wave),
  File ""/anaconda3/envs/sdss_classification_3.7/lib/python3.7/site-packages/scipy/interpolate/fitpack2.py"", line 848, in __call__
    raise ValueError(""Error code returned by bispev: %s"" % ier)"
1343401 0 6 6 6 0 nan nan nan nan nan nan nan nan nan nan nan nan "exception was raised in user function
User function arguments:
     z = +0.465772
    t0 = +57390.165653
    x0 = +0.000000
    x1 = -0.753688
     c = +0.872144
Original python exception in user function:
ValueError: Error code returned by bispev: 10
  File ""/anaconda3/envs/sdss_classification_3.7/lib/python3.7/site-packages/sncosmo/fitting.py"", line 46, in chisq
    zp=data.zp, zpsys=data.zpsys)
  File ""/anaconda3/envs/sdss_classification_3.7/lib/python3.7/site-packages/sncosmo/models.py"", line 1400, in bandflux
    raise e
  File ""/anaconda3/envs/sdss_classification_3.7/lib/python3.7/site-packages/sncosmo/models.py"", line 1397, in bandflux
    return _bandflux(self, band, time, zp, zpsys)
  File ""/anaconda3/envs/sdss_classification_3.7/lib/python3.7/site-packages/sncosmo/models.py"", line 154, in _bandflux
    fsum = _bandflux_single(model, b, time_or_phase[mask])
  File ""/anaconda3/envs/sdss_classification_3.7/lib/python3.7/site-packages/sncosmo/models.py"", line 116, in _bandflux_single
    f = model._flux(time_or_phase, wave)
  File ""/anaconda3/envs/sdss_classification_3.7/lib/python3.7/site-packages/sncosmo/models.py"", line 1272, in _flux
    f = a * self._source._flux(phase, restwave)
  File ""/Users/daniel/Github/SDSS-Classification/analysis_pipeline/_sn91bg_model/_model.py"", line 135, in _flux
    y = [self._model_flux[c1](phase / (st / 0.65), wave),
  File ""/anaconda3/envs/sdss_classification_3.7/lib/python3.7/site-packages/scipy/interpolate/fitpack2.py"", line 848, in __call__
    raise ValueError(""Error code returned by bispev: %s"" % ier)"
1343533 0 8 8 8 0 nan nan nan nan nan nan nan nan nan nan nan nan "exception was raised in user function
User function arguments:
     z = +0.471489
    t0 = +57395.249491
    x0 = +0.000000
    x1 = -1.620683
     c = +0.894912
Original python exception in user function:
ValueError: Error code returned by bispev: 10
  File ""/anaconda3/envs/sdss_classification_3.7/lib/python3.7/site-packages/sncosmo/fitting.py"", line 46, in chisq
    zp=data.zp, zpsys=data.zpsys)
  File ""/anaconda3/envs/sdss_classification_3.7/lib/python3.7/site-packages/sncosmo/models.py"", line 1400, in bandflux
    raise e
  File ""/anaconda3/envs/sdss_classification_3.7/lib/python3.7/site-packages/sncosmo/models.py"", line 1397, in bandflux
    return _bandflux(self, band, time, zp, zpsys)
  File ""/anaconda3/envs/sdss_classification_3.7/lib/python3.7/site-packages/sncosmo/models.py"", line 154, in _bandflux
    fsum = _bandflux_single(model, b, time_or_phase[mask])
  File ""/anaconda3/envs/sdss_classification_3.7/lib/python3.7/site-packages/sncosmo/models.py"", line 116, in _bandflux_single
    f = model._flux(time_or_phase, wave)
  File ""/anaconda3/envs/sdss_classification_3.7/lib/python3.7/site-packages/sncosmo/models.py"", line 1272, in _flux
    f = a * self._source._flux(phase, restwave)
  File ""/Users/daniel/Github/SDSS-Classification/analysis_pipeline/_sn91bg_model/_model.py"", line 135, in _flux
    y = [self._model_flux[c1](phase / (st / 0.65), wave),
  File ""/anaconda3/envs/sdss_classification_3.7/lib/python3.7/site-packages/scipy/interpolate/fitpack2.py"", line 848, in __call__
    raise ValueError(""Error code returned by bispev: %s"" % ier)"
1343759 0 0 7 8 0 0.3988066809344334 57391.35705893966 2.7745007097835025e-17 1.3601339782859299 9.829102833314174e-07 0.0018583674781847692 0.057678192602907075 2.893844312566266e-19 0.024781341955755248 1.9934804915827664e-05 43.10774617568569 10 "Covariance may not be accurate. Covariance not positive definite. Covariance forced positive definite."
1343871 0 0 7 7 0 0.4027297011916626 57387.63531129191 1.5802469498898504e-17 1.7882948431762458 6.566618579562089e-06 0.007679171077590974 0.311209047169541 4.912872779935753e-19 0.06051662721340346 0.0012378234797784382 6.449497688556864 9 "Covariance may not be accurate. Covariance not positive definite. Covariance forced positive definite."
1344692 0 7 7 7 0 0.20051617772362976 57391.48642204969 4.1706657603533564e-17 1.1913109931373296 0.4926857369768644 0.006082615507911157 0.21535234854673035 1.8165798906192934e-18 0.08708121353423463 0.03575436725708639 5.922778557305536 16 "Covariance may not be accurate. Covariance not positive definite. Covariance forced positive definite."
1345553 0 6 6 6 0 nan nan nan nan nan nan nan nan nan nan nan nan "exception was raised in user function
User function arguments:
     z = +0.470768
    t0 = +57389.833236
    x0 = +0.000000
    x1 = -0.810181
     c = +0.944302
Original python exception in user function:
ValueError: Error code returned by bispev: 10
  File ""/anaconda3/envs/sdss_classification_3.7/lib/python3.7/site-packages/sncosmo/fitting.py"", line 46, in chisq
    zp=data.zp, zpsys=data.zpsys)
  File ""/anaconda3/envs/sdss_classification_3.7/lib/python3.7/site-packages/sncosmo/models.py"", line 1400, in bandflux
    raise e
  File ""/anaconda3/envs/sdss_classification_3.7/lib/python3.7/site-packages/sncosmo/models.py"", line 1397, in bandflux
    return _bandflux(self, band, time, zp, zpsys)
  File ""/anaconda3/envs/sdss_classification_3.7/lib/python3.7/site-packages/sncosmo/models.py"", line 154, in _bandflux
    fsum = _bandflux_single(model, b, time_or_phase[mask])
  File ""/anaconda3/envs/sdss_classification_3.7/lib/python3.7/site-packages/sncosmo/models.py"", line 116, in _bandflux_single
    f = model._flux(time_or_phase, wave)
  File ""/anaconda3/envs/sdss_classification_3.7/lib/python3.7/site-packages/sncosmo/models.py"", line 1272, in _flux
    f = a * self._source._flux(phase, restwave)
  File ""/Users/daniel/Github/SDSS-Classification/analysis_pipeline/_sn91bg_model/_model.py"", line 135, in _flux
    y = [self._model_flux[c1](phase / (st / 0.65), wave),
  File ""/anaconda3/envs/sdss_classification_3.7/lib/python3.7/site-packages/scipy/interpolate/fitpack2.py"", line 848, in __call__
    raise ValueError(""Error code returned by bispev: %s"" % ier)"
1345582 0 0 7 7 0 0.3998574842409748 57394.70892362927 2.976672439435875e-17 1.427744812926313 4.86168645341678e-08 0.00472232701649708 0.33190528558407095 1.1206899957276077e-18 0.10062633605192595 0.00016252754138096348 12.991869400584477 9 "Covariance may not be accurate. Covariance not positive definite. Covariance forced positive definite."
1345594 0 5 6 6 0 0.09752354053311219 57404.77493879418 1.0783484705414004e-16 0.5533030778364196 0.15682202079610097 0.010526042334759282 0.14968303866044153 8.384202089785168e-18 0.024015228098158505 0.09048841936130861 287.87103052415983 12 "Covariance may not be accurate. Covariance not positive definite. Covariance forced positive definite."
1346137 0 7 7 7 0 0.39094439364696654 57402.930257205495 5.107731571466159e-17 1.6747932124580585 3.0572191445088492e-09 0.002553190504160363 0.4866823038282746 1.766291071875318e-18 0.04547592409785581 1.8408245263640266e-05 69.89355652488959 16 "Covariance may not be accurate. Covariance not positive definite. Covariance forced positive definite."
1346387 0 7 6 7 0 nan nan nan nan nan nan nan nan nan nan nan nan "exception was raised in user function
User function arguments:
     z = +0.475863
    t0 = +57395.244088
    x0 = +0.000000
    x1 = -1.183876
     c = +0.550000
Original python exception in user function:
ValueError: Error code returned by bispev: 10
  File ""/anaconda3/envs/sdss_classification_3.7/lib/python3.7/site-packages/sncosmo/fitting.py"", line 46, in chisq
    zp=data.zp, zpsys=data.zpsys)
  File ""/anaconda3/envs/sdss_classification_3.7/lib/python3.7/site-packages/sncosmo/models.py"", line 1400, in bandflux
    raise e
  File ""/anaconda3/envs/sdss_classification_3.7/lib/python3.7/site-packages/sncosmo/models.py"", line 1397, in bandflux
    return _bandflux(self, band, time, zp, zpsys)
  File ""/anaconda3/envs/sdss_classification_3.7/lib/python3.7/site-packages/sncosmo/models.py"", line 154, in _bandflux
    fsum = _bandflux_single(model, b, time_or_phase[mask])
  File ""/anaconda3/envs/sdss_classification_3.7/lib/python3.7/site-packages/sncosmo/models.py"", line 116, in _bandflux_single
    f = model._flux(time_or_phase, wave)
  File ""/anaconda3/envs/sdss_classification_3.7/lib/python3.7/site-packages/sncosmo/models.py"", line 1272, in _flux
    f = a * self._source._flux(phase, restwave)
  File ""/Users/daniel/Github/SDSS-Classification/analysis_pipeline/_sn91bg_model/_model.py"", line 135, in _flux
    y = [self._model_flux[c1](phase / (st / 0.65), wave),
  File ""/anaconda3/envs/sdss_classification_3.7/lib/python3.7/site-packages/scipy/interpolate/fitpack2.py"", line 848, in __call__
    raise ValueError(""Error code returned by bispev: %s"" % ier)"
1346956 0 5 5 5 0 0.17042854801803942 57409.994603892446 8.892741560792653e-17 1.7104962337688723 5.440925410216124e-08 0.002301861354187487 0.15142138249211712 1.5436441745093426e-18 0.021845108251511362 7.04316712937525e-05 61.435929485024175 10 "Covariance may not be accurate. Covariance not positive definite. Covariance forced positive definite."
1346966 0 7 7 7 0 nan nan nan nan nan nan nan nan nan nan nan nan "exception was raised in user function
User function arguments:
     z = +0.478438
    t0 = +57419.003189
    x0 = +0.000000
    x1 = -1.688752
     c = +0.865735
Original python exception in user function:
ValueError: Error code returned by bispev: 10
  File ""/anaconda3/envs/sdss_classification_3.7/lib/python3.7/site-packages/sncosmo/fitting.py"", line 46, in chisq
    zp=data.zp, zpsys=data.zpsys)
  File ""/anaconda3/envs/sdss_classification_3.7/lib/python3.7/site-packages/sncosmo/models.py"", line 1400, in bandflux
    raise e
  File ""/anaconda3/envs/sdss_classification_3.7/lib/python3.7/site-packages/sncosmo/models.py"", line 1397, in bandflux
    return _bandflux(self, band, time, zp, zpsys)
  File ""/anaconda3/envs/sdss_classification_3.7/lib/python3.7/site-packages/sncosmo/models.py"", line 154, in _bandflux
    fsum = _bandflux_single(model, b, time_or_phase[mask])
  File ""/anaconda3/envs/sdss_classification_3.7/lib/python3.7/site-packages/sncosmo/models.py"", line 116, in _bandflux_single
    f = model._flux(time_or_phase, wave)
  File ""/anaconda3/envs/sdss_classification_3.7/lib/python3.7/site-packages/sncosmo/models.py"", line 1272, in _flux
    f = a * self._source._flux(phase, restwave)
  File ""/Users/daniel/Github/SDSS-Classification/analysis_pipeline/_sn91bg_model/_model.py"", line 135, in _flux
    y = [self._model_flux[c1](phase / (st / 0.65), wave),
  File ""/anaconda3/envs/sdss_classification_3.7/lib/python3.7/site-packages/scipy/interpolate/fitpack2.py"", line 848, in __call__
    raise ValueError(""Error code returned by bispev: %s"" % ier)"
